{
  "version": 8,
  "blockIdVersion": 11,
  "anchorX": 0,
  "anchorY": 0,
  "anchorZ": 0,
  "blocks": [
    {
      "x": -9,
      "y": 0,
      "z": -7,
      "name": "Soil_Sand_Black"
    },
    {
      "x": -9,
      "y": 0,
      "z": -6,
      "name": "Soil_Sand_Black"
    },
    {
      "x": -9,
      "y": 0,
      "z": -5,
      "name": "Soil_Sand_Black"
    },
    {
      "x": -9,
      "y": 0,
      "z": -4,
      "name": "Soil_Sand_Black"
    },
    {
      "x": -9,
      "y": 0,
      "z": -3,
      "name": "Soil_Sand_Black"
    },
    {
      "x": -9,
      "y": 0,
      "z": -2,
      "name": "Soil_Sand_Black"
    },
    {
      "x": -9,
      "y": 0,
      "z": -1,
      "name": "Soil_Sand_Black"
    },
    {
      "x": -9,
      "y": 0,
      "z": 0,
      "name": "Soil_Sand_Black"
    },
    {
      "x": -9,
      "y": 0,
      "z": 1,
      "name": "Soil_Sand_Black"
    },
    {
      "x": -9,
      "y": 0,
      "z": 2,
      "name": "Soil_Sand_Black"
    },
    {
      "x": -9,
      "y": 0,
      "z": 3,
      "name": "Soil_Sand_Black"
    },
    {
      "x": -9,
      "y": 0,
      "z": 4,
      "name": "Soil_Sand_Black"
    },
    {
      "x": -9,
      "y": 0,
      "z": 5,
      "name": "Soil_Sand_Black"
    },
    {
      "x": -9,
      "y": 0,
      "z": 6,
      "name": "Soil_Sand_Black"
    },
    {
      "x": -9,
      "y": 0,
      "z": 7,
      "name": "Soil_Sand_Black"
    },
    {
      "x": -9,
      "y": 0,
      "z": 8,
      "name": "Soil_Sand_Black"
    },
    {
      "x": -8,
      "y": 0,
      "z": -7,
      "name": "Soil_Sand_Black"
    },
    {
      "x": -8,
      "y": 3,
      "z": -7,
      "name": "*Wood_Deadwood_Roof_Hollow_State_Definitions_Corner_Right",
      "rotation": 3
    },
    {
      "x": -8,
      "y": 0,
      "z": -6,
      "name": "Soil_Sand_Black"
    },
    {
      "x": -8,
      "y": 3,
      "z": -6,
      "name": "Wood_Deadwood_Roof_Hollow",
      "rotation": 3
    },
    {
      "x": -8,
      "y": 0,
      "z": -5,
      "name": "Soil_Sand_Black"
    },
    {
      "x": -8,
      "y": 1,
      "z": -5,
      "name": "Plant_Hay_Bundle"
    },
    {
      "x": -8,
      "y": 3,
      "z": -5,
      "name": "Wood_Deadwood_Roof_Hollow",
      "rotation": 3
    },
    {
      "x": -8,
      "y": 0,
      "z": -4,
      "name": "Soil_Sand_Black"
    },
    {
      "x": -8,
      "y": 2,
      "z": -4,
      "name": "Plant_Leaves_Bamboo",
      "support": 15
    },
    {
      "x": -8,
      "y": 3,
      "z": -4,
      "name": "Wood_Deadwood_Roof_Hollow",
      "rotation": 3
    },
    {
      "x": -8,
      "y": 0,
      "z": -3,
      "name": "Soil_Sand_Black"
    },
    {
      "x": -8,
      "y": 3,
      "z": -3,
      "name": "Wood_Deadwood_Roof_Hollow",
      "rotation": 3
    },
    {
      "x": -8,
      "y": 0,
      "z": -2,
      "name": "Soil_Sand_Black"
    },
    {
      "x": -8,
      "y": 3,
      "z": -2,
      "name": "Wood_Deadwood_Roof_Hollow",
      "rotation": 3
    },
    {
      "x": -8,
      "y": 0,
      "z": -1,
      "name": "Soil_Sand_Black"
    },
    {
      "x": -8,
      "y": 0,
      "z": 0,
      "name": "Soil_Sand_Black"
    },
    {
      "x": -8,
      "y": 0,
      "z": 1,
      "name": "Soil_Sand_Black"
    },
    {
      "x": -8,
      "y": 0,
      "z": 2,
      "name": "Soil_Sand_Black"
    },
    {
      "x": -8,
      "y": 3,
      "z": 2,
      "name": "Wood_Deadwood_Roof_Hollow",
      "rotation": 3
    },
    {
      "x": -8,
      "y": 0,
      "z": 3,
      "name": "Soil_Sand_Black"
    },
    {
      "x": -8,
      "y": 3,
      "z": 3,
      "name": "Wood_Deadwood_Roof_Hollow",
      "rotation": 3
    },
    {
      "x": -8,
      "y": 0,
      "z": 4,
      "name": "Soil_Sand_Black"
    },
    {
      "x": -8,
      "y": 3,
      "z": 4,
      "name": "Wood_Deadwood_Roof_Hollow",
      "rotation": 3
    },
    {
      "x": -8,
      "y": 0,
      "z": 5,
      "name": "Soil_Sand_Black"
    },
    {
      "x": -8,
      "y": 3,
      "z": 5,
      "name": "Wood_Deadwood_Roof_Hollow",
      "rotation": 3
    },
    {
      "x": -8,
      "y": 0,
      "z": 6,
      "name": "Soil_Sand_Black"
    },
    {
      "x": -8,
      "y": 3,
      "z": 6,
      "name": "Wood_Deadwood_Roof_Hollow",
      "rotation": 3
    },
    {
      "x": -8,
      "y": 0,
      "z": 7,
      "name": "Soil_Sand_Black"
    },
    {
      "x": -8,
      "y": 3,
      "z": 7,
      "name": "*Wood_Deadwood_Roof_Hollow_State_Definitions_Corner_Right"
    },
    {
      "x": -8,
      "y": 0,
      "z": 8,
      "name": "Soil_Sand_Black"
    },
    {
      "x": -7,
      "y": 0,
      "z": -7,
      "name": "Soil_Sand_Black"
    },
    {
      "x": -7,
      "y": 1,
      "z": -7,
      "name": "Plant_Hay_Bundle"
    },
    {
      "x": -7,
      "y": 3,
      "z": -7,
      "name": "Wood_Deadwood_Roof_Hollow",
      "rotation": 2
    },
    {
      "x": -7,
      "y": 0,
      "z": -6,
      "name": "Soil_Sand_Black"
    },
    {
      "x": -7,
      "y": 1,
      "z": -6,
      "name": "Wood_Beech_Trunk",
      "support": 15
    },
    {
      "x": -7,
      "y": 2,
      "z": -6,
      "name": "Wood_Hardwood_Planks"
    },
    {
      "x": -7,
      "y": 3,
      "z": -6,
      "name": "Wood_Hardwood_Planks"
    },
    {
      "x": -7,
      "y": 0,
      "z": -5,
      "name": "Soil_Sand_Black"
    },
    {
      "x": -7,
      "y": 1,
      "z": -5,
      "name": "Wood_Beech_Trunk",
      "support": 15
    },
    {
      "x": -7,
      "y": 2,
      "z": -5,
      "name": "Wood_Hardwood_Planks"
    },
    {
      "x": -7,
      "y": 3,
      "z": -5,
      "name": "Wood_Hardwood_Planks"
    },
    {
      "x": -7,
      "y": 0,
      "z": -4,
      "name": "Soil_Sand_Black"
    },
    {
      "x": -7,
      "y": 1,
      "z": -4,
      "name": "Wood_Beech_Trunk",
      "support": 15
    },
    {
      "x": -7,
      "y": 2,
      "z": -4,
      "name": "Wood_Hardwood_Planks"
    },
    {
      "x": -7,
      "y": 3,
      "z": -4,
      "name": "Wood_Hardwood_Planks"
    },
    {
      "x": -7,
      "y": 0,
      "z": -3,
      "name": "Soil_Sand_Black"
    },
    {
      "x": -7,
      "y": 1,
      "z": -3,
      "name": "Wood_Beech_Trunk",
      "support": 15
    },
    {
      "x": -7,
      "y": 2,
      "z": -3,
      "name": "Wood_Hardwood_Planks"
    },
    {
      "x": -7,
      "y": 3,
      "z": -3,
      "name": "Wood_Hardwood_Planks"
    },
    {
      "x": -7,
      "y": 0,
      "z": -2,
      "name": "Soil_Sand_Black"
    },
    {
      "x": -7,
      "y": 1,
      "z": -2,
      "name": "Wood_Beech_Trunk",
      "support": 15
    },
    {
      "x": -7,
      "y": 2,
      "z": -2,
      "name": "Wood_Hardwood_Planks"
    },
    {
      "x": -7,
      "y": 3,
      "z": -2,
      "name": "Wood_Hardwood_Planks"
    },
    {
      "x": -7,
      "y": 0,
      "z": -1,
      "name": "Soil_Sand_Black"
    },
    {
      "x": -7,
      "y": 0,
      "z": 0,
      "name": "Soil_Sand_Black"
    },
    {
      "x": -7,
      "y": 0,
      "z": 1,
      "name": "Soil_Sand_Black"
    },
    {
      "x": -7,
      "y": 0,
      "z": 2,
      "name": "Soil_Sand_Black"
    },
    {
      "x": -7,
      "y": 1,
      "z": 2,
      "name": "Wood_Beech_Trunk",
      "support": 15
    },
    {
      "x": -7,
      "y": 2,
      "z": 2,
      "name": "Wood_Hardwood_Planks"
    },
    {
      "x": -7,
      "y": 3,
      "z": 2,
      "name": "Wood_Hardwood_Planks"
    },
    {
      "x": -7,
      "y": 0,
      "z": 3,
      "name": "Soil_Sand_Black"
    },
    {
      "x": -7,
      "y": 1,
      "z": 3,
      "name": "Wood_Beech_Trunk",
      "support": 15
    },
    {
      "x": -7,
      "y": 2,
      "z": 3,
      "name": "Wood_Hardwood_Planks"
    },
    {
      "x": -7,
      "y": 3,
      "z": 3,
      "name": "Wood_Hardwood_Planks"
    },
    {
      "x": -7,
      "y": 0,
      "z": 4,
      "name": "Soil_Sand_Black"
    },
    {
      "x": -7,
      "y": 1,
      "z": 4,
      "name": "Wood_Beech_Trunk",
      "support": 15
    },
    {
      "x": -7,
      "y": 2,
      "z": 4,
      "name": "Wood_Hardwood_Planks"
    },
    {
      "x": -7,
      "y": 3,
      "z": 4,
      "name": "Wood_Hardwood_Planks"
    },
    {
      "x": -7,
      "y": 0,
      "z": 5,
      "name": "Soil_Sand_Black"
    },
    {
      "x": -7,
      "y": 1,
      "z": 5,
      "name": "Wood_Beech_Trunk",
      "support": 15
    },
    {
      "x": -7,
      "y": 2,
      "z": 5,
      "name": "Wood_Hardwood_Planks"
    },
    {
      "x": -7,
      "y": 3,
      "z": 5,
      "name": "Wood_Hardwood_Planks"
    },
    {
      "x": -7,
      "y": 0,
      "z": 6,
      "name": "Soil_Sand_Black"
    },
    {
      "x": -7,
      "y": 1,
      "z": 6,
      "name": "Wood_Beech_Trunk",
      "support": 15
    },
    {
      "x": -7,
      "y": 2,
      "z": 6,
      "name": "Wood_Hardwood_Planks"
    },
    {
      "x": -7,
      "y": 3,
      "z": 6,
      "name": "Wood_Hardwood_Planks"
    },
    {
      "x": -7,
      "y": 0,
      "z": 7,
      "name": "Soil_Sand_Black"
    },
    {
      "x": -7,
      "y": 3,
      "z": 7,
      "name": "Wood_Deadwood_Roof_Hollow"
    },
    {
      "x": -7,
      "y": 0,
      "z": 8,
      "name": "Soil_Sand_Black"
    },
    {
      "x": -6,
      "y": 0,
      "z": -7,
      "name": "Soil_Sand_Black"
    },
    {
      "x": -6,
      "y": 3,
      "z": -7,
      "name": "Wood_Deadwood_Roof_Hollow",
      "rotation": 2
    },
    {
      "x": -6,
      "y": 0,
      "z": -6,
      "name": "Soil_Sand_Black"
    },
    {
      "x": -6,
      "y": 1,
      "z": -6,
      "name": "Wood_Beech_Trunk",
      "support": 15
    },
    {
      "x": -6,
      "y": 2,
      "z": -6,
      "name": "Wood_Hardwood_Planks"
    },
    {
      "x": -6,
      "y": 3,
      "z": -6,
      "name": "Wood_Hardwood_Planks"
    },
    {
      "x": -6,
      "y": 6,
      "z": -6,
      "name": "*Wood_Deadwood_Roof_Hollow_State_Definitions_Corner_Right",
      "rotation": 3
    },
    {
      "x": -6,
      "y": 0,
      "z": -5,
      "name": "Furniture_Kweebec_Platform",
      "rotation": 1
    },
    {
      "x": -6,
      "y": 1,
      "z": -5,
      "name": "Furniture_Jungle_Torch"
    },
    {
      "x": -6,
      "y": 3,
      "z": -5,
      "name": "Wood_Hardwood_Planks"
    },
    {
      "x": -6,
      "y": 6,
      "z": -5,
      "name": "Wood_Deadwood_Roof_Hollow",
      "rotation": 3
    },
    {
      "x": -6,
      "y": 0,
      "z": -4,
      "name": "Furniture_Kweebec_Platform",
      "rotation": 1
    },
    {
      "x": -6,
      "y": 3,
      "z": -4,
      "name": "Wood_Hardwood_Planks"
    },
    {
      "x": -6,
      "y": 6,
      "z": -4,
      "name": "Wood_Deadwood_Roof_Hollow",
      "rotation": 3
    },
    {
      "x": -6,
      "y": 0,
      "z": -3,
      "name": "Furniture_Kweebec_Platform",
      "rotation": 1
    },
    {
      "x": -6,
      "y": 3,
      "z": -3,
      "name": "Wood_Hardwood_Planks"
    },
    {
      "x": -6,
      "y": 6,
      "z": -3,
      "name": "Wood_Deadwood_Roof_Hollow",
      "rotation": 3
    },
    {
      "x": -6,
      "y": 0,
      "z": -2,
      "name": "Furniture_Kweebec_Platform",
      "rotation": 1
    },
    {
      "x": -6,
      "y": 3,
      "z": -2,
      "name": "Wood_Hardwood_Planks"
    },
    {
      "x": -6,
      "y": 6,
      "z": -2,
      "name": "Wood_Deadwood_Roof_Hollow",
      "rotation": 3
    },
    {
      "x": -6,
      "y": 0,
      "z": -1,
      "name": "Furniture_Kweebec_Platform",
      "rotation": 1
    },
    {
      "x": -6,
      "y": 2,
      "z": -1,
      "name": "Wood_Bamboo_Roots_Deco"
    },
    {
      "x": -6,
      "y": 3,
      "z": -1,
      "name": "Wood_Hardwood_Planks"
    },
    {
      "x": -6,
      "y": 6,
      "z": -1,
      "name": "Wood_Deadwood_Roof_Hollow",
      "rotation": 3
    },
    {
      "x": -6,
      "y": 0,
      "z": 0,
      "name": "Furniture_Kweebec_Platform",
      "rotation": 1
    },
    {
      "x": -6,
      "y": 2,
      "z": 0,
      "name": "Wood_Bamboo_Roots_Deco"
    },
    {
      "x": -6,
      "y": 3,
      "z": 0,
      "name": "Wood_Hardwood_Planks"
    },
    {
      "x": -6,
      "y": 6,
      "z": 0,
      "name": "Wood_Deadwood_Roof_Hollow",
      "rotation": 3
    },
    {
      "x": -6,
      "y": 0,
      "z": 1,
      "name": "Furniture_Kweebec_Platform",
      "rotation": 1
    },
    {
      "x": -6,
      "y": 2,
      "z": 1,
      "name": "Wood_Bamboo_Roots_Deco"
    },
    {
      "x": -6,
      "y": 3,
      "z": 1,
      "name": "Wood_Hardwood_Planks"
    },
    {
      "x": -6,
      "y": 6,
      "z": 1,
      "name": "Wood_Deadwood_Roof_Hollow",
      "rotation": 3
    },
    {
      "x": -6,
      "y": 0,
      "z": 2,
      "name": "Furniture_Kweebec_Platform",
      "rotation": 1
    },
    {
      "x": -6,
      "y": 3,
      "z": 2,
      "name": "Wood_Hardwood_Planks"
    },
    {
      "x": -6,
      "y": 4,
      "z": 2,
      "name": "Plant_Hay_Bundle"
    },
    {
      "x": -6,
      "y": 6,
      "z": 2,
      "name": "Wood_Deadwood_Roof_Hollow",
      "rotation": 3
    },
    {
      "x": -6,
      "y": 0,
      "z": 3,
      "name": "Furniture_Kweebec_Platform",
      "rotation": 1
    },
    {
      "x": -6,
      "y": 3,
      "z": 3,
      "name": "Wood_Hardwood_Planks"
    },
    {
      "x": -6,
      "y": 4,
      "z": 3,
      "name": "Plant_Hay_Bundle"
    },
    {
      "x": -6,
      "y": 6,
      "z": 3,
      "name": "Wood_Deadwood_Roof_Hollow",
      "rotation": 3
    },
    {
      "x": -6,
      "y": 0,
      "z": 4,
      "name": "Furniture_Kweebec_Platform",
      "rotation": 1
    },
    {
      "x": -6,
      "y": 3,
      "z": 4,
      "name": "Wood_Hardwood_Planks"
    },
    {
      "x": -6,
      "y": 6,
      "z": 4,
      "name": "Wood_Deadwood_Roof_Hollow",
      "rotation": 3
    },
    {
      "x": -6,
      "y": 0,
      "z": 5,
      "name": "Furniture_Kweebec_Platform",
      "rotation": 1
    },
    {
      "x": -6,
      "y": 1,
      "z": 5,
      "name": "Furniture_Jungle_Torch"
    },
    {
      "x": -6,
      "y": 3,
      "z": 5,
      "name": "Wood_Hardwood_Planks"
    },
    {
      "x": -6,
      "y": 6,
      "z": 5,
      "name": "Wood_Deadwood_Roof_Hollow",
      "rotation": 3
    },
    {
      "x": -6,
      "y": 0,
      "z": 6,
      "name": "Soil_Sand_Black"
    },
    {
      "x": -6,
      "y": 1,
      "z": 6,
      "name": "Wood_Beech_Trunk",
      "support": 15
    },
    {
      "x": -6,
      "y": 2,
      "z": 6,
      "name": "Wood_Hardwood_Planks"
    },
    {
      "x": -6,
      "y": 3,
      "z": 6,
      "name": "Wood_Hardwood_Planks"
    },
    {
      "x": -6,
      "y": 6,
      "z": 6,
      "name": "*Wood_Deadwood_Roof_Hollow_State_Definitions_Corner_Right"
    },
    {
      "x": -6,
      "y": 0,
      "z": 7,
      "name": "Soil_Sand_Black"
    },
    {
      "x": -6,
      "y": 3,
      "z": 7,
      "name": "Wood_Deadwood_Roof_Hollow"
    },
    {
      "x": -6,
      "y": 0,
      "z": 8,
      "name": "Soil_Sand_Black"
    },
    {
      "x": -5,
      "y": 0,
      "z": -7,
      "name": "Soil_Sand_Black"
    },
    {
      "x": -5,
      "y": 3,
      "z": -7,
      "name": "Wood_Deadwood_Roof_Hollow",
      "rotation": 2
    },
    {
      "x": -5,
      "y": 0,
      "z": -6,
      "name": "Soil_Sand_Black"
    },
    {
      "x": -5,
      "y": 1,
      "z": -6,
      "name": "Wood_Beech_Trunk",
      "support": 15
    },
    {
      "x": -5,
      "y": 2,
      "z": -6,
      "name": "Wood_Hardwood_Planks"
    },
    {
      "x": -5,
      "y": 3,
      "z": -6,
      "name": "Wood_Hardwood_Planks"
    },
    {
      "x": -5,
      "y": 6,
      "z": -6,
      "name": "Wood_Deadwood_Roof_Hollow",
      "rotation": 2
    },
    {
      "x": -5,
      "y": 0,
      "z": -5,
      "name": "Furniture_Kweebec_Platform",
      "rotation": 1
    },
    {
      "x": -5,
      "y": 3,
      "z": -5,
      "name": "Wood_Hardwood_Planks"
    },
    {
      "x": -5,
      "y": 4,
      "z": -5,
      "name": "Wood_Beech_Trunk",
      "support": 15
    },
    {
      "x": -5,
      "y": 5,
      "z": -5,
      "name": "Wood_Hardwood_Planks"
    },
    {
      "x": -5,
      "y": 6,
      "z": -5,
      "name": "Wood_Hardwood_Planks"
    },
    {
      "x": -5,
      "y": 7,
      "z": -5,
      "name": "*Wood_Deadwood_Roof_State_Definitions_Corner_Left",
      "rotation": 2
    },
    {
      "x": -5,
      "y": 0,
      "z": -4,
      "name": "Furniture_Kweebec_Platform",
      "rotation": 1
    },
    {
      "x": -5,
      "y": 3,
      "z": -4,
      "name": "Wood_Hardwood_Planks"
    },
    {
      "x": -5,
      "y": 4,
      "z": -4,
      "name": "Wood_Beech_Trunk",
      "support": 15
    },
    {
      "x": -5,
      "y": 5,
      "z": -4,
      "name": "Wood_Hardwood_Planks"
    },
    {
      "x": -5,
      "y": 6,
      "z": -4,
      "name": "Wood_Hardwood_Planks"
    },
    {
      "x": -5,
      "y": 7,
      "z": -4,
      "name": "Wood_Deadwood_Roof",
      "rotation": 3
    },
    {
      "x": -5,
      "y": 8,
      "z": -4,
      "name": "Plant_Leaves_Bamboo",
      "support": 15
    },
    {
      "x": -5,
      "y": 0,
      "z": -3,
      "name": "Furniture_Kweebec_Platform",
      "rotation": 1
    },
    {
      "x": -5,
      "y": 3,
      "z": -3,
      "name": "Wood_Hardwood_Planks"
    },
    {
      "x": -5,
      "y": 4,
      "z": -3,
      "name": "Wood_Beech_Trunk",
      "support": 15
    },
    {
      "x": -5,
      "y": 5,
      "z": -3,
      "name": "Wood_Hardwood_Planks"
    },
    {
      "x": -5,
      "y": 6,
      "z": -3,
      "name": "Wood_Hardwood_Planks"
    },
    {
      "x": -5,
      "y": 7,
      "z": -3,
      "name": "Wood_Deadwood_Roof",
      "rotation": 3
    },
    {
      "x": -5,
      "y": 8,
      "z": -3,
      "name": "Plant_Leaves_Bamboo",
      "support": 15
    },
    {
      "x": -5,
      "y": 0,
      "z": -2,
      "name": "Furniture_Kweebec_Platform",
      "rotation": 1
    },
    {
      "x": -5,
      "y": 3,
      "z": -2,
      "name": "Wood_Hardwood_Planks"
    },
    {
      "x": -5,
      "y": 4,
      "z": -2,
      "name": "Wood_Beech_Trunk",
      "support": 15
    },
    {
      "x": -5,
      "y": 5,
      "z": -2,
      "name": "Wood_Hardwood_Planks"
    },
    {
      "x": -5,
      "y": 6,
      "z": -2,
      "name": "Wood_Hardwood_Planks"
    },
    {
      "x": -5,
      "y": 7,
      "z": -2,
      "name": "Wood_Deadwood_Roof",
      "rotation": 3
    },
    {
      "x": -5,
      "y": 0,
      "z": -1,
      "name": "Furniture_Kweebec_Platform",
      "rotation": 1
    },
    {
      "x": -5,
      "y": 3,
      "z": -1,
      "name": "Wood_Hardwood_Planks"
    },
    {
      "x": -5,
      "y": 4,
      "z": -1,
      "name": "Wood_Beech_Trunk",
      "support": 15
    },
    {
      "x": -5,
      "y": 5,
      "z": -1,
      "name": "Furniture_Jungle_Window",
      "rotation": 1
    },
    {
      "x": -5,
      "y": 6,
      "z": -1,
      "name": "Furniture_Jungle_Window",
      "rotation": 1
    },
    {
      "x": -5,
      "y": 7,
      "z": -1,
      "name": "Wood_Deadwood_Roof",
      "rotation": 3
    },
    {
      "x": -5,
      "y": 0,
      "z": 0,
      "name": "Furniture_Kweebec_Platform",
      "rotation": 1
    },
    {
      "x": -5,
      "y": 3,
      "z": 0,
      "name": "Wood_Hardwood_Planks"
    },
    {
      "x": -5,
      "y": 4,
      "z": 0,
      "name": "Wood_Beech_Trunk",
      "support": 15
    },
    {
      "x": -5,
      "y": 5,
      "z": 0,
      "name": "Furniture_Jungle_Window",
      "rotation": 1
    },
    {
      "x": -5,
      "y": 6,
      "z": 0,
      "name": "Furniture_Jungle_Window",
      "rotation": 1
    },
    {
      "x": -5,
      "y": 7,
      "z": 0,
      "name": "Wood_Deadwood_Roof",
      "rotation": 3
    },
    {
      "x": -5,
      "y": 0,
      "z": 1,
      "name": "Furniture_Kweebec_Platform",
      "rotation": 1
    },
    {
      "x": -5,
      "y": 3,
      "z": 1,
      "name": "Wood_Hardwood_Planks"
    },
    {
      "x": -5,
      "y": 4,
      "z": 1,
      "name": "Wood_Beech_Trunk",
      "support": 15
    },
    {
      "x": -5,
      "y": 5,
      "z": 1,
      "name": "Furniture_Jungle_Window",
      "rotation": 1
    },
    {
      "x": -5,
      "y": 6,
      "z": 1,
      "name": "Furniture_Jungle_Window",
      "rotation": 1
    },
    {
      "x": -5,
      "y": 7,
      "z": 1,
      "name": "Wood_Deadwood_Roof",
      "rotation": 3
    },
    {
      "x": -5,
      "y": 0,
      "z": 2,
      "name": "Furniture_Kweebec_Platform",
      "rotation": 1
    },
    {
      "x": -5,
      "y": 3,
      "z": 2,
      "name": "Wood_Hardwood_Planks"
    },
    {
      "x": -5,
      "y": 4,
      "z": 2,
      "name": "Wood_Beech_Trunk",
      "support": 15
    },
    {
      "x": -5,
      "y": 5,
      "z": 2,
      "name": "Wood_Hardwood_Planks"
    },
    {
      "x": -5,
      "y": 6,
      "z": 2,
      "name": "Wood_Hardwood_Planks"
    },
    {
      "x": -5,
      "y": 7,
      "z": 2,
      "name": "Wood_Deadwood_Roof",
      "rotation": 3
    },
    {
      "x": -5,
      "y": 0,
      "z": 3,
      "name": "Furniture_Kweebec_Platform",
      "rotation": 1
    },
    {
      "x": -5,
      "y": 3,
      "z": 3,
      "name": "Wood_Hardwood_Planks"
    },
    {
      "x": -5,
      "y": 4,
      "z": 3,
      "name": "Wood_Beech_Trunk",
      "support": 15
    },
    {
      "x": -5,
      "y": 5,
      "z": 3,
      "name": "Wood_Hardwood_Planks"
    },
    {
      "x": -5,
      "y": 6,
      "z": 3,
      "name": "Wood_Hardwood_Planks"
    },
    {
      "x": -5,
      "y": 7,
      "z": 3,
      "name": "Wood_Deadwood_Roof",
      "rotation": 3
    },
    {
      "x": -5,
      "y": 8,
      "z": 3,
      "name": "Plant_Leaves_Bamboo",
      "support": 15
    },
    {
      "x": -5,
      "y": 0,
      "z": 4,
      "name": "Furniture_Kweebec_Platform",
      "rotation": 1
    },
    {
      "x": -5,
      "y": 3,
      "z": 4,
      "name": "Wood_Hardwood_Planks"
    },
    {
      "x": -5,
      "y": 4,
      "z": 4,
      "name": "Wood_Beech_Trunk",
      "support": 15
    },
    {
      "x": -5,
      "y": 5,
      "z": 4,
      "name": "Wood_Hardwood_Planks"
    },
    {
      "x": -5,
      "y": 6,
      "z": 4,
      "name": "Wood_Hardwood_Planks"
    },
    {
      "x": -5,
      "y": 7,
      "z": 4,
      "name": "Wood_Deadwood_Roof",
      "rotation": 3
    },
    {
      "x": -5,
      "y": 0,
      "z": 5,
      "name": "Furniture_Kweebec_Platform",
      "rotation": 1
    },
    {
      "x": -5,
      "y": 3,
      "z": 5,
      "name": "Wood_Hardwood_Planks"
    },
    {
      "x": -5,
      "y": 4,
      "z": 5,
      "name": "Wood_Beech_Trunk",
      "support": 15
    },
    {
      "x": -5,
      "y": 5,
      "z": 5,
      "name": "Wood_Hardwood_Planks"
    },
    {
      "x": -5,
      "y": 6,
      "z": 5,
      "name": "Wood_Hardwood_Planks"
    },
    {
      "x": -5,
      "y": 7,
      "z": 5,
      "name": "*Wood_Deadwood_Roof_State_Definitions_Corner_Right"
    },
    {
      "x": -5,
      "y": 0,
      "z": 6,
      "name": "Soil_Sand_Black"
    },
    {
      "x": -5,
      "y": 1,
      "z": 6,
      "name": "Wood_Beech_Trunk",
      "support": 15
    },
    {
      "x": -5,
      "y": 2,
      "z": 6,
      "name": "Wood_Hardwood_Planks"
    },
    {
      "x": -5,
      "y": 3,
      "z": 6,
      "name": "Wood_Hardwood_Planks"
    },
    {
      "x": -5,
      "y": 6,
      "z": 6,
      "name": "Wood_Deadwood_Roof_Hollow"
    },
    {
      "x": -5,
      "y": 0,
      "z": 7,
      "name": "Soil_Sand_Black"
    },
    {
      "x": -5,
      "y": 1,
      "z": 7,
      "name": "Plant_Leaves_Bamboo",
      "support": 15
    },
    {
      "x": -5,
      "y": 3,
      "z": 7,
      "name": "Wood_Deadwood_Roof_Hollow"
    },
    {
      "x": -5,
      "y": 0,
      "z": 8,
      "name": "Soil_Sand_Black"
    },
    {
      "x": -4,
      "y": 0,
      "z": -7,
      "name": "Soil_Sand_Black"
    },
    {
      "x": -4,
      "y": 1,
      "z": -7,
      "name": "Plant_Leaves_Bamboo",
      "support": 15
    },
    {
      "x": -4,
      "y": 3,
      "z": -7,
      "name": "Wood_Deadwood_Roof_Hollow",
      "rotation": 2
    },
    {
      "x": -4,
      "y": 0,
      "z": -6,
      "name": "Soil_Sand_Black"
    },
    {
      "x": -4,
      "y": 1,
      "z": -6,
      "name": "Wood_Beech_Trunk",
      "support": 15
    },
    {
      "x": -4,
      "y": 2,
      "z": -6,
      "name": "Wood_Hardwood_Planks"
    },
    {
      "x": -4,
      "y": 3,
      "z": -6,
      "name": "Wood_Hardwood_Planks"
    },
    {
      "x": -4,
      "y": 6,
      "z": -6,
      "name": "Wood_Deadwood_Roof_Hollow",
      "rotation": 2
    },
    {
      "x": -4,
      "y": 0,
      "z": -5,
      "name": "Furniture_Kweebec_Platform",
      "rotation": 1
    },
    {
      "x": -4,
      "y": 3,
      "z": -5,
      "name": "Wood_Hardwood_Planks"
    },
    {
      "x": -4,
      "y": 4,
      "z": -5,
      "name": "Wood_Beech_Trunk",
      "support": 15
    },
    {
      "x": -4,
      "y": 5,
      "z": -5,
      "name": "Wood_Hardwood_Planks"
    },
    {
      "x": -4,
      "y": 6,
      "z": -5,
      "name": "Wood_Hardwood_Planks"
    },
    {
      "x": -4,
      "y": 7,
      "z": -5,
      "name": "Wood_Deadwood_Roof",
      "rotation": 2
    },
    {
      "x": -4,
      "y": 0,
      "z": -4,
      "name": "Furniture_Kweebec_Platform",
      "rotation": 1
    },
    {
      "x": -4,
      "y": 3,
      "z": -4,
      "name": "Wood_Hardwood_Planks"
    },
    {
      "x": -4,
      "y": 4,
      "z": -4,
      "name": "Furniture_Jungle_Torch"
    },
    {
      "x": -4,
      "y": 7,
      "z": -4,
      "name": "Wood_Hardwood_Planks"
    },
    {
      "x": -4,
      "y": 8,
      "z": -4,
      "name": "*Wood_Deadwood_Roof_State_Definitions_Corner_Left",
      "rotation": 2
    },
    {
      "x": -4,
      "y": 0,
      "z": -3,
      "name": "Furniture_Kweebec_Platform",
      "rotation": 1
    },
    {
      "x": -4,
      "y": 3,
      "z": -3,
      "name": "Wood_Hardwood_Planks"
    },
    {
      "x": -4,
      "y": 7,
      "z": -3,
      "name": "Wood_Hardwood_Planks"
    },
    {
      "x": -4,
      "y": 8,
      "z": -3,
      "name": "Wood_Deadwood_Roof",
      "rotation": 3
    },
    {
      "x": -4,
      "y": 0,
      "z": -2,
      "name": "Furniture_Kweebec_Platform",
      "rotation": 1
    },
    {
      "x": -4,
      "y": 3,
      "z": -2,
      "name": "Wood_Hardwood_Planks"
    },
    {
      "x": -4,
      "y": 7,
      "z": -2,
      "name": "Wood_Hardwood_Planks"
    },
    {
      "x": -4,
      "y": 8,
      "z": -2,
      "name": "Wood_Deadwood_Roof",
      "rotation": 3
    },
    {
      "x": -4,
      "y": 0,
      "z": -1,
      "name": "Furniture_Kweebec_Platform",
      "rotation": 1
    },
    {
      "x": -4,
      "y": 3,
      "z": -1,
      "name": "Wood_Hardwood_Planks"
    },
    {
      "x": -4,
      "y": 7,
      "z": -1,
      "name": "Wood_Hardwood_Planks"
    },
    {
      "x": -4,
      "y": 8,
      "z": -1,
      "name": "Wood_Deadwood_Roof",
      "rotation": 3
    },
    {
      "x": -4,
      "y": 0,
      "z": 0,
      "name": "Furniture_Kweebec_Platform",
      "rotation": 1
    },
    {
      "x": -4,
      "y": 3,
      "z": 0,
      "name": "Wood_Hardwood_Planks"
    },
    {
      "x": -4,
      "y": 7,
      "z": 0,
      "name": "Wood_Hardwood_Planks"
    },
    {
      "x": -4,
      "y": 8,
      "z": 0,
      "name": "Wood_Deadwood_Roof",
      "rotation": 3
    },
    {
      "x": -4,
      "y": 0,
      "z": 1,
      "name": "Furniture_Kweebec_Platform",
      "rotation": 1
    },
    {
      "x": -4,
      "y": 3,
      "z": 1,
      "name": "Wood_Hardwood_Planks"
    },
    {
      "x": -4,
      "y": 7,
      "z": 1,
      "name": "Wood_Hardwood_Planks"
    },
    {
      "x": -4,
      "y": 8,
      "z": 1,
      "name": "Wood_Deadwood_Roof",
      "rotation": 3
    },
    {
      "x": -4,
      "y": 0,
      "z": 2,
      "name": "Furniture_Kweebec_Platform",
      "rotation": 1
    },
    {
      "x": -4,
      "y": 3,
      "z": 2,
      "name": "Wood_Hardwood_Planks"
    },
    {
      "x": -4,
      "y": 7,
      "z": 2,
      "name": "Wood_Hardwood_Planks"
    },
    {
      "x": -4,
      "y": 8,
      "z": 2,
      "name": "Wood_Deadwood_Roof",
      "rotation": 3
    },
    {
      "x": -4,
      "y": 0,
      "z": 3,
      "name": "Furniture_Kweebec_Platform",
      "rotation": 1
    },
    {
      "x": -4,
      "y": 3,
      "z": 3,
      "name": "Wood_Hardwood_Planks"
    },
    {
      "x": -4,
      "y": 7,
      "z": 3,
      "name": "Wood_Hardwood_Planks"
    },
    {
      "x": -4,
      "y": 8,
      "z": 3,
      "name": "Wood_Deadwood_Roof",
      "rotation": 3
    },
    {
      "x": -4,
      "y": 0,
      "z": 4,
      "name": "Furniture_Kweebec_Platform",
      "rotation": 1
    },
    {
      "x": -4,
      "y": 3,
      "z": 4,
      "name": "Wood_Hardwood_Planks"
    },
    {
      "x": -4,
      "y": 4,
      "z": 4,
      "name": "Furniture_Jungle_Torch"
    },
    {
      "x": -4,
      "y": 7,
      "z": 4,
      "name": "Wood_Hardwood_Planks"
    },
    {
      "x": -4,
      "y": 8,
      "z": 4,
      "name": "*Wood_Deadwood_Roof_State_Definitions_Corner_Right"
    },
    {
      "x": -4,
      "y": 0,
      "z": 5,
      "name": "Furniture_Kweebec_Platform",
      "rotation": 1
    },
    {
      "x": -4,
      "y": 3,
      "z": 5,
      "name": "Wood_Hardwood_Planks"
    },
    {
      "x": -4,
      "y": 4,
      "z": 5,
      "name": "Wood_Beech_Trunk",
      "support": 15
    },
    {
      "x": -4,
      "y": 5,
      "z": 5,
      "name": "Wood_Hardwood_Planks"
    },
    {
      "x": -4,
      "y": 6,
      "z": 5,
      "name": "Wood_Hardwood_Planks"
    },
    {
      "x": -4,
      "y": 7,
      "z": 5,
      "name": "Wood_Deadwood_Roof"
    },
    {
      "x": -4,
      "y": 0,
      "z": 6,
      "name": "Soil_Sand_Black"
    },
    {
      "x": -4,
      "y": 1,
      "z": 6,
      "name": "Wood_Beech_Trunk",
      "support": 15
    },
    {
      "x": -4,
      "y": 2,
      "z": 6,
      "name": "Wood_Hardwood_Planks"
    },
    {
      "x": -4,
      "y": 3,
      "z": 6,
      "name": "Wood_Hardwood_Planks"
    },
    {
      "x": -4,
      "y": 6,
      "z": 6,
      "name": "Wood_Deadwood_Roof_Hollow"
    },
    {
      "x": -4,
      "y": 0,
      "z": 7,
      "name": "Soil_Sand_Black"
    },
    {
      "x": -4,
      "y": 3,
      "z": 7,
      "name": "Wood_Deadwood_Roof_Hollow"
    },
    {
      "x": -4,
      "y": 0,
      "z": 8,
      "name": "Soil_Sand_Black"
    },
    {
      "x": -3,
      "y": 0,
      "z": -7,
      "name": "Soil_Sand_Black"
    },
    {
      "x": -3,
      "y": 3,
      "z": -7,
      "name": "Wood_Deadwood_Roof_Hollow",
      "rotation": 2
    },
    {
      "x": -3,
      "y": 0,
      "z": -6,
      "name": "Soil_Sand_Black"
    },
    {
      "x": -3,
      "y": 1,
      "z": -6,
      "name": "Wood_Beech_Trunk",
      "support": 15
    },
    {
      "x": -3,
      "y": 2,
      "z": -6,
      "name": "Furniture_Jungle_Window"
    },
    {
      "x": -3,
      "y": 3,
      "z": -6,
      "name": "Wood_Hardwood_Planks"
    },
    {
      "x": -3,
      "y": 6,
      "z": -6,
      "name": "Wood_Deadwood_Roof_Hollow",
      "rotation": 2
    },
    {
      "x": -3,
      "y": 0,
      "z": -5,
      "name": "Furniture_Kweebec_Platform",
      "rotation": 1
    },
    {
      "x": -3,
      "y": 3,
      "z": -5,
      "name": "Wood_Hardwood_Planks"
    },
    {
      "x": -3,
      "y": 4,
      "z": -5,
      "name": "Wood_Beech_Trunk",
      "support": 15
    },
    {
      "x": -3,
      "y": 5,
      "z": -5,
      "name": "Wood_Hardwood_Planks"
    },
    {
      "x": -3,
      "y": 6,
      "z": -5,
      "name": "Wood_Hardwood_Planks"
    },
    {
      "x": -3,
      "y": 7,
      "z": -5,
      "name": "Wood_Deadwood_Roof",
      "rotation": 2
    },
    {
      "x": -3,
      "y": 0,
      "z": -4,
      "name": "Furniture_Kweebec_Platform",
      "rotation": 1
    },
    {
      "x": -3,
      "y": 3,
      "z": -4,
      "name": "Wood_Hardwood_Planks"
    },
    {
      "x": -3,
      "y": 7,
      "z": -4,
      "name": "Wood_Hardwood_Planks"
    },
    {
      "x": -3,
      "y": 8,
      "z": -4,
      "name": "Wood_Deadwood_Roof",
      "rotation": 2
    },
    {
      "x": -3,
      "y": 0,
      "z": -3,
      "name": "Furniture_Kweebec_Platform",
      "rotation": 1
    },
    {
      "x": -3,
      "y": 3,
      "z": -3,
      "name": "Wood_Hardwood_Planks"
    },
    {
      "x": -3,
      "y": 8,
      "z": -3,
      "name": "Wood_Hardwood_Planks"
    },
    {
      "x": -3,
      "y": 9,
      "z": -3,
      "name": "*Wood_Deadwood_Roof_State_Definitions_Corner_Left",
      "rotation": 2
    },
    {
      "x": -3,
      "y": 0,
      "z": -2,
      "name": "Furniture_Kweebec_Platform",
      "rotation": 1
    },
    {
      "x": -3,
      "y": 3,
      "z": -2,
      "name": "Wood_Hardwood_Planks"
    },
    {
      "x": -3,
      "y": 8,
      "z": -2,
      "name": "Wood_Hardwood_Planks"
    },
    {
      "x": -3,
      "y": 9,
      "z": -2,
      "name": "Wood_Deadwood_Roof",
      "rotation": 3
    },
    {
      "x": -3,
      "y": 0,
      "z": -1,
      "name": "Furniture_Kweebec_Platform",
      "rotation": 1
    },
    {
      "x": -3,
      "y": 3,
      "z": -1,
      "name": "Wood_Hardwood_Planks"
    },
    {
      "x": -3,
      "y": 8,
      "z": -1,
      "name": "Wood_Hardwood_Planks"
    },
    {
      "x": -3,
      "y": 9,
      "z": -1,
      "name": "Wood_Deadwood_Roof",
      "rotation": 3
    },
    {
      "x": -3,
      "y": 0,
      "z": 0,
      "name": "Furniture_Kweebec_Platform",
      "rotation": 1
    },
    {
      "x": -3,
      "y": 3,
      "z": 0,
      "name": "Wood_Hardwood_Planks"
    },
    {
      "x": -3,
      "y": 8,
      "z": 0,
      "name": "Wood_Hardwood_Planks"
    },
    {
      "x": -3,
      "y": 9,
      "z": 0,
      "name": "Wood_Deadwood_Roof",
      "rotation": 3
    },
    {
      "x": -3,
      "y": 0,
      "z": 1,
      "name": "Furniture_Kweebec_Platform",
      "rotation": 1
    },
    {
      "x": -3,
      "y": 3,
      "z": 1,
      "name": "Wood_Hardwood_Planks"
    },
    {
      "x": -3,
      "y": 8,
      "z": 1,
      "name": "Wood_Hardwood_Planks"
    },
    {
      "x": -3,
      "y": 9,
      "z": 1,
      "name": "Wood_Deadwood_Roof",
      "rotation": 3
    },
    {
      "x": -3,
      "y": 0,
      "z": 2,
      "name": "Furniture_Kweebec_Platform",
      "rotation": 1
    },
    {
      "x": -3,
      "y": 3,
      "z": 2,
      "name": "Wood_Hardwood_Planks"
    },
    {
      "x": -3,
      "y": 8,
      "z": 2,
      "name": "Wood_Hardwood_Planks"
    },
    {
      "x": -3,
      "y": 9,
      "z": 2,
      "name": "Wood_Deadwood_Roof",
      "rotation": 3
    },
    {
      "x": -3,
      "y": 0,
      "z": 3,
      "name": "Furniture_Kweebec_Platform",
      "rotation": 1
    },
    {
      "x": -3,
      "y": 3,
      "z": 3,
      "name": "Wood_Hardwood_Planks"
    },
    {
      "x": -3,
      "y": 8,
      "z": 3,
      "name": "Wood_Hardwood_Planks"
    },
    {
      "x": -3,
      "y": 9,
      "z": 3,
      "name": "*Wood_Deadwood_Roof_State_Definitions_Corner_Left",
      "rotation": 3
    },
    {
      "x": -3,
      "y": 0,
      "z": 4,
      "name": "Furniture_Kweebec_Platform",
      "rotation": 1
    },
    {
      "x": -3,
      "y": 3,
      "z": 4,
      "name": "Wood_Hardwood_Planks"
    },
    {
      "x": -3,
      "y": 7,
      "z": 4,
      "name": "Wood_Hardwood_Planks"
    },
    {
      "x": -3,
      "y": 8,
      "z": 4,
      "name": "Wood_Deadwood_Roof"
    },
    {
      "x": -3,
      "y": 0,
      "z": 5,
      "name": "Furniture_Kweebec_Platform",
      "rotation": 1
    },
    {
      "x": -3,
      "y": 3,
      "z": 5,
      "name": "Wood_Hardwood_Planks"
    },
    {
      "x": -3,
      "y": 4,
      "z": 5,
      "name": "Wood_Beech_Trunk",
      "support": 15
    },
    {
      "x": -3,
      "y": 5,
      "z": 5,
      "name": "Wood_Hardwood_Planks"
    },
    {
      "x": -3,
      "y": 6,
      "z": 5,
      "name": "Wood_Hardwood_Planks"
    },
    {
      "x": -3,
      "y": 7,
      "z": 5,
      "name": "Wood_Deadwood_Roof"
    },
    {
      "x": -3,
      "y": 0,
      "z": 6,
      "name": "Soil_Sand_Black"
    },
    {
      "x": -3,
      "y": 1,
      "z": 6,
      "name": "Wood_Beech_Trunk",
      "support": 15
    },
    {
      "x": -3,
      "y": 2,
      "z": 6,
      "name": "Wood_Hardwood_Planks"
    },
    {
      "x": -3,
      "y": 3,
      "z": 6,
      "name": "Wood_Hardwood_Planks"
    },
    {
      "x": -3,
      "y": 6,
      "z": 6,
      "name": "Wood_Deadwood_Roof_Hollow"
    },
    {
      "x": -3,
      "y": 0,
      "z": 7,
      "name": "Soil_Sand_Black"
    },
    {
      "x": -3,
      "y": 3,
      "z": 7,
      "name": "Wood_Deadwood_Roof_Hollow"
    },
    {
      "x": -3,
      "y": 0,
      "z": 8,
      "name": "Soil_Sand_Black"
    },
    {
      "x": -2,
      "y": 0,
      "z": -7,
      "name": "Soil_Sand_Black"
    },
    {
      "x": -2,
      "y": 3,
      "z": -7,
      "name": "Wood_Deadwood_Roof_Hollow",
      "rotation": 2
    },
    {
      "x": -2,
      "y": 0,
      "z": -6,
      "name": "Soil_Sand_Black"
    },
    {
      "x": -2,
      "y": 1,
      "z": -6,
      "name": "Wood_Beech_Trunk",
      "support": 15
    },
    {
      "x": -2,
      "y": 2,
      "z": -6,
      "name": "Furniture_Jungle_Window"
    },
    {
      "x": -2,
      "y": 3,
      "z": -6,
      "name": "Wood_Hardwood_Planks"
    },
    {
      "x": -2,
      "y": 6,
      "z": -6,
      "name": "Wood_Deadwood_Roof_Hollow",
      "rotation": 2
    },
    {
      "x": -2,
      "y": 0,
      "z": -5,
      "name": "Furniture_Kweebec_Platform",
      "rotation": 1
    },
    {
      "x": -2,
      "y": 3,
      "z": -5,
      "name": "Wood_Hardwood_Planks"
    },
    {
      "x": -2,
      "y": 4,
      "z": -5,
      "name": "Wood_Beech_Trunk",
      "support": 15
    },
    {
      "x": -2,
      "y": 5,
      "z": -5,
      "name": "Wood_Hardwood_Planks"
    },
    {
      "x": -2,
      "y": 6,
      "z": -5,
      "name": "Wood_Hardwood_Planks"
    },
    {
      "x": -2,
      "y": 7,
      "z": -5,
      "name": "Wood_Deadwood_Roof",
      "rotation": 2
    },
    {
      "x": -2,
      "y": 0,
      "z": -4,
      "name": "Furniture_Kweebec_Platform",
      "rotation": 1
    },
    {
      "x": -2,
      "y": 3,
      "z": -4,
      "name": "Wood_Hardwood_Planks"
    },
    {
      "x": -2,
      "y": 7,
      "z": -4,
      "name": "Wood_Hardwood_Planks"
    },
    {
      "x": -2,
      "y": 8,
      "z": -4,
      "name": "Wood_Deadwood_Roof",
      "rotation": 2
    },
    {
      "x": -2,
      "y": 0,
      "z": -3,
      "name": "Furniture_Kweebec_Platform",
      "rotation": 1
    },
    {
      "x": -2,
      "y": 3,
      "z": -3,
      "name": "Wood_Hardwood_Planks"
    },
    {
      "x": -2,
      "y": 8,
      "z": -3,
      "name": "Wood_Hardwood_Planks"
    },
    {
      "x": -2,
      "y": 9,
      "z": -3,
      "name": "Wood_Deadwood_Roof",
      "rotation": 2
    },
    {
      "x": -2,
      "y": 0,
      "z": -2,
      "name": "Furniture_Kweebec_Platform",
      "rotation": 1
    },
    {
      "x": -2,
      "y": 3,
      "z": -2,
      "name": "Wood_Hardwood_Planks"
    },
    {
      "x": -2,
      "y": 8,
      "z": -2,
      "name": "Wood_Hardwood_Planks"
    },
    {
      "x": -2,
      "y": 9,
      "z": -2,
      "name": "Ingredient_Hay"
    },
    {
      "x": -2,
      "y": 10,
      "z": -2,
      "name": "Plant_Leaves_Bamboo",
      "support": 15
    },
    {
      "x": -2,
      "y": 0,
      "z": -1,
      "name": "Furniture_Kweebec_Platform",
      "rotation": 1
    },
    {
      "x": -2,
      "y": 3,
      "z": -1,
      "name": "Wood_Hardwood_Planks"
    },
    {
      "x": -2,
      "y": 8,
      "z": -1,
      "name": "Wood_Hardwood_Planks"
    },
    {
      "x": -2,
      "y": 9,
      "z": -1,
      "name": "Ingredient_Hay"
    },
    {
      "x": -2,
      "y": 10,
      "z": -1,
      "name": "Plant_Leaves_Bamboo",
      "support": 15
    },
    {
      "x": -2,
      "y": 0,
      "z": 0,
      "name": "Furniture_Kweebec_Platform",
      "rotation": 1
    },
    {
      "x": -2,
      "y": 3,
      "z": 0,
      "name": "Wood_Hardwood_Planks"
    },
    {
      "x": -2,
      "y": 8,
      "z": 0,
      "name": "Wood_Hardwood_Planks"
    },
    {
      "x": -2,
      "y": 9,
      "z": 0,
      "name": "Ingredient_Hay"
    },
    {
      "x": -2,
      "y": 10,
      "z": 0,
      "name": "Plant_Hay_Bundle"
    },
    {
      "x": -2,
      "y": 0,
      "z": 1,
      "name": "Furniture_Kweebec_Platform",
      "rotation": 1
    },
    {
      "x": -2,
      "y": 3,
      "z": 1,
      "name": "Wood_Hardwood_Planks"
    },
    {
      "x": -2,
      "y": 8,
      "z": 1,
      "name": "Wood_Hardwood_Planks"
    },
    {
      "x": -2,
      "y": 9,
      "z": 1,
      "name": "Ingredient_Hay"
    },
    {
      "x": -2,
      "y": 10,
      "z": 1,
      "name": "Plant_Leaves_Bamboo",
      "support": 15
    },
    {
      "x": -2,
      "y": 0,
      "z": 2,
      "name": "Furniture_Kweebec_Platform",
      "rotation": 1
    },
    {
      "x": -2,
      "y": 3,
      "z": 2,
      "name": "Wood_Hardwood_Planks"
    },
    {
      "x": -2,
      "y": 8,
      "z": 2,
      "name": "Wood_Hardwood_Planks"
    },
    {
      "x": -2,
      "y": 9,
      "z": 2,
      "name": "Ingredient_Hay"
    },
    {
      "x": -2,
      "y": 10,
      "z": 2,
      "name": "Plant_Leaves_Bamboo",
      "support": 15
    },
    {
      "x": -2,
      "y": 0,
      "z": 3,
      "name": "Furniture_Kweebec_Platform",
      "rotation": 1
    },
    {
      "x": -2,
      "y": 3,
      "z": 3,
      "name": "Wood_Hardwood_Planks"
    },
    {
      "x": -2,
      "y": 8,
      "z": 3,
      "name": "Wood_Hardwood_Planks"
    },
    {
      "x": -2,
      "y": 9,
      "z": 3,
      "name": "Wood_Deadwood_Roof"
    },
    {
      "x": -2,
      "y": 10,
      "z": 3,
      "name": "Plant_Leaves_Bamboo",
      "support": 15
    },
    {
      "x": -2,
      "y": 0,
      "z": 4,
      "name": "Furniture_Kweebec_Platform",
      "rotation": 1
    },
    {
      "x": -2,
      "y": 3,
      "z": 4,
      "name": "Wood_Hardwood_Planks"
    },
    {
      "x": -2,
      "y": 7,
      "z": 4,
      "name": "Wood_Hardwood_Planks"
    },
    {
      "x": -2,
      "y": 8,
      "z": 4,
      "name": "Wood_Deadwood_Roof"
    },
    {
      "x": -2,
      "y": 0,
      "z": 5,
      "name": "Furniture_Kweebec_Platform",
      "rotation": 1
    },
    {
      "x": -2,
      "y": 3,
      "z": 5,
      "name": "Wood_Hardwood_Planks"
    },
    {
      "x": -2,
      "y": 4,
      "z": 5,
      "name": "Wood_Beech_Trunk",
      "support": 15
    },
    {
      "x": -2,
      "y": 5,
      "z": 5,
      "name": "Wood_Hardwood_Planks"
    },
    {
      "x": -2,
      "y": 6,
      "z": 5,
      "name": "Wood_Hardwood_Planks"
    },
    {
      "x": -2,
      "y": 7,
      "z": 5,
      "name": "Wood_Deadwood_Roof"
    },
    {
      "x": -2,
      "y": 0,
      "z": 6,
      "name": "Soil_Sand_Black"
    },
    {
      "x": -2,
      "y": 1,
      "z": 6,
      "name": "Wood_Beech_Trunk",
      "support": 15
    },
    {
      "x": -2,
      "y": 2,
      "z": 6,
      "name": "Furniture_Jungle_Window"
    },
    {
      "x": -2,
      "y": 3,
      "z": 6,
      "name": "Wood_Hardwood_Planks"
    },
    {
      "x": -2,
      "y": 4,
      "z": 6,
      "name": "Plant_Leaves_Bamboo",
      "support": 15
    },
    {
      "x": -2,
      "y": 6,
      "z": 6,
      "name": "Wood_Deadwood_Roof_Hollow"
    },
    {
      "x": -2,
      "y": 0,
      "z": 7,
      "name": "Soil_Sand_Black"
    },
    {
      "x": -2,
      "y": 3,
      "z": 7,
      "name": "Wood_Deadwood_Roof_Hollow"
    },
    {
      "x": -2,
      "y": 0,
      "z": 8,
      "name": "Soil_Sand_Black"
    },
    {
      "x": -1,
      "y": 0,
      "z": -7,
      "name": "Soil_Sand_Black"
    },
    {
      "x": -1,
      "y": 3,
      "z": -7,
      "name": "Wood_Deadwood_Roof_Hollow",
      "rotation": 2
    },
    {
      "x": -1,
      "y": 0,
      "z": -6,
      "name": "Soil_Sand_Black"
    },
    {
      "x": -1,
      "y": 1,
      "z": -6,
      "name": "Wood_Beech_Trunk",
      "support": 15
    },
    {
      "x": -1,
      "y": 2,
      "z": -6,
      "name": "Wood_Hardwood_Planks"
    },
    {
      "x": -1,
      "y": 3,
      "z": -6,
      "name": "Wood_Hardwood_Planks"
    },
    {
      "x": -1,
      "y": 6,
      "z": -6,
      "name": "Wood_Deadwood_Roof_Hollow",
      "rotation": 2
    },
    {
      "x": -1,
      "y": 0,
      "z": -5,
      "name": "Furniture_Kweebec_Platform",
      "rotation": 1
    },
    {
      "x": -1,
      "y": 3,
      "z": -5,
      "name": "Wood_Hardwood_Planks"
    },
    {
      "x": -1,
      "y": 4,
      "z": -5,
      "name": "Wood_Beech_Trunk",
      "support": 15
    },
    {
      "x": -1,
      "y": 5,
      "z": -5,
      "name": "Wood_Hardwood_Planks"
    },
    {
      "x": -1,
      "y": 6,
      "z": -5,
      "name": "Wood_Hardwood_Planks"
    },
    {
      "x": -1,
      "y": 7,
      "z": -5,
      "name": "Wood_Deadwood_Roof",
      "rotation": 2
    },
    {
      "x": -1,
      "y": 0,
      "z": -4,
      "name": "Furniture_Kweebec_Platform",
      "rotation": 1
    },
    {
      "x": -1,
      "y": 3,
      "z": -4,
      "name": "Wood_Hardwood_Planks"
    },
    {
      "x": -1,
      "y": 7,
      "z": -4,
      "name": "Wood_Hardwood_Planks"
    },
    {
      "x": -1,
      "y": 8,
      "z": -4,
      "name": "Wood_Deadwood_Roof",
      "rotation": 2
    },
    {
      "x": -1,
      "y": 0,
      "z": -3,
      "name": "Furniture_Kweebec_Platform",
      "rotation": 1
    },
    {
      "x": -1,
      "y": 3,
      "z": -3,
      "name": "Wood_Hardwood_Planks"
    },
    {
      "x": -1,
      "y": 8,
      "z": -3,
      "name": "Wood_Hardwood_Planks"
    },
    {
      "x": -1,
      "y": 9,
      "z": -3,
      "name": "Wood_Deadwood_Roof",
      "rotation": 2
    },
    {
      "x": -1,
      "y": 0,
      "z": -2,
      "name": "Furniture_Kweebec_Platform",
      "rotation": 1
    },
    {
      "x": -1,
      "y": 3,
      "z": -2,
      "name": "Wood_Hardwood_Planks"
    },
    {
      "x": -1,
      "y": 8,
      "z": -2,
      "name": "Wood_Hardwood_Planks"
    },
    {
      "x": -1,
      "y": 9,
      "z": -2,
      "name": "Ingredient_Hay"
    },
    {
      "x": -1,
      "y": 0,
      "z": -1,
      "name": "Furniture_Kweebec_Platform",
      "rotation": 1
    },
    {
      "x": -1,
      "y": 3,
      "z": -1,
      "name": "Wood_Hardwood_Planks"
    },
    {
      "x": -1,
      "y": 8,
      "z": -1,
      "name": "Wood_Hardwood_Planks"
    },
    {
      "x": -1,
      "y": 9,
      "z": -1,
      "name": "Ingredient_Hay"
    },
    {
      "x": -1,
      "y": 10,
      "z": -1,
      "name": "Plant_Hay_Bundle"
    },
    {
      "x": -1,
      "y": 0,
      "z": 0,
      "name": "Furniture_Kweebec_Platform",
      "rotation": 1
    },
    {
      "x": -1,
      "y": 3,
      "z": 0,
      "name": "Wood_Hardwood_Planks"
    },
    {
      "x": -1,
      "y": 8,
      "z": 0,
      "name": "Wood_Hardwood_Planks"
    },
    {
      "x": -1,
      "y": 9,
      "z": 0,
      "name": "Ingredient_Hay"
    },
    {
      "x": -1,
      "y": 10,
      "z": 0,
      "name": "Plant_Hay_Bundle"
    },
    {
      "x": -1,
      "y": 0,
      "z": 1,
      "name": "Furniture_Kweebec_Platform",
      "rotation": 1
    },
    {
      "x": -1,
      "y": 3,
      "z": 1,
      "name": "Wood_Hardwood_Planks"
    },
    {
      "x": -1,
      "y": 8,
      "z": 1,
      "name": "Wood_Hardwood_Planks"
    },
    {
      "x": -1,
      "y": 9,
      "z": 1,
      "name": "Ingredient_Hay"
    },
    {
      "x": -1,
      "y": 10,
      "z": 1,
      "name": "Plant_Hay_Bundle"
    },
    {
      "x": -1,
      "y": 0,
      "z": 2,
      "name": "Furniture_Kweebec_Platform",
      "rotation": 1
    },
    {
      "x": -1,
      "y": 3,
      "z": 2,
      "name": "Wood_Hardwood_Planks"
    },
    {
      "x": -1,
      "y": 8,
      "z": 2,
      "name": "Wood_Hardwood_Planks"
    },
    {
      "x": -1,
      "y": 9,
      "z": 2,
      "name": "Ingredient_Hay"
    },
    {
      "x": -1,
      "y": 10,
      "z": 2,
      "name": "Plant_Hay_Bundle"
    },
    {
      "x": -1,
      "y": 0,
      "z": 3,
      "name": "Furniture_Kweebec_Platform",
      "rotation": 1
    },
    {
      "x": -1,
      "y": 3,
      "z": 3,
      "name": "Wood_Hardwood_Planks"
    },
    {
      "x": -1,
      "y": 8,
      "z": 3,
      "name": "Wood_Hardwood_Planks"
    },
    {
      "x": -1,
      "y": 9,
      "z": 3,
      "name": "Wood_Deadwood_Roof"
    },
    {
      "x": -1,
      "y": 0,
      "z": 4,
      "name": "Furniture_Kweebec_Platform",
      "rotation": 1
    },
    {
      "x": -1,
      "y": 3,
      "z": 4,
      "name": "Wood_Hardwood_Planks"
    },
    {
      "x": -1,
      "y": 7,
      "z": 4,
      "name": "Wood_Hardwood_Planks"
    },
    {
      "x": -1,
      "y": 8,
      "z": 4,
      "name": "Wood_Deadwood_Roof"
    },
    {
      "x": -1,
      "y": 0,
      "z": 5,
      "name": "Furniture_Kweebec_Platform",
      "rotation": 1
    },
    {
      "x": -1,
      "y": 3,
      "z": 5,
      "name": "Wood_Hardwood_Planks"
    },
    {
      "x": -1,
      "y": 4,
      "z": 5,
      "name": "Wood_Beech_Trunk",
      "support": 15
    },
    {
      "x": -1,
      "y": 5,
      "z": 5,
      "name": "Wood_Hardwood_Planks"
    },
    {
      "x": -1,
      "y": 6,
      "z": 5,
      "name": "Wood_Hardwood_Planks"
    },
    {
      "x": -1,
      "y": 7,
      "z": 5,
      "name": "Wood_Deadwood_Roof"
    },
    {
      "x": -1,
      "y": 0,
      "z": 6,
      "name": "Soil_Sand_Black"
    },
    {
      "x": -1,
      "y": 1,
      "z": 6,
      "name": "Wood_Beech_Trunk",
      "support": 15
    },
    {
      "x": -1,
      "y": 2,
      "z": 6,
      "name": "Furniture_Jungle_Window"
    },
    {
      "x": -1,
      "y": 3,
      "z": 6,
      "name": "Wood_Hardwood_Planks"
    },
    {
      "x": -1,
      "y": 6,
      "z": 6,
      "name": "Wood_Deadwood_Roof_Hollow"
    },
    {
      "x": -1,
      "y": 0,
      "z": 7,
      "name": "Soil_Sand_Black"
    },
    {
      "x": -1,
      "y": 3,
      "z": 7,
      "name": "Wood_Deadwood_Roof_Hollow"
    },
    {
      "x": -1,
      "y": 0,
      "z": 8,
      "name": "Soil_Sand_Black"
    },
    {
      "x": 0,
      "y": 0,
      "z": -7,
      "name": "Soil_Sand_Black"
    },
    {
      "x": 0,
      "y": 3,
      "z": -7,
      "name": "Wood_Deadwood_Roof_Hollow",
      "rotation": 2
    },
    {
      "x": 0,
      "y": 0,
      "z": -6,
      "name": "Soil_Sand_Black"
    },
    {
      "x": 0,
      "y": 1,
      "z": -6,
      "name": "Wood_Beech_Trunk",
      "support": 15
    },
    {
      "x": 0,
      "y": 2,
      "z": -6,
      "name": "Wood_Hardwood_Planks"
    },
    {
      "x": 0,
      "y": 3,
      "z": -6,
      "name": "Wood_Hardwood_Planks"
    },
    {
      "x": 0,
      "y": 6,
      "z": -6,
      "name": "Wood_Deadwood_Roof_Hollow",
      "rotation": 2
    },
    {
      "x": 0,
      "y": 0,
      "z": -5,
      "name": "Furniture_Kweebec_Platform",
      "rotation": 1
    },
    {
      "x": 0,
      "y": 3,
      "z": -5,
      "name": "Wood_Hardwood_Planks"
    },
    {
      "x": 0,
      "y": 4,
      "z": -5,
      "name": "Wood_Beech_Trunk",
      "support": 15
    },
    {
      "x": 0,
      "y": 5,
      "z": -5,
      "name": "Furniture_Jungle_Window"
    },
    {
      "x": 0,
      "y": 6,
      "z": -5,
      "name": "Furniture_Jungle_Window"
    },
    {
      "x": 0,
      "y": 7,
      "z": -5,
      "name": "Wood_Deadwood_Roof",
      "rotation": 2
    },
    {
      "x": 0,
      "y": 8,
      "z": -5,
      "name": "Plant_Leaves_Bamboo",
      "support": 15
    },
    {
      "x": 0,
      "y": 0,
      "z": -4,
      "name": "Furniture_Kweebec_Platform",
      "rotation": 1
    },
    {
      "x": 0,
      "y": 3,
      "z": -4,
      "name": "Wood_Hardwood_Planks"
    },
    {
      "x": 0,
      "y": 7,
      "z": -4,
      "name": "Wood_Hardwood_Planks"
    },
    {
      "x": 0,
      "y": 8,
      "z": -4,
      "name": "Wood_Deadwood_Roof",
      "rotation": 2
    },
    {
      "x": 0,
      "y": 0,
      "z": -3,
      "name": "Furniture_Kweebec_Platform",
      "rotation": 1
    },
    {
      "x": 0,
      "y": 3,
      "z": -3,
      "name": "Wood_Hardwood_Planks"
    },
    {
      "x": 0,
      "y": 8,
      "z": -3,
      "name": "Wood_Hardwood_Planks"
    },
    {
      "x": 0,
      "y": 9,
      "z": -3,
      "name": "Wood_Deadwood_Roof",
      "rotation": 2
    },
    {
      "x": 0,
      "y": 0,
      "z": -2,
      "name": "Furniture_Kweebec_Platform",
      "rotation": 1
    },
    {
      "x": 0,
      "y": 3,
      "z": -2,
      "name": "Wood_Hardwood_Planks"
    },
    {
      "x": 0,
      "y": 8,
      "z": -2,
      "name": "Wood_Hardwood_Planks"
    },
    {
      "x": 0,
      "y": 9,
      "z": -2,
      "name": "Ingredient_Hay"
    },
    {
      "x": 0,
      "y": 10,
      "z": -2,
      "name": "Plant_Leaves_Bamboo",
      "support": 15
    },
    {
      "x": 0,
      "y": 0,
      "z": -1,
      "name": "Furniture_Kweebec_Platform",
      "rotation": 1
    },
    {
      "x": 0,
      "y": 3,
      "z": -1,
      "name": "Wood_Hardwood_Planks"
    },
    {
      "x": 0,
      "y": 8,
      "z": -1,
      "name": "Wood_Hardwood_Planks"
    },
    {
      "x": 0,
      "y": 9,
      "z": -1,
      "name": "Ingredient_Hay"
    },
    {
      "x": 0,
      "y": 10,
      "z": -1,
      "name": "Plant_Leaves_Bamboo",
      "support": 15
    },
    {
      "x": 0,
      "y": 0,
      "z": 0,
      "name": "Furniture_Kweebec_Platform",
      "rotation": 1
    },
    {
      "x": 0,
      "y": 3,
      "z": 0,
      "name": "Wood_Hardwood_Planks"
    },
    {
      "x": 0,
      "y": 8,
      "z": 0,
      "name": "Wood_Hardwood_Planks"
    },
    {
      "x": 0,
      "y": 9,
      "z": 0,
      "name": "Ingredient_Hay"
    },
    {
      "x": 0,
      "y": 10,
      "z": 0,
      "name": "Plant_Leaves_Bamboo",
      "support": 15
    },
    {
      "x": 0,
      "y": 0,
      "z": 1,
      "name": "Furniture_Kweebec_Platform",
      "rotation": 1
    },
    {
      "x": 0,
      "y": 3,
      "z": 1,
      "name": "Wood_Hardwood_Planks"
    },
    {
      "x": 0,
      "y": 8,
      "z": 1,
      "name": "Wood_Hardwood_Planks"
    },
    {
      "x": 0,
      "y": 9,
      "z": 1,
      "name": "Ingredient_Hay"
    },
    {
      "x": 0,
      "y": 10,
      "z": 1,
      "name": "Plant_Leaves_Bamboo",
      "support": 15
    },
    {
      "x": 0,
      "y": 0,
      "z": 2,
      "name": "Furniture_Kweebec_Platform",
      "rotation": 1
    },
    {
      "x": 0,
      "y": 3,
      "z": 2,
      "name": "Wood_Hardwood_Planks"
    },
    {
      "x": 0,
      "y": 8,
      "z": 2,
      "name": "Wood_Hardwood_Planks"
    },
    {
      "x": 0,
      "y": 9,
      "z": 2,
      "name": "Ingredient_Hay"
    },
    {
      "x": 0,
      "y": 10,
      "z": 2,
      "name": "Plant_Hay_Bundle"
    },
    {
      "x": 0,
      "y": 0,
      "z": 3,
      "name": "Furniture_Kweebec_Platform",
      "rotation": 1
    },
    {
      "x": 0,
      "y": 3,
      "z": 3,
      "name": "Wood_Hardwood_Planks"
    },
    {
      "x": 0,
      "y": 8,
      "z": 3,
      "name": "Wood_Hardwood_Planks"
    },
    {
      "x": 0,
      "y": 9,
      "z": 3,
      "name": "Wood_Deadwood_Roof"
    },
    {
      "x": 0,
      "y": 0,
      "z": 4,
      "name": "Furniture_Kweebec_Platform",
      "rotation": 1
    },
    {
      "x": 0,
      "y": 3,
      "z": 4,
      "name": "Wood_Hardwood_Planks"
    },
    {
      "x": 0,
      "y": 7,
      "z": 4,
      "name": "Wood_Hardwood_Planks"
    },
    {
      "x": 0,
      "y": 8,
      "z": 4,
      "name": "Wood_Deadwood_Roof"
    },
    {
      "x": 0,
      "y": 0,
      "z": 5,
      "name": "Furniture_Kweebec_Platform",
      "rotation": 1
    },
    {
      "x": 0,
      "y": 3,
      "z": 5,
      "name": "Wood_Hardwood_Planks"
    },
    {
      "x": 0,
      "y": 4,
      "z": 5,
      "name": "Wood_Beech_Trunk",
      "support": 15
    },
    {
      "x": 0,
      "y": 5,
      "z": 5,
      "name": "Furniture_Jungle_Window"
    },
    {
      "x": 0,
      "y": 6,
      "z": 5,
      "name": "Furniture_Jungle_Window"
    },
    {
      "x": 0,
      "y": 7,
      "z": 5,
      "name": "Wood_Deadwood_Roof"
    },
    {
      "x": 0,
      "y": 0,
      "z": 6,
      "name": "Soil_Sand_Black"
    },
    {
      "x": 0,
      "y": 1,
      "z": 6,
      "name": "Wood_Beech_Trunk",
      "support": 15
    },
    {
      "x": 0,
      "y": 2,
      "z": 6,
      "name": "Wood_Hardwood_Planks"
    },
    {
      "x": 0,
      "y": 3,
      "z": 6,
      "name": "Wood_Hardwood_Planks"
    },
    {
      "x": 0,
      "y": 6,
      "z": 6,
      "name": "Wood_Deadwood_Roof_Hollow"
    },
    {
      "x": 0,
      "y": 0,
      "z": 7,
      "name": "Soil_Sand_Black"
    },
    {
      "x": 0,
      "y": 3,
      "z": 7,
      "name": "Wood_Deadwood_Roof_Hollow"
    },
    {
      "x": 0,
      "y": 0,
      "z": 8,
      "name": "Soil_Sand_Black"
    },
    {
      "x": 1,
      "y": 0,
      "z": -7,
      "name": "Soil_Sand_Black"
    },
    {
      "x": 1,
      "y": 3,
      "z": -7,
      "name": "Wood_Deadwood_Roof_Hollow",
      "rotation": 2
    },
    {
      "x": 1,
      "y": 0,
      "z": -6,
      "name": "Soil_Sand_Black"
    },
    {
      "x": 1,
      "y": 1,
      "z": -6,
      "name": "Wood_Beech_Trunk",
      "support": 15
    },
    {
      "x": 1,
      "y": 2,
      "z": -6,
      "name": "Wood_Hardwood_Planks"
    },
    {
      "x": 1,
      "y": 3,
      "z": -6,
      "name": "Wood_Hardwood_Planks"
    },
    {
      "x": 1,
      "y": 5,
      "z": -6,
      "name": "Plant_Leaves_Bamboo",
      "support": 15
    },
    {
      "x": 1,
      "y": 6,
      "z": -6,
      "name": "Wood_Deadwood_Roof_Hollow",
      "rotation": 2
    },
    {
      "x": 1,
      "y": 0,
      "z": -5,
      "name": "Furniture_Kweebec_Platform",
      "rotation": 1
    },
    {
      "x": 1,
      "y": 3,
      "z": -5,
      "name": "Wood_Hardwood_Planks"
    },
    {
      "x": 1,
      "y": 4,
      "z": -5,
      "name": "Wood_Beech_Trunk",
      "support": 15
    },
    {
      "x": 1,
      "y": 5,
      "z": -5,
      "name": "Furniture_Jungle_Window"
    },
    {
      "x": 1,
      "y": 6,
      "z": -5,
      "name": "Furniture_Jungle_Window"
    },
    {
      "x": 1,
      "y": 7,
      "z": -5,
      "name": "Wood_Deadwood_Roof",
      "rotation": 2
    },
    {
      "x": 1,
      "y": 0,
      "z": -4,
      "name": "Furniture_Kweebec_Platform",
      "rotation": 1
    },
    {
      "x": 1,
      "y": 3,
      "z": -4,
      "name": "Wood_Hardwood_Planks"
    },
    {
      "x": 1,
      "y": 7,
      "z": -4,
      "name": "Wood_Hardwood_Planks"
    },
    {
      "x": 1,
      "y": 8,
      "z": -4,
      "name": "Wood_Deadwood_Roof",
      "rotation": 2
    },
    {
      "x": 1,
      "y": 0,
      "z": -3,
      "name": "Furniture_Kweebec_Platform",
      "rotation": 1
    },
    {
      "x": 1,
      "y": 3,
      "z": -3,
      "name": "Wood_Hardwood_Planks"
    },
    {
      "x": 1,
      "y": 8,
      "z": -3,
      "name": "Wood_Hardwood_Planks"
    },
    {
      "x": 1,
      "y": 9,
      "z": -3,
      "name": "Wood_Deadwood_Roof",
      "rotation": 2
    },
    {
      "x": 1,
      "y": 0,
      "z": -2,
      "name": "Furniture_Kweebec_Platform",
      "rotation": 1
    },
    {
      "x": 1,
      "y": 3,
      "z": -2,
      "name": "Wood_Hardwood_Planks"
    },
    {
      "x": 1,
      "y": 8,
      "z": -2,
      "name": "Wood_Hardwood_Planks"
    },
    {
      "x": 1,
      "y": 9,
      "z": -2,
      "name": "Ingredient_Hay"
    },
    {
      "x": 1,
      "y": 10,
      "z": -2,
      "name": "Plant_Leaves_Bamboo",
      "support": 15
    },
    {
      "x": 1,
      "y": 0,
      "z": -1,
      "name": "Furniture_Kweebec_Platform",
      "rotation": 1
    },
    {
      "x": 1,
      "y": 3,
      "z": -1,
      "name": "Wood_Hardwood_Planks"
    },
    {
      "x": 1,
      "y": 8,
      "z": -1,
      "name": "Wood_Hardwood_Planks"
    },
    {
      "x": 1,
      "y": 9,
      "z": -1,
      "name": "Ingredient_Hay"
    },
    {
      "x": 1,
      "y": 10,
      "z": -1,
      "name": "Plant_Leaves_Bamboo",
      "support": 15
    },
    {
      "x": 1,
      "y": 0,
      "z": 0,
      "name": "Furniture_Kweebec_Platform",
      "rotation": 1
    },
    {
      "x": 1,
      "y": 3,
      "z": 0,
      "name": "Wood_Hardwood_Planks"
    },
    {
      "x": 1,
      "y": 8,
      "z": 0,
      "name": "Wood_Hardwood_Planks"
    },
    {
      "x": 1,
      "y": 9,
      "z": 0,
      "name": "Ingredient_Hay"
    },
    {
      "x": 1,
      "y": 10,
      "z": 0,
      "name": "Plant_Leaves_Bamboo",
      "support": 15
    },
    {
      "x": 1,
      "y": 0,
      "z": 1,
      "name": "Furniture_Kweebec_Platform",
      "rotation": 1
    },
    {
      "x": 1,
      "y": 3,
      "z": 1,
      "name": "Wood_Hardwood_Planks"
    },
    {
      "x": 1,
      "y": 8,
      "z": 1,
      "name": "Wood_Hardwood_Planks"
    },
    {
      "x": 1,
      "y": 9,
      "z": 1,
      "name": "Ingredient_Hay"
    },
    {
      "x": 1,
      "y": 10,
      "z": 1,
      "name": "Plant_Hay_Bundle"
    },
    {
      "x": 1,
      "y": 0,
      "z": 2,
      "name": "Furniture_Kweebec_Platform",
      "rotation": 1
    },
    {
      "x": 1,
      "y": 3,
      "z": 2,
      "name": "Wood_Hardwood_Planks"
    },
    {
      "x": 1,
      "y": 8,
      "z": 2,
      "name": "Wood_Hardwood_Planks"
    },
    {
      "x": 1,
      "y": 9,
      "z": 2,
      "name": "Ingredient_Hay"
    },
    {
      "x": 1,
      "y": 10,
      "z": 2,
      "name": "Plant_Leaves_Bamboo",
      "support": 15
    },
    {
      "x": 1,
      "y": 0,
      "z": 3,
      "name": "Furniture_Kweebec_Platform",
      "rotation": 1
    },
    {
      "x": 1,
      "y": 3,
      "z": 3,
      "name": "Wood_Hardwood_Planks"
    },
    {
      "x": 1,
      "y": 8,
      "z": 3,
      "name": "Wood_Hardwood_Planks"
    },
    {
      "x": 1,
      "y": 9,
      "z": 3,
      "name": "Wood_Deadwood_Roof"
    },
    {
      "x": 1,
      "y": 0,
      "z": 4,
      "name": "Furniture_Kweebec_Platform",
      "rotation": 1
    },
    {
      "x": 1,
      "y": 3,
      "z": 4,
      "name": "Wood_Hardwood_Planks"
    },
    {
      "x": 1,
      "y": 7,
      "z": 4,
      "name": "Wood_Hardwood_Planks"
    },
    {
      "x": 1,
      "y": 8,
      "z": 4,
      "name": "Wood_Deadwood_Roof"
    },
    {
      "x": 1,
      "y": 0,
      "z": 5,
      "name": "Furniture_Kweebec_Platform",
      "rotation": 1
    },
    {
      "x": 1,
      "y": 3,
      "z": 5,
      "name": "Wood_Hardwood_Planks"
    },
    {
      "x": 1,
      "y": 4,
      "z": 5,
      "name": "Wood_Beech_Trunk",
      "support": 15
    },
    {
      "x": 1,
      "y": 5,
      "z": 5,
      "name": "Furniture_Jungle_Window"
    },
    {
      "x": 1,
      "y": 6,
      "z": 5,
      "name": "Furniture_Jungle_Window"
    },
    {
      "x": 1,
      "y": 7,
      "z": 5,
      "name": "Wood_Deadwood_Roof"
    },
    {
      "x": 1,
      "y": 0,
      "z": 6,
      "name": "Soil_Sand_Black"
    },
    {
      "x": 1,
      "y": 1,
      "z": 6,
      "name": "Wood_Beech_Trunk",
      "support": 15
    },
    {
      "x": 1,
      "y": 2,
      "z": 6,
      "name": "Wood_Hardwood_Planks"
    },
    {
      "x": 1,
      "y": 3,
      "z": 6,
      "name": "Wood_Hardwood_Planks"
    },
    {
      "x": 1,
      "y": 6,
      "z": 6,
      "name": "Wood_Deadwood_Roof_Hollow"
    },
    {
      "x": 1,
      "y": 0,
      "z": 7,
      "name": "Soil_Sand_Black"
    },
    {
      "x": 1,
      "y": 3,
      "z": 7,
      "name": "Wood_Deadwood_Roof_Hollow"
    },
    {
      "x": 1,
      "y": 0,
      "z": 8,
      "name": "Soil_Sand_Black"
    },
    {
      "x": 1,
      "y": 3,
      "z": 8,
      "name": "Plant_Leaves_Bamboo",
      "support": 15
    },
    {
      "x": 2,
      "y": 0,
      "z": -7,
      "name": "Soil_Sand_Black"
    },
    {
      "x": 2,
      "y": 3,
      "z": -7,
      "name": "Wood_Deadwood_Roof_Hollow",
      "rotation": 2
    },
    {
      "x": 2,
      "y": 0,
      "z": -6,
      "name": "Soil_Sand_Black"
    },
    {
      "x": 2,
      "y": 1,
      "z": -6,
      "name": "Wood_Beech_Trunk",
      "support": 15
    },
    {
      "x": 2,
      "y": 2,
      "z": -6,
      "name": "Wood_Hardwood_Planks"
    },
    {
      "x": 2,
      "y": 3,
      "z": -6,
      "name": "Wood_Hardwood_Planks"
    },
    {
      "x": 2,
      "y": 6,
      "z": -6,
      "name": "Wood_Deadwood_Roof_Hollow",
      "rotation": 2
    },
    {
      "x": 2,
      "y": 0,
      "z": -5,
      "name": "Furniture_Kweebec_Platform",
      "rotation": 1
    },
    {
      "x": 2,
      "y": 3,
      "z": -5,
      "name": "Wood_Hardwood_Planks"
    },
    {
      "x": 2,
      "y": 4,
      "z": -5,
      "name": "Wood_Beech_Trunk",
      "support": 15
    },
    {
      "x": 2,
      "y": 5,
      "z": -5,
      "name": "Wood_Hardwood_Planks"
    },
    {
      "x": 2,
      "y": 6,
      "z": -5,
      "name": "Wood_Hardwood_Planks"
    },
    {
      "x": 2,
      "y": 7,
      "z": -5,
      "name": "Wood_Deadwood_Roof",
      "rotation": 2
    },
    {
      "x": 2,
      "y": 0,
      "z": -4,
      "name": "Furniture_Kweebec_Platform",
      "rotation": 1
    },
    {
      "x": 2,
      "y": 3,
      "z": -4,
      "name": "Wood_Hardwood_Planks"
    },
    {
      "x": 2,
      "y": 7,
      "z": -4,
      "name": "Wood_Hardwood_Planks"
    },
    {
      "x": 2,
      "y": 8,
      "z": -4,
      "name": "Wood_Deadwood_Roof",
      "rotation": 2
    },
    {
      "x": 2,
      "y": 0,
      "z": -3,
      "name": "Furniture_Kweebec_Platform",
      "rotation": 1
    },
    {
      "x": 2,
      "y": 3,
      "z": -3,
      "name": "Wood_Hardwood_Planks"
    },
    {
      "x": 2,
      "y": 8,
      "z": -3,
      "name": "Wood_Hardwood_Planks"
    },
    {
      "x": 2,
      "y": 9,
      "z": -3,
      "name": "Wood_Deadwood_Roof",
      "rotation": 2
    },
    {
      "x": 2,
      "y": 0,
      "z": -2,
      "name": "Furniture_Kweebec_Platform",
      "rotation": 1
    },
    {
      "x": 2,
      "y": 3,
      "z": -2,
      "name": "Wood_Hardwood_Planks"
    },
    {
      "x": 2,
      "y": 8,
      "z": -2,
      "name": "Wood_Hardwood_Planks"
    },
    {
      "x": 2,
      "y": 9,
      "z": -2,
      "name": "Ingredient_Hay"
    },
    {
      "x": 2,
      "y": 10,
      "z": -2,
      "name": "Plant_Leaves_Bamboo",
      "support": 15
    },
    {
      "x": 2,
      "y": 0,
      "z": -1,
      "name": "Furniture_Kweebec_Platform",
      "rotation": 1
    },
    {
      "x": 2,
      "y": 3,
      "z": -1,
      "name": "Wood_Hardwood_Planks"
    },
    {
      "x": 2,
      "y": 8,
      "z": -1,
      "name": "Wood_Hardwood_Planks"
    },
    {
      "x": 2,
      "y": 9,
      "z": -1,
      "name": "Ingredient_Hay"
    },
    {
      "x": 2,
      "y": 0,
      "z": 0,
      "name": "Furniture_Kweebec_Platform",
      "rotation": 1
    },
    {
      "x": 2,
      "y": 3,
      "z": 0,
      "name": "Wood_Hardwood_Planks"
    },
    {
      "x": 2,
      "y": 8,
      "z": 0,
      "name": "Wood_Hardwood_Planks"
    },
    {
      "x": 2,
      "y": 9,
      "z": 0,
      "name": "Ingredient_Hay"
    },
    {
      "x": 2,
      "y": 0,
      "z": 1,
      "name": "Furniture_Kweebec_Platform",
      "rotation": 1
    },
    {
      "x": 2,
      "y": 3,
      "z": 1,
      "name": "Wood_Hardwood_Planks"
    },
    {
      "x": 2,
      "y": 8,
      "z": 1,
      "name": "Wood_Hardwood_Planks"
    },
    {
      "x": 2,
      "y": 9,
      "z": 1,
      "name": "Ingredient_Hay"
    },
    {
      "x": 2,
      "y": 10,
      "z": 1,
      "name": "Plant_Leaves_Bamboo",
      "support": 15
    },
    {
      "x": 2,
      "y": 0,
      "z": 2,
      "name": "Furniture_Kweebec_Platform",
      "rotation": 1
    },
    {
      "x": 2,
      "y": 3,
      "z": 2,
      "name": "Wood_Hardwood_Planks"
    },
    {
      "x": 2,
      "y": 8,
      "z": 2,
      "name": "Wood_Hardwood_Planks"
    },
    {
      "x": 2,
      "y": 9,
      "z": 2,
      "name": "Ingredient_Hay"
    },
    {
      "x": 2,
      "y": 0,
      "z": 3,
      "name": "Furniture_Kweebec_Platform",
      "rotation": 1
    },
    {
      "x": 2,
      "y": 3,
      "z": 3,
      "name": "Wood_Hardwood_Planks"
    },
    {
      "x": 2,
      "y": 8,
      "z": 3,
      "name": "Wood_Hardwood_Planks"
    },
    {
      "x": 2,
      "y": 9,
      "z": 3,
      "name": "Wood_Deadwood_Roof"
    },
    {
      "x": 2,
      "y": 0,
      "z": 4,
      "name": "Furniture_Kweebec_Platform",
      "rotation": 1
    },
    {
      "x": 2,
      "y": 3,
      "z": 4,
      "name": "Wood_Hardwood_Planks"
    },
    {
      "x": 2,
      "y": 7,
      "z": 4,
      "name": "Wood_Hardwood_Planks"
    },
    {
      "x": 2,
      "y": 8,
      "z": 4,
      "name": "Wood_Deadwood_Roof"
    },
    {
      "x": 2,
      "y": 0,
      "z": 5,
      "name": "Furniture_Kweebec_Platform",
      "rotation": 1
    },
    {
      "x": 2,
      "y": 3,
      "z": 5,
      "name": "Wood_Hardwood_Planks"
    },
    {
      "x": 2,
      "y": 4,
      "z": 5,
      "name": "Wood_Beech_Trunk",
      "support": 15
    },
    {
      "x": 2,
      "y": 5,
      "z": 5,
      "name": "Wood_Hardwood_Planks"
    },
    {
      "x": 2,
      "y": 6,
      "z": 5,
      "name": "Wood_Hardwood_Planks"
    },
    {
      "x": 2,
      "y": 7,
      "z": 5,
      "name": "Wood_Deadwood_Roof"
    },
    {
      "x": 2,
      "y": 0,
      "z": 6,
      "name": "Soil_Sand_Black"
    },
    {
      "x": 2,
      "y": 1,
      "z": 6,
      "name": "Wood_Beech_Trunk",
      "support": 15
    },
    {
      "x": 2,
      "y": 2,
      "z": 6,
      "name": "Wood_Hardwood_Planks"
    },
    {
      "x": 2,
      "y": 3,
      "z": 6,
      "name": "Wood_Hardwood_Planks"
    },
    {
      "x": 2,
      "y": 6,
      "z": 6,
      "name": "Wood_Deadwood_Roof_Hollow"
    },
    {
      "x": 2,
      "y": 0,
      "z": 7,
      "name": "Soil_Sand_Black"
    },
    {
      "x": 2,
      "y": 3,
      "z": 7,
      "name": "Wood_Deadwood_Roof_Hollow"
    },
    {
      "x": 2,
      "y": 0,
      "z": 8,
      "name": "Soil_Sand_Black"
    },
    {
      "x": 3,
      "y": 0,
      "z": -7,
      "name": "Soil_Sand_Black"
    },
    {
      "x": 3,
      "y": 3,
      "z": -7,
      "name": "Wood_Deadwood_Roof_Hollow",
      "rotation": 2
    },
    {
      "x": 3,
      "y": 0,
      "z": -6,
      "name": "Soil_Sand_Black"
    },
    {
      "x": 3,
      "y": 1,
      "z": -6,
      "name": "Wood_Beech_Trunk",
      "support": 15
    },
    {
      "x": 3,
      "y": 2,
      "z": -6,
      "name": "Wood_Hardwood_Planks"
    },
    {
      "x": 3,
      "y": 3,
      "z": -6,
      "name": "Wood_Hardwood_Planks"
    },
    {
      "x": 3,
      "y": 6,
      "z": -6,
      "name": "Wood_Deadwood_Roof_Hollow",
      "rotation": 2
    },
    {
      "x": 3,
      "y": 0,
      "z": -5,
      "name": "Furniture_Kweebec_Platform",
      "rotation": 1
    },
    {
      "x": 3,
      "y": 1,
      "z": -5,
      "name": "Furniture_Jungle_Torch"
    },
    {
      "x": 3,
      "y": 3,
      "z": -5,
      "name": "Wood_Hardwood_Planks"
    },
    {
      "x": 3,
      "y": 4,
      "z": -5,
      "name": "Wood_Beech_Trunk",
      "support": 15
    },
    {
      "x": 3,
      "y": 5,
      "z": -5,
      "name": "Wood_Hardwood_Planks"
    },
    {
      "x": 3,
      "y": 6,
      "z": -5,
      "name": "Wood_Hardwood_Planks"
    },
    {
      "x": 3,
      "y": 7,
      "z": -5,
      "name": "Wood_Deadwood_Roof",
      "rotation": 2
    },
    {
      "x": 3,
      "y": 0,
      "z": -4,
      "name": "Furniture_Kweebec_Platform",
      "rotation": 1
    },
    {
      "x": 3,
      "y": 3,
      "z": -4,
      "name": "Wood_Hardwood_Planks"
    },
    {
      "x": 3,
      "y": 7,
      "z": -4,
      "name": "Wood_Hardwood_Planks"
    },
    {
      "x": 3,
      "y": 8,
      "z": -4,
      "name": "Wood_Deadwood_Roof",
      "rotation": 2
    },
    {
      "x": 3,
      "y": 0,
      "z": -3,
      "name": "Furniture_Kweebec_Platform",
      "rotation": 1
    },
    {
      "x": 3,
      "y": 3,
      "z": -3,
      "name": "Wood_Hardwood_Planks"
    },
    {
      "x": 3,
      "y": 8,
      "z": -3,
      "name": "Wood_Hardwood_Planks"
    },
    {
      "x": 3,
      "y": 9,
      "z": -3,
      "name": "Wood_Deadwood_Roof",
      "rotation": 2
    },
    {
      "x": 3,
      "y": 0,
      "z": -2,
      "name": "Furniture_Kweebec_Platform",
      "rotation": 1
    },
    {
      "x": 3,
      "y": 3,
      "z": -2,
      "name": "Wood_Hardwood_Planks"
    },
    {
      "x": 3,
      "y": 8,
      "z": -2,
      "name": "Wood_Hardwood_Planks"
    },
    {
      "x": 3,
      "y": 9,
      "z": -2,
      "name": "Ingredient_Hay"
    },
    {
      "x": 3,
      "y": 0,
      "z": -1,
      "name": "Furniture_Kweebec_Platform",
      "rotation": 1
    },
    {
      "x": 3,
      "y": 3,
      "z": -1,
      "name": "Wood_Hardwood_Planks"
    },
    {
      "x": 3,
      "y": 8,
      "z": -1,
      "name": "Wood_Hardwood_Planks"
    },
    {
      "x": 3,
      "y": 9,
      "z": -1,
      "name": "Ingredient_Hay"
    },
    {
      "x": 3,
      "y": 10,
      "z": -1,
      "name": "Plant_Leaves_Bamboo",
      "support": 15
    },
    {
      "x": 3,
      "y": 0,
      "z": 0,
      "name": "Furniture_Kweebec_Platform",
      "rotation": 1
    },
    {
      "x": 3,
      "y": 1,
      "z": 0,
      "name": "Furniture_Jungle_Torch"
    },
    {
      "x": 3,
      "y": 3,
      "z": 0,
      "name": "Wood_Hardwood_Planks"
    },
    {
      "x": 3,
      "y": 8,
      "z": 0,
      "name": "Wood_Hardwood_Planks"
    },
    {
      "x": 3,
      "y": 9,
      "z": 0,
      "name": "Ingredient_Hay"
    },
    {
      "x": 3,
      "y": 10,
      "z": 0,
      "name": "Plant_Hay_Bundle"
    },
    {
      "x": 3,
      "y": 0,
      "z": 1,
      "name": "Furniture_Kweebec_Platform",
      "rotation": 1
    },
    {
      "x": 3,
      "y": 3,
      "z": 1,
      "name": "Wood_Hardwood_Planks"
    },
    {
      "x": 3,
      "y": 8,
      "z": 1,
      "name": "Wood_Hardwood_Planks"
    },
    {
      "x": 3,
      "y": 9,
      "z": 1,
      "name": "Ingredient_Hay"
    },
    {
      "x": 3,
      "y": 10,
      "z": 1,
      "name": "Plant_Leaves_Bamboo",
      "support": 15
    },
    {
      "x": 3,
      "y": 0,
      "z": 2,
      "name": "Furniture_Kweebec_Platform",
      "rotation": 1
    },
    {
      "x": 3,
      "y": 3,
      "z": 2,
      "name": "Wood_Hardwood_Planks"
    },
    {
      "x": 3,
      "y": 8,
      "z": 2,
      "name": "Wood_Hardwood_Planks"
    },
    {
      "x": 3,
      "y": 9,
      "z": 2,
      "name": "Ingredient_Hay"
    },
    {
      "x": 3,
      "y": 10,
      "z": 2,
      "name": "Plant_Leaves_Bamboo",
      "support": 15
    },
    {
      "x": 3,
      "y": 0,
      "z": 3,
      "name": "Furniture_Kweebec_Platform",
      "rotation": 1
    },
    {
      "x": 3,
      "y": 3,
      "z": 3,
      "name": "Wood_Hardwood_Planks"
    },
    {
      "x": 3,
      "y": 8,
      "z": 3,
      "name": "Wood_Hardwood_Planks"
    },
    {
      "x": 3,
      "y": 9,
      "z": 3,
      "name": "Wood_Deadwood_Roof"
    },
    {
      "x": 3,
      "y": 0,
      "z": 4,
      "name": "Furniture_Kweebec_Platform",
      "rotation": 1
    },
    {
      "x": 3,
      "y": 3,
      "z": 4,
      "name": "Wood_Hardwood_Planks"
    },
    {
      "x": 3,
      "y": 7,
      "z": 4,
      "name": "Wood_Hardwood_Planks"
    },
    {
      "x": 3,
      "y": 8,
      "z": 4,
      "name": "Wood_Deadwood_Roof"
    },
    {
      "x": 3,
      "y": 0,
      "z": 5,
      "name": "Furniture_Kweebec_Platform",
      "rotation": 1
    },
    {
      "x": 3,
      "y": 3,
      "z": 5,
      "name": "Wood_Hardwood_Planks"
    },
    {
      "x": 3,
      "y": 4,
      "z": 5,
      "name": "Wood_Beech_Trunk",
      "support": 15
    },
    {
      "x": 3,
      "y": 5,
      "z": 5,
      "name": "Wood_Hardwood_Planks"
    },
    {
      "x": 3,
      "y": 6,
      "z": 5,
      "name": "Wood_Hardwood_Planks"
    },
    {
      "x": 3,
      "y": 7,
      "z": 5,
      "name": "Wood_Deadwood_Roof"
    },
    {
      "x": 3,
      "y": 0,
      "z": 6,
      "name": "Soil_Sand_Black"
    },
    {
      "x": 3,
      "y": 1,
      "z": 6,
      "name": "Wood_Beech_Trunk",
      "support": 15
    },
    {
      "x": 3,
      "y": 2,
      "z": 6,
      "name": "Wood_Hardwood_Planks"
    },
    {
      "x": 3,
      "y": 3,
      "z": 6,
      "name": "Wood_Hardwood_Planks"
    },
    {
      "x": 3,
      "y": 6,
      "z": 6,
      "name": "Wood_Deadwood_Roof_Hollow"
    },
    {
      "x": 3,
      "y": 0,
      "z": 7,
      "name": "Soil_Sand_Black"
    },
    {
      "x": 3,
      "y": 3,
      "z": 7,
      "name": "Wood_Deadwood_Roof_Hollow"
    },
    {
      "x": 3,
      "y": 0,
      "z": 8,
      "name": "Soil_Sand_Black"
    },
    {
      "x": 4,
      "y": 0,
      "z": -7,
      "name": "Soil_Sand_Black"
    },
    {
      "x": 4,
      "y": 3,
      "z": -7,
      "name": "Wood_Deadwood_Roof_Hollow",
      "rotation": 2
    },
    {
      "x": 4,
      "y": 0,
      "z": -6,
      "name": "Soil_Sand_Black"
    },
    {
      "x": 4,
      "y": 1,
      "z": -6,
      "name": "Wood_Beech_Trunk",
      "support": 15
    },
    {
      "x": 4,
      "y": 2,
      "z": -6,
      "name": "Wood_Hardwood_Planks"
    },
    {
      "x": 4,
      "y": 3,
      "z": -6,
      "name": "Wood_Hardwood_Planks"
    },
    {
      "x": 4,
      "y": 5,
      "z": -6,
      "name": "Plant_Leaves_Bamboo",
      "support": 15
    },
    {
      "x": 4,
      "y": 6,
      "z": -6,
      "name": "Wood_Deadwood_Roof_Hollow",
      "rotation": 2
    },
    {
      "x": 4,
      "y": 0,
      "z": -5,
      "name": "Furniture_Kweebec_Platform",
      "rotation": 1
    },
    {
      "x": 4,
      "y": 1,
      "z": -5,
      "name": "Wood_Hardwood_Planks"
    },
    {
      "x": 4,
      "y": 3,
      "z": -5,
      "name": "Wood_Hardwood_Planks"
    },
    {
      "x": 4,
      "y": 4,
      "z": -5,
      "name": "Wood_Beech_Trunk",
      "support": 15
    },
    {
      "x": 4,
      "y": 5,
      "z": -5,
      "name": "Wood_Hardwood_Planks"
    },
    {
      "x": 4,
      "y": 6,
      "z": -5,
      "name": "Wood_Hardwood_Planks"
    },
    {
      "x": 4,
      "y": 7,
      "z": -5,
      "name": "Wood_Deadwood_Roof",
      "rotation": 2
    },
    {
      "x": 4,
      "y": 0,
      "z": -4,
      "name": "Furniture_Kweebec_Platform",
      "rotation": 1
    },
    {
      "x": 4,
      "y": 1,
      "z": -4,
      "name": "Wood_Hardwood_Planks"
    },
    {
      "x": 4,
      "y": 2,
      "z": -4,
      "name": "Wood_Hardwood_Stairs",
      "rotation": 1
    },
    {
      "x": 4,
      "y": 7,
      "z": -4,
      "name": "Wood_Hardwood_Planks"
    },
    {
      "x": 4,
      "y": 8,
      "z": -4,
      "name": "Wood_Deadwood_Roof",
      "rotation": 2
    },
    {
      "x": 4,
      "y": 0,
      "z": -3,
      "name": "Furniture_Kweebec_Platform",
      "rotation": 1
    },
    {
      "x": 4,
      "y": 1,
      "z": -3,
      "name": "Wood_Hardwood_Planks"
    },
    {
      "x": 4,
      "y": 2,
      "z": -3,
      "name": "Wood_Hardwood_Stairs",
      "rotation": 1
    },
    {
      "x": 4,
      "y": 8,
      "z": -3,
      "name": "Wood_Hardwood_Planks"
    },
    {
      "x": 4,
      "y": 9,
      "z": -3,
      "name": "*Wood_Deadwood_Roof_State_Definitions_Corner_Right",
      "rotation": 2
    },
    {
      "x": 4,
      "y": 0,
      "z": -2,
      "name": "Furniture_Kweebec_Platform",
      "rotation": 1
    },
    {
      "x": 4,
      "y": 1,
      "z": -2,
      "name": "Wood_Hardwood_Planks"
    },
    {
      "x": 4,
      "y": 2,
      "z": -2,
      "name": "Wood_Hardwood_Planks"
    },
    {
      "x": 4,
      "y": 3,
      "z": -2,
      "name": "Wood_Hardwood_Planks"
    },
    {
      "x": 4,
      "y": 8,
      "z": -2,
      "name": "Wood_Hardwood_Planks"
    },
    {
      "x": 4,
      "y": 9,
      "z": -2,
      "name": "Wood_Deadwood_Roof",
      "rotation": 1
    },
    {
      "x": 4,
      "y": 0,
      "z": -1,
      "name": "Furniture_Kweebec_Platform",
      "rotation": 1
    },
    {
      "x": 4,
      "y": 1,
      "z": -1,
      "name": "Wood_Hardwood_Planks"
    },
    {
      "x": 4,
      "y": 2,
      "z": -1,
      "name": "Wood_Hardwood_Planks"
    },
    {
      "x": 4,
      "y": 3,
      "z": -1,
      "name": "Wood_Hardwood_Planks"
    },
    {
      "x": 4,
      "y": 8,
      "z": -1,
      "name": "Wood_Hardwood_Planks"
    },
    {
      "x": 4,
      "y": 9,
      "z": -1,
      "name": "Wood_Deadwood_Roof",
      "rotation": 1
    },
    {
      "x": 4,
      "y": 10,
      "z": -1,
      "name": "Plant_Leaves_Bamboo",
      "support": 15
    },
    {
      "x": 4,
      "y": 0,
      "z": 0,
      "name": "Furniture_Kweebec_Platform",
      "rotation": 1
    },
    {
      "x": 4,
      "y": 1,
      "z": 0,
      "name": "Wood_Hardwood_Planks"
    },
    {
      "x": 4,
      "y": 2,
      "z": 0,
      "name": "Wood_Hardwood_Planks"
    },
    {
      "x": 4,
      "y": 3,
      "z": 0,
      "name": "Wood_Hardwood_Planks"
    },
    {
      "x": 4,
      "y": 8,
      "z": 0,
      "name": "Wood_Hardwood_Planks"
    },
    {
      "x": 4,
      "y": 9,
      "z": 0,
      "name": "Wood_Deadwood_Roof",
      "rotation": 1
    },
    {
      "x": 4,
      "y": 0,
      "z": 1,
      "name": "Furniture_Kweebec_Platform",
      "rotation": 1
    },
    {
      "x": 4,
      "y": 3,
      "z": 1,
      "name": "Wood_Hardwood_Planks"
    },
    {
      "x": 4,
      "y": 8,
      "z": 1,
      "name": "Wood_Hardwood_Planks"
    },
    {
      "x": 4,
      "y": 9,
      "z": 1,
      "name": "Wood_Deadwood_Roof",
      "rotation": 1
    },
    {
      "x": 4,
      "y": 0,
      "z": 2,
      "name": "Furniture_Kweebec_Platform",
      "rotation": 1
    },
    {
      "x": 4,
      "y": 3,
      "z": 2,
      "name": "Wood_Hardwood_Planks"
    },
    {
      "x": 4,
      "y": 8,
      "z": 2,
      "name": "Wood_Hardwood_Planks"
    },
    {
      "x": 4,
      "y": 9,
      "z": 2,
      "name": "Wood_Deadwood_Roof",
      "rotation": 1
    },
    {
      "x": 4,
      "y": 0,
      "z": 3,
      "name": "Furniture_Kweebec_Platform",
      "rotation": 1
    },
    {
      "x": 4,
      "y": 3,
      "z": 3,
      "name": "Wood_Hardwood_Planks"
    },
    {
      "x": 4,
      "y": 8,
      "z": 3,
      "name": "Wood_Hardwood_Planks"
    },
    {
      "x": 4,
      "y": 9,
      "z": 3,
      "name": "*Wood_Deadwood_Roof_State_Definitions_Corner_Left"
    },
    {
      "x": 4,
      "y": 0,
      "z": 4,
      "name": "Furniture_Kweebec_Platform",
      "rotation": 1
    },
    {
      "x": 4,
      "y": 3,
      "z": 4,
      "name": "Wood_Hardwood_Planks"
    },
    {
      "x": 4,
      "y": 7,
      "z": 4,
      "name": "Wood_Hardwood_Planks"
    },
    {
      "x": 4,
      "y": 8,
      "z": 4,
      "name": "Wood_Deadwood_Roof"
    },
    {
      "x": 4,
      "y": 0,
      "z": 5,
      "name": "Furniture_Kweebec_Platform",
      "rotation": 1
    },
    {
      "x": 4,
      "y": 3,
      "z": 5,
      "name": "Wood_Hardwood_Planks"
    },
    {
      "x": 4,
      "y": 4,
      "z": 5,
      "name": "Wood_Beech_Trunk",
      "support": 15
    },
    {
      "x": 4,
      "y": 5,
      "z": 5,
      "name": "Wood_Hardwood_Planks"
    },
    {
      "x": 4,
      "y": 6,
      "z": 5,
      "name": "Wood_Hardwood_Planks"
    },
    {
      "x": 4,
      "y": 7,
      "z": 5,
      "name": "Wood_Deadwood_Roof"
    },
    {
      "x": 4,
      "y": 0,
      "z": 6,
      "name": "Soil_Sand_Black"
    },
    {
      "x": 4,
      "y": 1,
      "z": 6,
      "name": "Wood_Beech_Trunk",
      "support": 15
    },
    {
      "x": 4,
      "y": 2,
      "z": 6,
      "name": "Wood_Hardwood_Planks"
    },
    {
      "x": 4,
      "y": 3,
      "z": 6,
      "name": "Wood_Hardwood_Planks"
    },
    {
      "x": 4,
      "y": 6,
      "z": 6,
      "name": "Wood_Deadwood_Roof_Hollow"
    },
    {
      "x": 4,
      "y": 0,
      "z": 7,
      "name": "Soil_Sand_Black"
    },
    {
      "x": 4,
      "y": 1,
      "z": 7,
      "name": "Plant_Hay_Bundle"
    },
    {
      "x": 4,
      "y": 3,
      "z": 7,
      "name": "Wood_Deadwood_Roof_Hollow"
    },
    {
      "x": 4,
      "y": 0,
      "z": 8,
      "name": "Soil_Sand_Black"
    },
    {
      "x": 5,
      "y": 0,
      "z": -7,
      "name": "Soil_Sand_Black"
    },
    {
      "x": 5,
      "y": 3,
      "z": -7,
      "name": "Wood_Deadwood_Roof_Hollow",
      "rotation": 2
    },
    {
      "x": 5,
      "y": 0,
      "z": -6,
      "name": "Soil_Sand_Black"
    },
    {
      "x": 5,
      "y": 1,
      "z": -6,
      "name": "Wood_Beech_Trunk",
      "support": 15
    },
    {
      "x": 5,
      "y": 2,
      "z": -6,
      "name": "Wood_Hardwood_Planks"
    },
    {
      "x": 5,
      "y": 3,
      "z": -6,
      "name": "Wood_Hardwood_Planks"
    },
    {
      "x": 5,
      "y": 6,
      "z": -6,
      "name": "Wood_Deadwood_Roof_Hollow",
      "rotation": 2
    },
    {
      "x": 5,
      "y": 0,
      "z": -5,
      "name": "Furniture_Kweebec_Platform",
      "rotation": 1
    },
    {
      "x": 5,
      "y": 1,
      "z": -5,
      "name": "Wood_Hardwood_Planks"
    },
    {
      "x": 5,
      "y": 2,
      "z": -5,
      "name": "Wood_Hardwood_Planks"
    },
    {
      "x": 5,
      "y": 3,
      "z": -5,
      "name": "Wood_Hardwood_Planks"
    },
    {
      "x": 5,
      "y": 4,
      "z": -5,
      "name": "Wood_Beech_Trunk",
      "support": 15
    },
    {
      "x": 5,
      "y": 5,
      "z": -5,
      "name": "Wood_Hardwood_Planks"
    },
    {
      "x": 5,
      "y": 6,
      "z": -5,
      "name": "Wood_Hardwood_Planks"
    },
    {
      "x": 5,
      "y": 7,
      "z": -5,
      "name": "Wood_Deadwood_Roof",
      "rotation": 2
    },
    {
      "x": 5,
      "y": 0,
      "z": -4,
      "name": "Furniture_Kweebec_Platform",
      "rotation": 1
    },
    {
      "x": 5,
      "y": 1,
      "z": -4,
      "name": "Wood_Hardwood_Planks"
    },
    {
      "x": 5,
      "y": 7,
      "z": -4,
      "name": "Wood_Hardwood_Planks"
    },
    {
      "x": 5,
      "y": 8,
      "z": -4,
      "name": "*Wood_Deadwood_Roof_State_Definitions_Corner_Right",
      "rotation": 2
    },
    {
      "x": 5,
      "y": 0,
      "z": -3,
      "name": "Furniture_Kweebec_Platform",
      "rotation": 1
    },
    {
      "x": 5,
      "y": 1,
      "z": -3,
      "name": "Wood_Hardwood_Stairs"
    },
    {
      "x": 5,
      "y": 7,
      "z": -3,
      "name": "Wood_Hardwood_Planks"
    },
    {
      "x": 5,
      "y": 8,
      "z": -3,
      "name": "Wood_Deadwood_Roof",
      "rotation": 1
    },
    {
      "x": 5,
      "y": 0,
      "z": -2,
      "name": "Furniture_Kweebec_Platform",
      "rotation": 1
    },
    {
      "x": 5,
      "y": 7,
      "z": -2,
      "name": "Wood_Hardwood_Planks"
    },
    {
      "x": 5,
      "y": 8,
      "z": -2,
      "name": "Wood_Deadwood_Roof",
      "rotation": 1
    },
    {
      "x": 5,
      "y": 0,
      "z": -1,
      "name": "Furniture_Kweebec_Platform",
      "rotation": 1
    },
    {
      "x": 5,
      "y": 3,
      "z": -1,
      "name": "Wood_Hardwood_Planks"
    },
    {
      "x": 5,
      "y": 7,
      "z": -1,
      "name": "Wood_Hardwood_Planks"
    },
    {
      "x": 5,
      "y": 8,
      "z": -1,
      "name": "Wood_Deadwood_Roof",
      "rotation": 1
    },
    {
      "x": 5,
      "y": 0,
      "z": 0,
      "name": "Furniture_Kweebec_Platform",
      "rotation": 1
    },
    {
      "x": 5,
      "y": 3,
      "z": 0,
      "name": "Wood_Hardwood_Planks"
    },
    {
      "x": 5,
      "y": 7,
      "z": 0,
      "name": "Wood_Hardwood_Planks"
    },
    {
      "x": 5,
      "y": 8,
      "z": 0,
      "name": "Wood_Deadwood_Roof",
      "rotation": 1
    },
    {
      "x": 5,
      "y": 0,
      "z": 1,
      "name": "Furniture_Kweebec_Platform",
      "rotation": 1
    },
    {
      "x": 5,
      "y": 3,
      "z": 1,
      "name": "Wood_Hardwood_Planks"
    },
    {
      "x": 5,
      "y": 7,
      "z": 1,
      "name": "Wood_Hardwood_Planks"
    },
    {
      "x": 5,
      "y": 8,
      "z": 1,
      "name": "Wood_Deadwood_Roof",
      "rotation": 1
    },
    {
      "x": 5,
      "y": 0,
      "z": 2,
      "name": "Furniture_Kweebec_Platform",
      "rotation": 1
    },
    {
      "x": 5,
      "y": 3,
      "z": 2,
      "name": "Wood_Hardwood_Planks"
    },
    {
      "x": 5,
      "y": 7,
      "z": 2,
      "name": "Wood_Hardwood_Planks"
    },
    {
      "x": 5,
      "y": 8,
      "z": 2,
      "name": "Wood_Deadwood_Roof",
      "rotation": 1
    },
    {
      "x": 5,
      "y": 0,
      "z": 3,
      "name": "Furniture_Kweebec_Platform",
      "rotation": 1
    },
    {
      "x": 5,
      "y": 3,
      "z": 3,
      "name": "Wood_Hardwood_Planks"
    },
    {
      "x": 5,
      "y": 7,
      "z": 3,
      "name": "Wood_Hardwood_Planks"
    },
    {
      "x": 5,
      "y": 8,
      "z": 3,
      "name": "Wood_Deadwood_Roof",
      "rotation": 1
    },
    {
      "x": 5,
      "y": 9,
      "z": 3,
      "name": "Plant_Leaves_Bamboo",
      "support": 15
    },
    {
      "x": 5,
      "y": 0,
      "z": 4,
      "name": "Furniture_Kweebec_Platform",
      "rotation": 1
    },
    {
      "x": 5,
      "y": 3,
      "z": 4,
      "name": "Wood_Hardwood_Planks"
    },
    {
      "x": 5,
      "y": 4,
      "z": 4,
      "name": "Furniture_Jungle_Torch"
    },
    {
      "x": 5,
      "y": 7,
      "z": 4,
      "name": "Wood_Hardwood_Planks"
    },
    {
      "x": 5,
      "y": 8,
      "z": 4,
      "name": "*Wood_Deadwood_Roof_State_Definitions_Corner_Right",
      "rotation": 1
    },
    {
      "x": 5,
      "y": 0,
      "z": 5,
      "name": "Furniture_Kweebec_Platform",
      "rotation": 1
    },
    {
      "x": 5,
      "y": 3,
      "z": 5,
      "name": "Wood_Hardwood_Planks"
    },
    {
      "x": 5,
      "y": 4,
      "z": 5,
      "name": "Wood_Beech_Trunk",
      "support": 15
    },
    {
      "x": 5,
      "y": 5,
      "z": 5,
      "name": "Wood_Hardwood_Planks"
    },
    {
      "x": 5,
      "y": 6,
      "z": 5,
      "name": "Wood_Hardwood_Planks"
    },
    {
      "x": 5,
      "y": 7,
      "z": 5,
      "name": "Wood_Deadwood_Roof"
    },
    {
      "x": 5,
      "y": 0,
      "z": 6,
      "name": "Soil_Sand_Black"
    },
    {
      "x": 5,
      "y": 1,
      "z": 6,
      "name": "Wood_Beech_Trunk",
      "support": 15
    },
    {
      "x": 5,
      "y": 2,
      "z": 6,
      "name": "Wood_Hardwood_Planks"
    },
    {
      "x": 5,
      "y": 3,
      "z": 6,
      "name": "Wood_Hardwood_Planks"
    },
    {
      "x": 5,
      "y": 5,
      "z": 6,
      "name": "Plant_Leaves_Bamboo",
      "support": 15
    },
    {
      "x": 5,
      "y": 6,
      "z": 6,
      "name": "Wood_Deadwood_Roof_Hollow"
    },
    {
      "x": 5,
      "y": 0,
      "z": 7,
      "name": "Soil_Sand_Black"
    },
    {
      "x": 5,
      "y": 3,
      "z": 7,
      "name": "Wood_Deadwood_Roof_Hollow"
    },
    {
      "x": 5,
      "y": 0,
      "z": 8,
      "name": "Soil_Sand_Black"
    },
    {
      "x": 6,
      "y": 0,
      "z": -7,
      "name": "Soil_Sand_Black"
    },
    {
      "x": 6,
      "y": 3,
      "z": -7,
      "name": "Wood_Deadwood_Roof_Hollow",
      "rotation": 2
    },
    {
      "x": 6,
      "y": 0,
      "z": -6,
      "name": "Soil_Sand_Black"
    },
    {
      "x": 6,
      "y": 1,
      "z": -6,
      "name": "Wood_Beech_Trunk",
      "support": 15
    },
    {
      "x": 6,
      "y": 2,
      "z": -6,
      "name": "Wood_Hardwood_Planks"
    },
    {
      "x": 6,
      "y": 3,
      "z": -6,
      "name": "Wood_Hardwood_Planks"
    },
    {
      "x": 6,
      "y": 4,
      "z": -6,
      "name": "Plant_Hay_Bundle"
    },
    {
      "x": 6,
      "y": 6,
      "z": -6,
      "name": "Wood_Deadwood_Roof_Hollow",
      "rotation": 2
    },
    {
      "x": 6,
      "y": 0,
      "z": -5,
      "name": "Furniture_Kweebec_Platform",
      "rotation": 1
    },
    {
      "x": 6,
      "y": 1,
      "z": -5,
      "name": "Wood_Hardwood_Planks"
    },
    {
      "x": 6,
      "y": 2,
      "z": -5,
      "name": "Wood_Hardwood_Planks"
    },
    {
      "x": 6,
      "y": 3,
      "z": -5,
      "name": "Wood_Hardwood_Planks"
    },
    {
      "x": 6,
      "y": 4,
      "z": -5,
      "name": "Wood_Beech_Trunk",
      "support": 15
    },
    {
      "x": 6,
      "y": 5,
      "z": -5,
      "name": "Wood_Hardwood_Planks"
    },
    {
      "x": 6,
      "y": 6,
      "z": -5,
      "name": "Wood_Hardwood_Planks"
    },
    {
      "x": 6,
      "y": 7,
      "z": -5,
      "name": "*Wood_Deadwood_Roof_State_Definitions_Corner_Right",
      "rotation": 2
    },
    {
      "x": 6,
      "y": 0,
      "z": -4,
      "name": "Furniture_Kweebec_Platform",
      "rotation": 1
    },
    {
      "x": 6,
      "y": 1,
      "z": -4,
      "name": "Wood_Hardwood_Planks"
    },
    {
      "x": 6,
      "y": 4,
      "z": -4,
      "name": "Wood_Beech_Trunk",
      "support": 15
    },
    {
      "x": 6,
      "y": 5,
      "z": -4,
      "name": "Wood_Hardwood_Planks"
    },
    {
      "x": 6,
      "y": 6,
      "z": -4,
      "name": "Wood_Hardwood_Planks"
    },
    {
      "x": 6,
      "y": 7,
      "z": -4,
      "name": "Wood_Deadwood_Roof",
      "rotation": 1
    },
    {
      "x": 6,
      "y": 0,
      "z": -3,
      "name": "Furniture_Kweebec_Platform",
      "rotation": 1
    },
    {
      "x": 6,
      "y": 1,
      "z": -3,
      "name": "Wood_Hardwood_Stairs"
    },
    {
      "x": 6,
      "y": 4,
      "z": -3,
      "name": "Wood_Beech_Trunk",
      "support": 15
    },
    {
      "x": 6,
      "y": 5,
      "z": -3,
      "name": "Wood_Hardwood_Planks"
    },
    {
      "x": 6,
      "y": 6,
      "z": -3,
      "name": "Wood_Hardwood_Planks"
    },
    {
      "x": 6,
      "y": 7,
      "z": -3,
      "name": "Wood_Deadwood_Roof",
      "rotation": 1
    },
    {
      "x": 6,
      "y": 0,
      "z": -2,
      "name": "Furniture_Kweebec_Platform",
      "rotation": 1
    },
    {
      "x": 6,
      "y": 4,
      "z": -2,
      "name": "Wood_Beech_Trunk",
      "support": 15
    },
    {
      "x": 6,
      "y": 5,
      "z": -2,
      "name": "Wood_Hardwood_Planks"
    },
    {
      "x": 6,
      "y": 6,
      "z": -2,
      "name": "Wood_Hardwood_Planks"
    },
    {
      "x": 6,
      "y": 7,
      "z": -2,
      "name": "Wood_Deadwood_Roof",
      "rotation": 1
    },
    {
      "x": 6,
      "y": 0,
      "z": -1,
      "name": "Furniture_Kweebec_Platform",
      "rotation": 1
    },
    {
      "x": 6,
      "y": 3,
      "z": -1,
      "name": "Wood_Hardwood_Planks"
    },
    {
      "x": 6,
      "y": 4,
      "z": -1,
      "name": "Wood_Beech_Trunk",
      "support": 15
    },
    {
      "x": 6,
      "y": 5,
      "z": -1,
      "name": "Furniture_Jungle_Window",
      "rotation": 1
    },
    {
      "x": 6,
      "y": 6,
      "z": -1,
      "name": "Furniture_Jungle_Window",
      "rotation": 1
    },
    {
      "x": 6,
      "y": 7,
      "z": -1,
      "name": "Wood_Deadwood_Roof",
      "rotation": 1
    },
    {
      "x": 6,
      "y": 0,
      "z": 0,
      "name": "Furniture_Kweebec_Platform",
      "rotation": 1
    },
    {
      "x": 6,
      "y": 3,
      "z": 0,
      "name": "Wood_Hardwood_Planks"
    },
    {
      "x": 6,
      "y": 4,
      "z": 0,
      "name": "Wood_Beech_Trunk",
      "support": 15
    },
    {
      "x": 6,
      "y": 5,
      "z": 0,
      "name": "Furniture_Jungle_Window",
      "rotation": 1
    },
    {
      "x": 6,
      "y": 6,
      "z": 0,
      "name": "Furniture_Jungle_Window",
      "rotation": 1
    },
    {
      "x": 6,
      "y": 7,
      "z": 0,
      "name": "Wood_Deadwood_Roof",
      "rotation": 1
    },
    {
      "x": 6,
      "y": 0,
      "z": 1,
      "name": "Furniture_Kweebec_Platform",
      "rotation": 1
    },
    {
      "x": 6,
      "y": 3,
      "z": 1,
      "name": "Wood_Hardwood_Planks"
    },
    {
      "x": 6,
      "y": 4,
      "z": 1,
      "name": "Wood_Beech_Trunk",
      "support": 15
    },
    {
      "x": 6,
      "y": 5,
      "z": 1,
      "name": "Furniture_Jungle_Window",
      "rotation": 1
    },
    {
      "x": 6,
      "y": 6,
      "z": 1,
      "name": "Furniture_Jungle_Window",
      "rotation": 1
    },
    {
      "x": 6,
      "y": 7,
      "z": 1,
      "name": "Wood_Deadwood_Roof",
      "rotation": 1
    },
    {
      "x": 6,
      "y": 0,
      "z": 2,
      "name": "Furniture_Kweebec_Platform",
      "rotation": 1
    },
    {
      "x": 6,
      "y": 3,
      "z": 2,
      "name": "Wood_Hardwood_Planks"
    },
    {
      "x": 6,
      "y": 4,
      "z": 2,
      "name": "Wood_Beech_Trunk",
      "support": 15
    },
    {
      "x": 6,
      "y": 5,
      "z": 2,
      "name": "Wood_Hardwood_Planks"
    },
    {
      "x": 6,
      "y": 6,
      "z": 2,
      "name": "Wood_Hardwood_Planks"
    },
    {
      "x": 6,
      "y": 7,
      "z": 2,
      "name": "Wood_Deadwood_Roof",
      "rotation": 1
    },
    {
      "x": 6,
      "y": 0,
      "z": 3,
      "name": "Furniture_Kweebec_Platform",
      "rotation": 1
    },
    {
      "x": 6,
      "y": 3,
      "z": 3,
      "name": "Wood_Hardwood_Planks"
    },
    {
      "x": 6,
      "y": 4,
      "z": 3,
      "name": "Wood_Beech_Trunk",
      "support": 15
    },
    {
      "x": 6,
      "y": 5,
      "z": 3,
      "name": "Wood_Hardwood_Planks"
    },
    {
      "x": 6,
      "y": 6,
      "z": 3,
      "name": "Wood_Hardwood_Planks"
    },
    {
      "x": 6,
      "y": 7,
      "z": 3,
      "name": "Wood_Deadwood_Roof",
      "rotation": 1
    },
    {
      "x": 6,
      "y": 0,
      "z": 4,
      "name": "Furniture_Kweebec_Platform",
      "rotation": 1
    },
    {
      "x": 6,
      "y": 3,
      "z": 4,
      "name": "Wood_Hardwood_Planks"
    },
    {
      "x": 6,
      "y": 4,
      "z": 4,
      "name": "Wood_Beech_Trunk",
