{
  "version": 8,
  "blockIdVersion": 11,
  "anchorX": 0,
  "anchorY": 0,
  "anchorZ": 0,
  "blocks": [
    {
      "x": -8,
      "y": 0,
      "z": -5,
      "name": "Plant_Seaweed_Dead_Short",
      "support": 15
    },
    {
      "x": -8,
      "y": 0,
      "z": -4,
      "name": "Plant_Seaweed_Dead_Short",
      "support": 15
    },
    {
      "x": -7,
      "y": 0,
      "z": -6,
      "name": "Plant_Seaweed_Dead_Short",
      "support": 15
    },
    {
      "x": -7,
      "y": 0,
      "z": -5,
      "name": "Plant_Seaweed_Dead_Ghostly",
      "support": 15
    },
    {
      "x": -7,
      "y": 1,
      "z": -5,
      "name": "Plant_Seaweed_Dead_Ghostly",
      "filler": 1024
    },
    {
      "x": -7,
      "y": 0,
      "z": -4,
      "name": "Plant_Seaweed_Dead_Ghostly",
      "support": 15
    },
    {
      "x": -7,
      "y": 1,
      "z": -4,
      "name": "Plant_Seaweed_Dead_Ghostly",
      "filler": 1024
    },
    {
      "x": -7,
      "y": 0,
      "z": -3,
      "name": "Plant_Seaweed_Dead_Short",
      "support": 15
    },
    {
      "x": -6,
      "y": 0,
      "z": -10,
      "name": "*Rock_Runic_Blue_Brick_Stairs_State_Definitions_Corner_Right",
      "rotation": 8
    },
    {
      "x": -6,
      "y": 1,
      "z": -10,
      "name": "Rock_Runic_Blue_Brick"
    },
    {
      "x": -6,
      "y": 2,
      "z": -10,
      "name": "Rock_Runic_Blue_Brick"
    },
    {
      "x": -6,
      "y": 3,
      "z": -10,
      "name": "Rock_Runic_Blue_Brick"
    },
    {
      "x": -6,
      "y": 4,
      "z": -10,
      "name": "Rock_Runic_Blue_Brick"
    },
    {
      "x": -6,
      "y": 5,
      "z": -10,
      "name": "Rock_Runic_Blue_Brick"
    },
    {
      "x": -6,
      "y": 6,
      "z": -10,
      "name": "Rock_Runic_Blue_Brick"
    },
    {
      "x": -6,
      "y": 7,
      "z": -10,
      "name": "Plant_Seaweed_Dead_Ghostly",
      "support": 15
    },
    {
      "x": -6,
      "y": 8,
      "z": -10,
      "name": "Plant_Seaweed_Dead_Ghostly",
      "filler": 1024
    },
    {
      "x": -6,
      "y": 0,
      "z": -9,
      "name": "Rock_Runic_Blue_Brick_Stairs",
      "rotation": 9
    },
    {
      "x": -6,
      "y": 1,
      "z": -9,
      "name": "Rock_Runic_Blue_Brick"
    },
    {
      "x": -6,
      "y": 2,
      "z": -9,
      "name": "Rock_Runic_Blue_Brick"
    },
    {
      "x": -6,
      "y": 3,
      "z": -9,
      "name": "Rock_Runic_Blue_Brick"
    },
    {
      "x": -6,
      "y": 4,
      "z": -9,
      "name": "Rock_Runic_Blue_Brick"
    },
    {
      "x": -6,
      "y": 5,
      "z": -9,
      "name": "Rock_Runic_Blue_Brick"
    },
    {
      "x": -6,
      "y": 6,
      "z": -9,
      "name": "Rock_Runic_Blue_Brick"
    },
    {
      "x": -6,
      "y": 7,
      "z": -9,
      "name": "Rock_Runic_Blue_Brick"
    },
    {
      "x": -6,
      "y": 0,
      "z": -8,
      "name": "Rock_Runic_Blue_Brick"
    },
    {
      "x": -6,
      "y": 1,
      "z": -8,
      "name": "Rock_Runic_Blue_Brick"
    },
    {
      "x": -6,
      "y": 2,
      "z": -8,
      "name": "Rock_Runic_Blue_Brick"
    },
    {
      "x": -6,
      "y": 3,
      "z": -8,
      "name": "Rock_Runic_Blue_Brick"
    },
    {
      "x": -6,
      "y": 4,
      "z": -8,
      "name": "Rock_Runic_Blue_Brick"
    },
    {
      "x": -6,
      "y": 5,
      "z": -8,
      "name": "Rock_Runic_Blue_Brick"
    },
    {
      "x": -6,
      "y": 6,
      "z": -8,
      "name": "Rock_Runic_Blue_Brick"
    },
    {
      "x": -6,
      "y": 7,
      "z": -8,
      "name": "Rock_Runic_Blue_Brick"
    },
    {
      "x": -6,
      "y": 0,
      "z": -7,
      "name": "Rock_Runic_Blue_Brick"
    },
    {
      "x": -6,
      "y": 1,
      "z": -7,
      "name": "Rock_Runic_Blue_Brick"
    },
    {
      "x": -6,
      "y": 2,
      "z": -7,
      "name": "Rock_Runic_Blue_Brick"
    },
    {
      "x": -6,
      "y": 3,
      "z": -7,
      "name": "Rock_Runic_Blue_Brick"
    },
    {
      "x": -6,
      "y": 4,
      "z": -7,
      "name": "Rock_Runic_Blue_Brick"
    },
    {
      "x": -6,
      "y": 5,
      "z": -7,
      "name": "Rock_Runic_Blue_Brick"
    },
    {
      "x": -6,
      "y": 6,
      "z": -7,
      "name": "Rock_Runic_Blue_Brick"
    },
    {
      "x": -6,
      "y": 7,
      "z": -7,
      "name": "Rock_Runic_Blue_Brick"
    },
    {
      "x": -6,
      "y": 0,
      "z": -6,
      "name": "Rock_Runic_Blue_Brick"
    },
    {
      "x": -6,
      "y": 1,
      "z": -6,
      "name": "Rock_Runic_Blue_Brick"
    },
    {
      "x": -6,
      "y": 2,
      "z": -6,
      "name": "Rock_Runic_Blue_Brick"
    },
    {
      "x": -6,
      "y": 3,
      "z": -6,
      "name": "Rock_Runic_Blue_Brick"
    },
    {
      "x": -6,
      "y": 4,
      "z": -6,
      "name": "Rock_Runic_Blue_Brick"
    },
    {
      "x": -6,
      "y": 5,
      "z": -6,
      "name": "Rock_Runic_Blue_Brick"
    },
    {
      "x": -6,
      "y": 6,
      "z": -6,
      "name": "Rock_Runic_Blue_Brick"
    },
    {
      "x": -6,
      "y": 7,
      "z": -6,
      "name": "Rock_Runic_Blue_Brick"
    },
    {
      "x": -6,
      "y": 0,
      "z": -5,
      "name": "Rock_Runic_Blue_Brick"
    },
    {
      "x": -6,
      "y": 1,
      "z": -5,
      "name": "Rock_Runic_Blue_Brick"
    },
    {
      "x": -6,
      "y": 2,
      "z": -5,
      "name": "Rock_Runic_Blue_Brick"
    },
    {
      "x": -6,
      "y": 3,
      "z": -5,
      "name": "Rock_Runic_Blue_Brick"
    },
    {
      "x": -6,
      "y": 4,
      "z": -5,
      "name": "Rock_Runic_Blue_Brick"
    },
    {
      "x": -6,
      "y": 5,
      "z": -5,
      "name": "Rock_Runic_Blue_Brick"
    },
    {
      "x": -6,
      "y": 6,
      "z": -5,
      "name": "Rock_Runic_Blue_Brick"
    },
    {
      "x": -6,
      "y": 7,
      "z": -5,
      "name": "Rock_Runic_Blue_Brick"
    },
    {
      "x": -6,
      "y": 0,
      "z": -4,
      "name": "Rock_Runic_Blue_Brick"
    },
    {
      "x": -6,
      "y": 1,
      "z": -4,
      "name": "Rock_Runic_Blue_Brick"
    },
    {
      "x": -6,
      "y": 2,
      "z": -4,
      "name": "Rock_Runic_Blue_Brick"
    },
    {
      "x": -6,
      "y": 3,
      "z": -4,
      "name": "Rock_Runic_Blue_Brick"
    },
    {
      "x": -6,
      "y": 4,
      "z": -4,
      "name": "Rock_Runic_Blue_Brick"
    },
    {
      "x": -6,
      "y": 5,
      "z": -4,
      "name": "Rock_Runic_Blue_Brick"
    },
    {
      "x": -6,
      "y": 6,
      "z": -4,
      "name": "Rock_Runic_Blue_Brick"
    },
    {
      "x": -6,
      "y": 7,
      "z": -4,
      "name": "Rock_Runic_Blue_Brick"
    },
    {
      "x": -6,
      "y": 0,
      "z": -3,
      "name": "Rock_Runic_Blue_Brick"
    },
    {
      "x": -6,
      "y": 1,
      "z": -3,
      "name": "Rock_Runic_Blue_Brick"
    },
    {
      "x": -6,
      "y": 2,
      "z": -3,
      "name": "Rock_Runic_Blue_Brick"
    },
    {
      "x": -6,
      "y": 3,
      "z": -3,
      "name": "Rock_Runic_Blue_Brick"
    },
    {
      "x": -6,
      "y": 4,
      "z": -3,
      "name": "Rock_Runic_Blue_Brick"
    },
    {
      "x": -6,
      "y": 5,
      "z": -3,
      "name": "Rock_Runic_Blue_Brick"
    },
    {
      "x": -6,
      "y": 6,
      "z": -3,
      "name": "Rock_Runic_Blue_Brick"
    },
    {
      "x": -6,
      "y": 7,
      "z": -3,
      "name": "Rock_Runic_Blue_Brick"
    },
    {
      "x": -6,
      "y": 0,
      "z": -2,
      "name": "Rock_Runic_Blue_Brick"
    },
    {
      "x": -6,
      "y": 1,
      "z": -2,
      "name": "Rock_Runic_Blue_Brick"
    },
    {
      "x": -6,
      "y": 2,
      "z": -2,
      "name": "Rock_Runic_Blue_Brick"
    },
    {
      "x": -6,
      "y": 3,
      "z": -2,
      "name": "Rock_Runic_Blue_Brick"
    },
    {
      "x": -6,
      "y": 4,
      "z": -2,
      "name": "Rock_Runic_Blue_Brick"
    },
    {
      "x": -6,
      "y": 5,
      "z": -2,
      "name": "Rock_Runic_Blue_Brick"
    },
    {
      "x": -6,
      "y": 6,
      "z": -2,
      "name": "Rock_Runic_Blue_Brick"
    },
    {
      "x": -6,
      "y": 7,
      "z": -2,
      "name": "Rock_Runic_Blue_Brick"
    },
    {
      "x": -6,
      "y": 0,
      "z": -1,
      "name": "Rock_Runic_Blue_Brick"
    },
    {
      "x": -6,
      "y": 1,
      "z": -1,
      "name": "Rock_Runic_Blue_Brick"
    },
    {
      "x": -6,
      "y": 2,
      "z": -1,
      "name": "Rock_Runic_Blue_Brick"
    },
    {
      "x": -6,
      "y": 3,
      "z": -1,
      "name": "Rock_Runic_Blue_Brick"
    },
    {
      "x": -6,
      "y": 4,
      "z": -1,
      "name": "Rock_Runic_Blue_Brick"
    },
    {
      "x": -6,
      "y": 5,
      "z": -1,
      "name": "Rock_Runic_Blue_Brick"
    },
    {
      "x": -6,
      "y": 6,
      "z": -1,
      "name": "Rock_Runic_Blue_Brick"
    },
    {
      "x": -6,
      "y": 7,
      "z": -1,
      "name": "Rock_Runic_Blue_Brick"
    },
    {
      "x": -6,
      "y": 0,
      "z": 0,
      "name": "Rock_Runic_Blue_Brick"
    },
    {
      "x": -6,
      "y": 1,
      "z": 0,
      "name": "Rock_Runic_Blue_Brick"
    },
    {
      "x": -6,
      "y": 2,
      "z": 0,
      "name": "Rock_Runic_Blue_Brick"
    },
    {
      "x": -6,
      "y": 3,
      "z": 0,
      "name": "Rock_Runic_Blue_Brick"
    },
    {
      "x": -6,
      "y": 4,
      "z": 0,
      "name": "Rock_Runic_Blue_Brick"
    },
    {
      "x": -6,
      "y": 5,
      "z": 0,
      "name": "Rock_Runic_Blue_Brick"
    },
    {
      "x": -6,
      "y": 6,
      "z": 0,
      "name": "Rock_Runic_Blue_Brick"
    },
    {
      "x": -6,
      "y": 7,
      "z": 0,
      "name": "Rock_Runic_Blue_Brick"
    },
    {
      "x": -6,
      "y": 0,
      "z": 1,
      "name": "Rock_Runic_Blue_Brick"
    },
    {
      "x": -6,
      "y": 1,
      "z": 1,
      "name": "Rock_Runic_Blue_Brick"
    },
    {
      "x": -6,
      "y": 2,
      "z": 1,
      "name": "Rock_Runic_Blue_Brick"
    },
    {
      "x": -6,
      "y": 3,
      "z": 1,
      "name": "Rock_Runic_Blue_Brick"
    },
    {
      "x": -6,
      "y": 4,
      "z": 1,
      "name": "Rock_Runic_Blue_Brick"
    },
    {
      "x": -6,
      "y": 5,
      "z": 1,
      "name": "Rock_Runic_Blue_Brick"
    },
    {
      "x": -6,
      "y": 6,
      "z": 1,
      "name": "Rock_Runic_Blue_Brick"
    },
    {
      "x": -6,
      "y": 7,
      "z": 1,
      "name": "Rock_Runic_Blue_Brick"
    },
    {
      "x": -6,
      "y": 0,
      "z": 2,
      "name": "Rock_Runic_Blue_Brick"
    },
    {
      "x": -6,
      "y": 1,
      "z": 2,
      "name": "Rock_Runic_Blue_Brick"
    },
    {
      "x": -6,
      "y": 2,
      "z": 2,
      "name": "Rock_Runic_Blue_Brick"
    },
    {
      "x": -6,
      "y": 3,
      "z": 2,
      "name": "Rock_Runic_Blue_Brick"
    },
    {
      "x": -6,
      "y": 4,
      "z": 2,
      "name": "Rock_Runic_Blue_Brick"
    },
    {
      "x": -6,
      "y": 5,
      "z": 2,
      "name": "Rock_Runic_Blue_Brick"
    },
    {
      "x": -6,
      "y": 6,
      "z": 2,
      "name": "Rock_Runic_Blue_Brick"
    },
    {
      "x": -6,
      "y": 7,
      "z": 2,
      "name": "Rock_Runic_Blue_Brick"
    },
    {
      "x": -6,
      "y": 0,
      "z": 3,
      "name": "Rock_Runic_Blue_Brick"
    },
    {
      "x": -6,
      "y": 1,
      "z": 3,
      "name": "Rock_Runic_Blue_Brick"
    },
    {
      "x": -6,
      "y": 2,
      "z": 3,
      "name": "Rock_Runic_Blue_Brick"
    },
    {
      "x": -6,
      "y": 3,
      "z": 3,
      "name": "Rock_Runic_Blue_Brick"
    },
    {
      "x": -6,
      "y": 4,
      "z": 3,
      "name": "Rock_Runic_Blue_Brick"
    },
    {
      "x": -6,
      "y": 5,
      "z": 3,
      "name": "Rock_Runic_Blue_Brick"
    },
    {
      "x": -6,
      "y": 6,
      "z": 3,
      "name": "Rock_Runic_Blue_Brick"
    },
    {
      "x": -6,
      "y": 7,
      "z": 3,
      "name": "Rock_Runic_Blue_Brick"
    },
    {
      "x": -6,
      "y": 0,
      "z": 4,
      "name": "Rock_Runic_Blue_Brick"
    },
    {
      "x": -6,
      "y": 1,
      "z": 4,
      "name": "Rock_Runic_Blue_Brick"
    },
    {
      "x": -6,
      "y": 2,
      "z": 4,
      "name": "Rock_Runic_Blue_Brick"
    },
    {
      "x": -6,
      "y": 3,
      "z": 4,
      "name": "Rock_Runic_Blue_Brick"
    },
    {
      "x": -6,
      "y": 4,
      "z": 4,
      "name": "Rock_Runic_Blue_Brick"
    },
    {
      "x": -6,
      "y": 5,
      "z": 4,
      "name": "Rock_Runic_Blue_Brick"
    },
    {
      "x": -6,
      "y": 6,
      "z": 4,
      "name": "Rock_Runic_Blue_Brick"
    },
    {
      "x": -6,
      "y": 7,
      "z": 4,
      "name": "Rock_Runic_Blue_Brick"
    },
    {
      "x": -6,
      "y": 0,
      "z": 5,
      "name": "Rock_Runic_Blue_Brick"
    },
    {
      "x": -6,
      "y": 1,
      "z": 5,
      "name": "Rock_Runic_Blue_Brick"
    },
    {
      "x": -6,
      "y": 2,
      "z": 5,
      "name": "Rock_Runic_Blue_Brick"
    },
    {
      "x": -6,
      "y": 3,
      "z": 5,
      "name": "Rock_Runic_Blue_Brick"
    },
    {
      "x": -6,
      "y": 4,
      "z": 5,
      "name": "Rock_Runic_Blue_Brick"
    },
    {
      "x": -6,
      "y": 5,
      "z": 5,
      "name": "Rock_Runic_Blue_Brick"
    },
    {
      "x": -6,
      "y": 6,
      "z": 5,
      "name": "Rock_Runic_Blue_Brick"
    },
    {
      "x": -6,
      "y": 7,
      "z": 5,
      "name": "Rock_Runic_Blue_Brick"
    },
    {
      "x": -6,
      "y": 0,
      "z": 6,
      "name": "Rock_Runic_Blue_Brick"
    },
    {
      "x": -6,
      "y": 1,
      "z": 6,
      "name": "Rock_Runic_Blue_Brick"
    },
    {
      "x": -6,
      "y": 2,
      "z": 6,
      "name": "Rock_Runic_Blue_Brick"
    },
    {
      "x": -6,
      "y": 3,
      "z": 6,
      "name": "Rock_Runic_Blue_Brick"
    },
    {
      "x": -6,
      "y": 4,
      "z": 6,
      "name": "Rock_Runic_Blue_Brick"
    },
    {
      "x": -6,
      "y": 5,
      "z": 6,
      "name": "Rock_Runic_Blue_Brick"
    },
    {
      "x": -6,
      "y": 6,
      "z": 6,
      "name": "Rock_Runic_Blue_Brick"
    },
    {
      "x": -6,
      "y": 7,
      "z": 6,
      "name": "Rock_Runic_Blue_Brick"
    },
    {
      "x": -6,
      "y": 0,
      "z": 7,
      "name": "Rock_Runic_Blue_Brick"
    },
    {
      "x": -6,
      "y": 1,
      "z": 7,
      "name": "Rock_Runic_Blue_Brick"
    },
    {
      "x": -6,
      "y": 2,
      "z": 7,
      "name": "Rock_Runic_Blue_Brick"
    },
    {
      "x": -6,
      "y": 3,
      "z": 7,
      "name": "Rock_Runic_Blue_Brick"
    },
    {
      "x": -6,
      "y": 4,
      "z": 7,
      "name": "Rock_Runic_Blue_Brick"
    },
    {
      "x": -6,
      "y": 5,
      "z": 7,
      "name": "Rock_Runic_Blue_Brick"
    },
    {
      "x": -6,
      "y": 6,
      "z": 7,
      "name": "Rock_Runic_Blue_Brick"
    },
    {
      "x": -6,
      "y": 7,
      "z": 7,
      "name": "Rock_Runic_Blue_Brick"
    },
    {
      "x": -6,
      "y": 0,
      "z": 8,
      "name": "Rock_Runic_Blue_Brick"
    },
    {
      "x": -6,
      "y": 1,
      "z": 8,
      "name": "Rock_Runic_Blue_Brick"
    },
    {
      "x": -6,
      "y": 2,
      "z": 8,
      "name": "Rock_Runic_Blue_Brick"
    },
    {
      "x": -6,
      "y": 3,
      "z": 8,
      "name": "Rock_Runic_Blue_Brick"
    },
    {
      "x": -6,
      "y": 4,
      "z": 8,
      "name": "Rock_Runic_Blue_Brick"
    },
    {
      "x": -6,
      "y": 5,
      "z": 8,
      "name": "Rock_Runic_Blue_Brick"
    },
    {
      "x": -6,
      "y": 6,
      "z": 8,
      "name": "Rock_Runic_Blue_Brick"
    },
    {
      "x": -6,
      "y": 7,
      "z": 8,
      "name": "Rock_Runic_Blue_Brick"
    },
    {
      "x": -6,
      "y": 0,
      "z": 9,
      "name": "Rock_Runic_Blue_Brick"
    },
    {
      "x": -6,
      "y": 1,
      "z": 9,
      "name": "Rock_Runic_Blue_Brick"
    },
    {
      "x": -6,
      "y": 2,
      "z": 9,
      "name": "Rock_Runic_Blue_Brick"
    },
    {
      "x": -6,
      "y": 3,
      "z": 9,
      "name": "Rock_Runic_Blue_Brick"
    },
    {
      "x": -6,
      "y": 4,
      "z": 9,
      "name": "Rock_Runic_Blue_Brick"
    },
    {
      "x": -6,
      "y": 5,
      "z": 9,
      "name": "Rock_Runic_Blue_Brick"
    },
    {
      "x": -6,
      "y": 6,
      "z": 9,
      "name": "Rock_Runic_Blue_Brick"
    },
    {
      "x": -6,
      "y": 7,
      "z": 9,
      "name": "Rock_Runic_Blue_Brick"
    },
    {
      "x": -6,
      "y": 0,
      "z": 10,
      "name": "Rock_Runic_Blue_Brick"
    },
    {
      "x": -6,
      "y": 1,
      "z": 10,
      "name": "Rock_Runic_Blue_Brick"
    },
    {
      "x": -6,
      "y": 2,
      "z": 10,
      "name": "Rock_Runic_Blue_Brick"
    },
    {
      "x": -6,
      "y": 3,
      "z": 10,
      "name": "Rock_Runic_Blue_Brick"
    },
    {
      "x": -6,
      "y": 4,
      "z": 10,
      "name": "Rock_Runic_Blue_Brick"
    },
    {
      "x": -6,
      "y": 5,
      "z": 10,
      "name": "Rock_Runic_Blue_Brick"
    },
    {
      "x": -6,
      "y": 6,
      "z": 10,
      "name": "Rock_Runic_Blue_Brick"
    },
    {
      "x": -6,
      "y": 7,
      "z": 10,
      "name": "Rock_Runic_Blue_Brick"
    },
    {
      "x": -6,
      "y": 0,
      "z": 11,
      "name": "Rock_Runic_Blue_Brick"
    },
    {
      "x": -6,
      "y": 1,
      "z": 11,
      "name": "Rock_Runic_Blue_Brick"
    },
    {
      "x": -6,
      "y": 2,
      "z": 11,
      "name": "Rock_Runic_Blue_Brick"
    },
    {
      "x": -6,
      "y": 3,
      "z": 11,
      "name": "Rock_Runic_Blue_Brick"
    },
    {
      "x": -6,
      "y": 4,
      "z": 11,
      "name": "Rock_Runic_Blue_Brick"
    },
    {
      "x": -6,
      "y": 5,
      "z": 11,
      "name": "Rock_Runic_Blue_Brick"
    },
    {
      "x": -6,
      "y": 6,
      "z": 11,
      "name": "Rock_Runic_Blue_Brick"
    },
    {
      "x": -6,
      "y": 7,
      "z": 11,
      "name": "Rock_Runic_Blue_Brick"
    },
    {
      "x": -6,
      "y": 0,
      "z": 12,
      "name": "Rock_Runic_Blue_Brick_Stairs",
      "rotation": 9
    },
    {
      "x": -6,
      "y": 1,
      "z": 12,
      "name": "Rock_Runic_Blue_Brick"
    },
    {
      "x": -6,
      "y": 2,
      "z": 12,
      "name": "Rock_Runic_Blue_Brick"
    },
    {
      "x": -6,
      "y": 3,
      "z": 12,
      "name": "Rock_Runic_Blue_Brick"
    },
    {
      "x": -6,
      "y": 4,
      "z": 12,
      "name": "Rock_Runic_Blue_Brick"
    },
    {
      "x": -6,
      "y": 5,
      "z": 12,
      "name": "Rock_Runic_Blue_Brick"
    },
    {
      "x": -6,
      "y": 6,
      "z": 12,
      "name": "Rock_Runic_Blue_Brick"
    },
    {
      "x": -6,
      "y": 7,
      "z": 12,
      "name": "Rock_Runic_Blue_Brick"
    },
    {
      "x": -6,
      "y": 0,
      "z": 13,
      "name": "*Rock_Runic_Blue_Brick_Stairs_State_Definitions_Corner_Left",
      "rotation": 10
    },
    {
      "x": -6,
      "y": 1,
      "z": 13,
      "name": "Rock_Runic_Blue_Brick"
    },
    {
      "x": -6,
      "y": 2,
      "z": 13,
      "name": "Rock_Runic_Blue_Brick"
    },
    {
      "x": -6,
      "y": 3,
      "z": 13,
      "name": "Rock_Runic_Blue_Brick"
    },
    {
      "x": -6,
      "y": 4,
      "z": 13,
      "name": "Rock_Runic_Blue_Brick"
    },
    {
      "x": -6,
      "y": 5,
      "z": 13,
      "name": "Rock_Runic_Blue_Brick"
    },
    {
      "x": -6,
      "y": 6,
      "z": 13,
      "name": "Rock_Runic_Blue_Brick"
    },
    {
      "x": -6,
      "y": 7,
      "z": 13,
      "name": "Rock_Runic_Blue_Brick"
    },
    {
      "x": -5,
      "y": 0,
      "z": -10,
      "name": "Rock_Runic_Blue_Brick_Stairs",
      "rotation": 8
    },
    {
      "x": -5,
      "y": 1,
      "z": -10,
      "name": "Rock_Runic_Blue_Brick_Stairs",
      "rotation": 1
    },
    {
      "x": -5,
      "y": 6,
      "z": -10,
      "name": "Rock_Runic_Blue_Brick_Stairs",
      "rotation": 11
    },
    {
      "x": -5,
      "y": 7,
      "z": -10,
      "name": "Rock_Runic_Blue_Brick"
    },
    {
      "x": -5,
      "y": 7,
      "z": -9,
      "name": "Rock_Runic_Blue_Brick"
    },
    {
      "x": -5,
      "y": 7,
      "z": -8,
      "name": "Rock_Runic_Blue_Brick"
    },
    {
      "x": -5,
      "y": 7,
      "z": -7,
      "name": "Rock_Runic_Blue_Brick"
    },
    {
      "x": -5,
      "y": 8,
      "z": -7,
      "name": "Plant_Seaweed_Dead_Short",
      "support": 15
    },
    {
      "x": -5,
      "y": 7,
      "z": -6,
      "name": "Rock_Runic_Blue_Brick"
    },
    {
      "x": -5,
      "y": 8,
      "z": -6,
      "name": "Plant_Seaweed_Dead_Ghostly",
      "support": 15
    },
    {
      "x": -5,
      "y": 9,
      "z": -6,
      "name": "Plant_Seaweed_Dead_Ghostly",
      "filler": 1024
    },
    {
      "x": -5,
      "y": 7,
      "z": -5,
      "name": "Rock_Runic_Blue_Brick"
    },
    {
      "x": -5,
      "y": 7,
      "z": -4,
      "name": "Rock_Runic_Blue_Brick"
    },
    {
      "x": -5,
      "y": 7,
      "z": -3,
      "name": "Rock_Runic_Blue_Brick"
    },
    {
      "x": -5,
      "y": 7,
      "z": -2,
      "name": "Rock_Runic_Blue_Brick"
    },
    {
      "x": -5,
      "y": 7,
      "z": -1,
      "name": "Rock_Runic_Blue_Brick"
    },
    {
      "x": -5,
      "y": 7,
      "z": 0,
      "name": "Furniture_Temple_Light_Trapdoor"
    },
    {
      "x": -5,
      "y": 7,
      "z": 1,
      "name": "Rock_Marble_Brick"
    },
    {
      "x": -5,
      "y": 7,
      "z": 2,
      "name": "Furniture_Temple_Light_Trapdoor",
      "rotation": 2
    },
    {
      "x": -5,
      "y": 7,
      "z": 3,
      "name": "Rock_Runic_Blue_Brick"
    },
    {
      "x": -5,
      "y": 7,
      "z": 4,
      "name": "Rock_Runic_Blue_Brick"
    },
    {
      "x": -5,
      "y": 7,
      "z": 5,
      "name": "Rock_Runic_Blue_Brick"
    },
    {
      "x": -5,
      "y": 7,
      "z": 6,
      "name": "Rock_Runic_Blue_Brick"
    },
    {
      "x": -5,
      "y": 7,
      "z": 7,
      "name": "Rock_Runic_Blue_Brick"
    },
    {
      "x": -5,
      "y": 7,
      "z": 8,
      "name": "Rock_Runic_Blue_Brick"
    },
    {
      "x": -5,
      "y": 7,
      "z": 9,
      "name": "Rock_Runic_Blue_Brick"
    },
    {
      "x": -5,
      "y": 7,
      "z": 10,
      "name": "Rock_Runic_Blue_Brick"
    },
    {
      "x": -5,
      "y": 8,
      "z": 10,
      "name": "Plant_Seaweed_Dead_Short",
      "support": 15
    },
    {
      "x": -5,
      "y": 7,
      "z": 11,
      "name": "Rock_Runic_Blue_Brick"
    },
    {
      "x": -5,
      "y": 7,
      "z": 12,
      "name": "Rock_Runic_Blue_Brick"
    },
    {
      "x": -5,
      "y": 0,
      "z": 13,
      "name": "Rock_Runic_Blue_Brick_Stairs",
      "rotation": 10
    },
    {
      "x": -5,
      "y": 1,
      "z": 13,
      "name": "Rock_Runic_Blue_Brick_Stairs",
      "rotation": 1
    },
    {
      "x": -5,
      "y": 6,
      "z": 13,
      "name": "Rock_Runic_Blue_Brick_Stairs",
      "rotation": 11
    },
    {
      "x": -5,
      "y": 7,
      "z": 13,
      "name": "Rock_Runic_Blue_Brick"
    },
    {
      "x": -4,
      "y": 0,
      "z": -11,
      "name": "Plant_Seaweed_Dead_Ghostly",
      "support": 15
    },
    {
      "x": -4,
      "y": 1,
      "z": -11,
      "name": "Plant_Seaweed_Dead_Ghostly",
      "filler": 1024
    },
    {
      "x": -4,
      "y": 0,
      "z": -10,
      "name": "Rock_Runic_Blue_Brick"
    },
    {
      "x": -4,
      "y": 7,
      "z": -10,
      "name": "Rock_Runic_Blue_Brick"
    },
    {
      "x": -4,
      "y": 7,
      "z": -9,
      "name": "Rock_Runic_Blue_Brick"
    },
    {
      "x": -4,
      "y": 7,
      "z": -8,
      "name": "Rock_Runic_Blue_Brick"
    },
    {
      "x": -4,
      "y": 7,
      "z": -7,
      "name": "Rock_Runic_Blue_Brick"
    },
    {
      "x": -4,
      "y": 8,
      "z": -7,
      "name": "Plant_Seaweed_Dead_Short",
      "support": 15
    },
    {
      "x": -4,
      "y": 7,
      "z": -6,
      "name": "Rock_Runic_Blue_Brick"
    },
    {
      "x": -4,
      "y": 8,
      "z": -6,
      "name": "Plant_Seaweed_Dead_Short",
      "support": 15
    },
    {
      "x": -4,
      "y": 7,
      "z": -5,
      "name": "Rock_Runic_Blue_Brick"
    },
    {
      "x": -4,
      "y": 7,
      "z": -4,
      "name": "Rock_Runic_Blue_Brick"
    },
    {
      "x": -4,
      "y": 7,
      "z": -3,
      "name": "Rock_Runic_Blue_Brick"
    },
    {
      "x": -4,
      "y": 7,
      "z": -2,
      "name": "Rock_Runic_Blue_Brick"
    },
    {
      "x": -4,
      "y": 7,
      "z": -1,
      "name": "Rock_Runic_Blue_Brick"
    },
    {
      "x": -4,
      "y": 7,
      "z": 0,
      "name": "Furniture_Temple_Light_Trapdoor"
    },
    {
      "x": -4,
      "y": 7,
      "z": 1,
      "name": "Rock_Marble_Brick"
    },
    {
      "x": -4,
      "y": 7,
      "z": 2,
      "name": "Furniture_Temple_Light_Trapdoor",
      "rotation": 2
    },
    {
      "x": -4,
      "y": 7,
      "z": 3,
      "name": "Rock_Runic_Blue_Brick"
    },
    {
      "x": -4,
      "y": 7,
      "z": 4,
      "name": "Rock_Runic_Blue_Brick"
    },
    {
      "x": -4,
      "y": 7,
      "z": 5,
      "name": "Rock_Runic_Blue_Brick"
    },
    {
      "x": -4,
      "y": 7,
      "z": 6,
      "name": "Rock_Runic_Blue_Brick"
    },
    {
      "x": -4,
      "y": 7,
      "z": 7,
      "name": "Rock_Runic_Blue_Brick"
    },
    {
      "x": -4,
      "y": 7,
      "z": 8,
      "name": "Rock_Runic_Blue_Brick"
    },
    {
      "x": -4,
      "y": 7,
      "z": 9,
      "name": "Rock_Runic_Blue_Brick"
    },
    {
      "x": -4,
      "y": 8,
      "z": 9,
      "name": "Plant_Seaweed_Dead_Short",
      "support": 15
    },
    {
      "x": -4,
      "y": 7,
      "z": 10,
      "name": "Rock_Runic_Blue_Brick"
    },
    {
      "x": -4,
      "y": 8,
      "z": 10,
      "name": "Plant_Seaweed_Dead_Short",
      "support": 15
    },
    {
      "x": -4,
      "y": 7,
      "z": 11,
      "name": "Rock_Runic_Blue_Brick"
    },
    {
      "x": -4,
      "y": 7,
      "z": 12,
      "name": "Rock_Runic_Blue_Brick"
    },
    {
      "x": -4,
      "y": 0,
      "z": 13,
      "name": "Rock_Runic_Blue_Brick"
    },
    {
      "x": -4,
      "y": 7,
      "z": 13,
      "name": "Rock_Runic_Blue_Brick"
    },
    {
      "x": -3,
      "y": 0,
      "z": -11,
      "name": "Plant_Seaweed_Dead_Short",
      "support": 15
    },
    {
      "x": -3,
      "y": 0,
      "z": -10,
      "name": "Rock_Runic_Blue_Brick"
    },
    {
      "x": -3,
      "y": 7,
      "z": -10,
      "name": "Rock_Runic_Blue_Brick"
    },
    {
      "x": -3,
      "y": 8,
      "z": -10,
      "name": "Rock_Runic_Blue_Brick_Stairs",
      "rotation": 3
    },
    {
      "x": -3,
      "y": 7,
      "z": -9,
      "name": "Rock_Runic_Blue_Brick"
    },
    {
      "x": -3,
      "y": 7,
      "z": -8,
      "name": "Rock_Runic_Blue_Brick"
    },
    {
      "x": -3,
      "y": 7,
      "z": -7,
      "name": "Rock_Runic_Blue_Brick"
    },
    {
      "x": -3,
      "y": 8,
      "z": -7,
      "name": "Plant_Seaweed_Dead_Short",
      "support": 15
    },
    {
      "x": -3,
      "y": 7,
      "z": -6,
      "name": "Rock_Runic_Blue_Brick"
    },
    {
      "x": -3,
      "y": 7,
      "z": -5,
      "name": "Rock_Runic_Blue_Brick"
    },
    {
      "x": -3,
      "y": 7,
      "z": -4,
      "name": "Rock_Runic_Blue_Brick"
    },
    {
      "x": -3,
      "y": 7,
      "z": -3,
      "name": "Rock_Runic_Blue_Brick"
    },
    {
      "x": -3,
      "y": 7,
      "z": -2,
      "name": "Rock_Runic_Blue_Brick"
    },
    {
      "x": -3,
      "y": 7,
      "z": -1,
      "name": "Rock_Runic_Blue_Brick"
    },
    {
      "x": -3,
      "y": 7,
      "z": 0,
      "name": "Furniture_Temple_Light_Trapdoor"
    },
    {
      "x": -3,
      "y": 7,
      "z": 1,
      "name": "Rock_Marble_Brick"
    },
    {
      "x": -3,
      "y": 7,
      "z": 2,
      "name": "Furniture_Temple_Light_Trapdoor",
      "rotation": 2
    },
    {
      "x": -3,
      "y": 7,
      "z": 3,
      "name": "Rock_Runic_Blue_Brick"
    },
    {
      "x": -3,
      "y": 7,
      "z": 4,
      "name": "Rock_Runic_Blue_Brick"
    },
    {
      "x": -3,
      "y": 7,
      "z": 5,
      "name": "Rock_Runic_Blue_Brick"
    },
    {
      "x": -3,
      "y": 7,
      "z": 6,
      "name": "Rock_Runic_Blue_Brick"
    },
    {
      "x": -3,
      "y": 7,
      "z": 7,
      "name": "Rock_Runic_Blue_Brick"
    },
    {
      "x": -3,
      "y": 7,
      "z": 8,
      "name": "Rock_Runic_Blue_Brick"
    },
    {
      "x": -3,
      "y": 7,
      "z": 9,
      "name": "Rock_Runic_Blue_Brick"
    },
    {
      "x": -3,
      "y": 7,
      "z": 10,
      "name": "Rock_Runic_Blue_Brick"
    },
    {
      "x": -3,
      "y": 8,
      "z": 10,
      "name": "Plant_Seaweed_Dead_Short",
      "support": 15
    },
    {
      "x": -3,
      "y": 7,
      "z": 11,
      "name": "Rock_Runic_Blue_Brick"
    },
    {
      "x": -3,
      "y": 8,
      "z": 11,
      "name": "Plant_Seaweed_Dead_Short",
      "support": 15
    },
    {
      "x": -3,
      "y": 7,
      "z": 12,
      "name": "Rock_Runic_Blue_Brick"
    },
    {
      "x": -3,
      "y": 0,
      "z": 13,
      "name": "Rock_Runic_Blue_Brick"
    },
    {
      "x": -3,
      "y": 7,
      "z": 13,
      "name": "Rock_Runic_Blue_Brick"
    },
    {
      "x": -3,
      "y": 8,
      "z": 13,
      "name": "Rock_Runic_Blue_Brick_Stairs",
      "rotation": 3
    },
    {
      "x": -2,
      "y": 0,
      "z": -12,
      "name": "Plant_Seaweed_Dead_Short",
      "support": 15
    },
    {
      "x": -2,
      "y": 0,
      "z": -11,
      "name": "Plant_Seaweed_Dead_Ghostly",
      "support": 15
    },
    {
      "x": -2,
      "y": 1,
      "z": -11,
      "name": "Plant_Seaweed_Dead_Ghostly",
      "filler": 1024
    },
    {
      "x": -2,
      "y": 0,
      "z": -10,
      "name": "Rock_Runic_Blue_Brick"
    },
    {
      "x": -2,
      "y": 7,
      "z": -10,
      "name": "Rock_Runic_Blue_Brick"
    },
    {
      "x": -2,
      "y": 8,
      "z": -10,
      "name": "Rock_Runic_Blue_Brick"
    },
    {
      "x": -2,
      "y": 7,
      "z": -9,
      "name": "Rock_Runic_Blue_Brick"
    },
    {
      "x": -2,
      "y": 7,
      "z": -8,
      "name": "Rock_Runic_Blue_Brick"
    },
    {
      "x": -2,
      "y": 7,
      "z": -7,
      "name": "Rock_Runic_Blue_Brick"
    },
    {
      "x": -2,
      "y": 7,
      "z": -6,
      "name": "Rock_Runic_Blue_Brick"
    },
    {
      "x": -2,
      "y": 7,
      "z": -5,
      "name": "Rock_Runic_Blue_Brick"
    },
    {
      "x": -2,
      "y": 7,
      "z": -4,
      "name": "Rock_Runic_Blue_Brick"
    },
    {
      "x": -2,
      "y": 7,
      "z": -3,
      "name": "Rock_Runic_Blue_Brick"
    },
    {
      "x": -2,
      "y": 7,
      "z": -2,
      "name": "Rock_Runic_Blue_Brick"
    },
    {
      "x": -2,
      "y": 7,
      "z": -1,
      "name": "Rock_Runic_Blue_Brick"
    },
    {
      "x": -2,
      "y": 7,
      "z": 0,
      "name": "Rock_Runic_Blue_Brick"
    },
    {
      "x": -2,
      "y": 7,
      "z": 1,
      "name": "Rock_Runic_Blue_Brick"
    },
    {
      "x": -2,
      "y": 7,
      "z": 2,
      "name": "Rock_Runic_Blue_Brick"
    },
    {
      "x": -2,
      "y": 7,
      "z": 3,
      "name": "Rock_Runic_Blue_Brick"
    },
    {
      "x": -2,
      "y": 7,
      "z": 4,
      "name": "Rock_Runic_Blue_Brick"
    },
    {
      "x": -2,
      "y": 7,
      "z": 5,
      "name": "Rock_Runic_Blue_Brick"
    },
    {
      "x": -2,
      "y": 7,
      "z": 6,
      "name": "Rock_Runic_Blue_Brick"
    },
    {
      "x": -2,
      "y": 7,
      "z": 7,
      "name": "Rock_Runic_Blue_Brick"
    },
    {
      "x": -2,
      "y": 7,
      "z": 8,
      "name": "Rock_Runic_Blue_Brick"
    },
    {
      "x": -2,
      "y": 7,
      "z": 9,
      "name": "Rock_Runic_Blue_Brick"
    },
    {
      "x": -2,
      "y": 7,
      "z": 10,
      "name": "Rock_Runic_Blue_Brick"
    },
    {
      "x": -2,
      "y": 7,
      "z": 11,
      "name": "Rock_Runic_Blue_Brick"
    },
    {
      "x": -2,
      "y": 7,
      "z": 12,
      "name": "Rock_Runic_Blue_Brick"
    },
    {
      "x": -2,
      "y": 0,
      "z": 13,
      "name": "Rock_Runic_Blue_Brick"
    },
    {
      "x": -2,
      "y": 7,
      "z": 13,
      "name": "Rock_Runic_Blue_Brick"
    },
    {
      "x": -2,
      "y": 8,
      "z": 13,
      "name": "Rock_Runic_Blue_Brick"
    },
    {
      "x": -1,
      "y": 0,
      "z": -10,
      "name": "Rock_Runic_Blue_Brick"
    },
    {
      "x": -1,
      "y": 1,
      "z": -10,
      "name": "Rock_Runic_Blue_Brick_Stairs",
      "rotation": 3
    },
    {
      "x": -1,
      "y": 6,
      "z": -10,
      "name": "Rock_Runic_Blue_Brick_Stairs",
      "rotation": 9
    },
    {
      "x": -1,
      "y": 7,
      "z": -10,
      "name": "Rock_Runic_Blue_Brick"
    },
    {
      "x": -1,
      "y": 8,
      "z": -10,
      "name": "Rock_Runic_Blue_Brick"
    },
    {
      "x": -1,
      "y": 8,
      "z": -9,
      "name": "Rock_Runic_Blue_Brick"
    },
    {
      "x": -1,
      "y": 8,
      "z": -8,
      "name": "Rock_Runic_Blue_Brick"
    },
    {
      "x": -1,
      "y": 9,
      "z": -8,
      "name": "Plant_Seaweed_Dead_Short",
      "support": 15
    },
    {
      "x": -1,
      "y": 8,
      "z": -7,
      "name": "Rock_Runic_Blue_Brick"
    },
    {
      "x": -1,
      "y": 8,
      "z": -6,
      "name": "Rock_Runic_Blue_Brick"
    },
    {
      "x": -1,
      "y": 8,
      "z": -5,
      "name": "Rock_Runic_Blue_Brick"
    },
    {
      "x": -1,
      "y": 8,
      "z": -4,
      "name": "Rock_Runic_Blue_Brick"
    },
    {
      "x": -1,
      "y": 8,
      "z": -3,
      "name": "Rock_Runic_Blue_Brick"
    },
    {
      "x": -1,
      "y": 8,
      "z": -2,
      "name": "Rock_Runic_Blue_Brick"
    },
    {
      "x": -1,
      "y": 8,
      "z": -1,
      "name": "Rock_Runic_Blue_Brick"
    },
    {
      "x": -1,
      "y": 8,
      "z": 0,
      "name": "Rock_Runic_Blue_Brick"
    },
    {
      "x": -1,
      "y": 8,
      "z": 1,
      "name": "Rock_Runic_Blue_Brick"
    },
    {
      "x": -1,
      "y": 9,
      "z": 1,
      "name": "Plant_Seaweed_Dead_Short",
      "support": 15
    },
    {
      "x": -1,
      "y": 8,
      "z": 2,
      "name": "Rock_Runic_Blue_Brick"
    },
    {
      "x": -1,
      "y": 9,
      "z": 2,
      "name": "Plant_Seaweed_Dead_Short",
      "support": 15
    },
    {
      "x": -1,
      "y": 8,
      "z": 3,
      "name": "Rock_Runic_Blue_Brick"
    },
    {
      "x": -1,
      "y": 8,
      "z": 4,
      "name": "Rock_Runic_Blue_Brick"
    },
    {
      "x": -1,
      "y": 8,
      "z": 5,
      "name": "Rock_Runic_Blue_Brick"
    },
    {
      "x": -1,
      "y": 8,
      "z": 6,
      "name": "Rock_Runic_Blue_Brick"
    },
    {
      "x": -1,
      "y": 8,
      "z": 7,
      "name": "Rock_Runic_Blue_Brick"
    },
    {
      "x": -1,
      "y": 8,
      "z": 8,
      "name": "Rock_Runic_Blue_Brick"
    },
    {
      "x": -1,
      "y": 8,
      "z": 9,
      "name": "Rock_Runic_Blue_Brick"
    },
    {
      "x": -1,
      "y": 8,
      "z": 10,
      "name": "Rock_Runic_Blue_Brick"
    },
    {
      "x": -1,
      "y": 8,
      "z": 11,
      "name": "Rock_Runic_Blue_Brick"
    },
    {
      "x": -1,
      "y": 8,
      "z": 12,
      "name": "Rock_Runic_Blue_Brick"
    },
    {
      "x": -1,
      "y": 0,
      "z": 13,
      "name": "Rock_Runic_Blue_Brick"
    },
    {
      "x": -1,
      "y": 8,
      "z": 13,
      "name": "Rock_Runic_Blue_Brick"
    },
    {
      "x": 0,
      "y": 0,
      "z": -10,
      "name": "Rock_Runic_Blue_Brick"
    },
    {
      "x": 0,
      "y": 1,
      "z": -10,
      "name": "Rock_Runic_Blue_Brick"
    },
    {
      "x": 0,
      "y": 2,
      "z": -10,
      "name": "Rock_Runic_Blue_Brick"
    },
    {
      "x": 0,
      "y": 3,
      "z": -10,
      "name": "Rock_Runic_Blue_Brick"
    },
    {
      "x": 0,
      "y": 4,
      "z": -10,
      "name": "Rock_Runic_Blue_Brick"
    },
    {
      "x": 0,
      "y": 5,
      "z": -10,
      "name": "Rock_Runic_Blue_Brick"
    },
    {
      "x": 0,
      "y": 6,
      "z": -10,
      "name": "Rock_Runic_Blue_Brick"
    },
    {
      "x": 0,
      "y": 7,
      "z": -10,
      "name": "Rock_Runic_Blue_Brick"
    },
    {
      "x": 0,
      "y": 8,
      "z": -10,
      "name": "Rock_Runic_Blue_Brick"
    },
    {
      "x": 0,
      "y": 9,
      "z": -10,
      "name": "Rock_Runic_Blue_Brick_Stairs",
      "rotation": 3
    },
    {
      "x": 0,
      "y": 0,
      "z": -9,
      "name": "Deco_Iron_Bars",
      "rotation": 1
    },
    {
      "x": 0,
      "y": 8,
      "z": -9,
      "name": "Rock_Runic_Blue_Brick"
    },
    {
      "x": 0,
      "y": 9,
      "z": -9,
      "name": "Plant_Seaweed_Dead_Short",
      "support": 15
    },
    {
      "x": 0,
      "y": 0,
      "z": -8,
      "name": "Deco_Iron_Bars",
      "rotation": 1
    },
    {
      "x": 0,
      "y": 8,
      "z": -8,
      "name": "Rock_Runic_Blue_Brick"
    },
    {
      "x": 0,
      "y": 9,
      "z": -8,
      "name": "Plant_Seaweed_Dead_Ghostly",
      "support": 15
    },
    {
      "x": 0,
      "y": 10,
      "z": -8,
      "name": "Plant_Seaweed_Dead_Ghostly",
      "filler": 1024
    },
    {
      "x": 0,
      "y": 0,
      "z": -7,
      "name": "Deco_Iron_Bars",
      "rotation": 1
    },
    {
      "x": 0,
      "y": 8,
      "z": -7,
      "name": "Rock_Runic_Blue_Brick"
    },
    {
      "x": 0,
      "y": 0,
      "z": -6,
      "name": "Deco_Iron_Bars",
      "rotation": 1
    },
    {
      "x": 0,
      "y": 8,
      "z": -6,
      "name": "Rock_Runic_Blue_Brick"
    },
    {
      "x": 0,
      "y": 0,
      "z": -5,
      "name": "Deco_Iron_Bars",
      "rotation": 1
    },
    {
      "x": 0,
      "y": 8,
      "z": -5,
      "name": "Rock_Runic_Blue_Brick"
    },
    {
      "x": 0,
      "y": 0,
      "z": -4,
      "name": "Deco_Iron_Bars",
      "rotation": 1
    },
    {
      "x": 0,
      "y": 8,
      "z": -4,
      "name": "Rock_Runic_Blue_Brick"
    },
    {
      "x": 0,
      "y": 0,
      "z": -3,
      "name": "Rock_Runic_Blue_Brick"
    },
    {
      "x": 0,
      "y": 8,
      "z": -3,
      "name": "Rock_Runic_Blue_Brick"
    },
    {
      "x": 0,
      "y": 8,
      "z": -2,
      "name": "Rock_Runic_Blue_Brick"
    },
    {
      "x": 0,
      "y": 8,
      "z": -1,
      "name": "Rock_Runic_Blue_Brick"
    },
    {
      "x": 0,
      "y": 8,
      "z": 0,
      "name": "Rock_Runic_Blue_Brick"
    },
    {
      "x": 0,
      "y": 8,
      "z": 1,
      "name": "Rock_Runic_Blue_Brick"
    },
    {
      "x": 0,
      "y": 8,
      "z": 2,
      "name": "Rock_Runic_Blue_Brick"
    },
    {
      "x": 0,
      "y": 9,
      "z": 2,
      "name": "Plant_Seaweed_Dead_Ghostly",
      "support": 15
    },
    {
      "x": 0,
      "y": 10,
      "z": 2,
      "name": "Plant_Seaweed_Dead_Ghostly",
      "filler": 1024
    },
    {
      "x": 0,
      "y": 8,
      "z": 3,
      "name": "Rock_Runic_Blue_Brick"
    },
    {
      "x": 0,
      "y": 8,
      "z": 4,
      "name": "Rock_Runic_Blue_Brick"
    },
    {
      "x": 0,
      "y": 8,
      "z": 5,
      "name": "Rock_Runic_Blue_Brick"
    },
    {
      "x": 0,
      "y": 8,
      "z": 6,
      "name": "Rock_Runic_Blue_Brick"
    },
    {
      "x": 0,
      "y": 8,
      "z": 7,
      "name": "Rock_Runic_Blue_Brick"
    },
    {
      "x": 0,
      "y": 8,
      "z": 8,
      "name": "Rock_Runic_Blue_Brick"
    },
    {
      "x": 0,
      "y": 8,
      "z": 9,
      "name": "Rock_Runic_Blue_Brick"
    },
    {
      "x": 0,
      "y": 8,
      "z": 10,
      "name": "Rock_Runic_Blue_Brick"
    },
    {
      "x": 0,
      "y": 8,
      "z": 11,
      "name": "Rock_Runic_Blue_Brick"
    },
    {
      "x": 0,
      "y": 8,
      "z": 12,
      "name": "Rock_Runic_Blue_Brick"
    },
    {
      "x": 0,
      "y": 0,
      "z": 13,
      "name": "Rock_Runic_Blue_Brick"
    },
    {
      "x": 0,
      "y": 8,
      "z": 13,
      "name": "Rock_Runic_Blue_Brick"
    },
    {
      "x": 0,
      "y": 9,
      "z": 13,
      "name": "Rock_Runic_Blue_Brick_Stairs",
      "rotation": 3
    },
    {
      "x": 1,
      "y": 0,
      "z": -10,
      "name": "Rock_Runic_Blue_Brick"
    },
    {
      "x": 1,
      "y": 1,
      "z": -10,
      "name": "Rock_Runic_Blue_Brick"
    },
    {
      "x": 1,
      "y": 2,
      "z": -10,
      "name": "Rock_Runic_Blue_Brick"
    },
    {
      "x": 1,
      "y": 3,
      "z": -10,
      "name": "Rock_Runic_Blue_Brick"
    },
    {
      "x": 1,
      "y": 4,
      "z": -10,
      "name": "Rock_Runic_Blue_Brick"
    },
    {
      "x": 1,
      "y": 5,
      "z": -10,
      "name": "Rock_Runic_Blue_Brick"
    },
    {
      "x": 1,
      "y": 6,
      "z": -10,
      "name": "Rock_Runic_Blue_Brick"
    },
    {
      "x": 1,
      "y": 7,
      "z": -10,
      "name": "Rock_Runic_Blue_Brick"
    },
    {
      "x": 1,
      "y": 8,
      "z": -10,
      "name": "Rock_Runic_Blue_Brick"
    },
    {
      "x": 1,
      "y": 9,
      "z": -10,
      "name": "Rock_Runic_Blue_Brick"
    },
    {
      "x": 1,
      "y": 1,
      "z": -9,
      "name": "Deco_Iron_Bars",
      "rotation": 1
    },
    {
      "x": 1,
      "y": 8,
      "z": -9,
      "name": "Rock_Runic_Blue_Brick"
    },
    {
      "x": 1,
      "y": 9,
      "z": -9,
      "name": "Rock_Runic_Blue_Brick_Stairs",
      "rotation": 3
    },
    {
      "x": 1,
      "y": 1,
      "z": -8,
      "name": "Deco_Iron_Bars",
      "rotation": 1
    },
    {
      "x": 1,
      "y": 8,
      "z": -8,
      "name": "Rock_Runic_Blue_Brick"
    },
    {
      "x": 1,
      "y": 9,
      "z": -8,
      "name": "Rock_Runic_Blue_Brick_Stairs",
      "rotation": 3
    },
    {
      "x": 1,
      "y": 1,
      "z": -7,
      "name": "Deco_Iron_Bars",
      "rotation": 1
    },
    {
      "x": 1,
      "y": 8,
      "z": -7,
      "name": "Rock_Runic_Blue_Brick"
    },
    {
      "x": 1,
      "y": 9,
      "z": -7,
      "name": "Rock_Runic_Blue_Brick_Stairs",
      "rotation": 3
    },
    {
      "x": 1,
      "y": 1,
      "z": -6,
      "name": "Deco_Iron_Bars",
      "rotation": 1
    },
    {
      "x": 1,
      "y": 8,
      "z": -6,
      "name": "Rock_Runic_Blue_Brick"
    },
    {
      "x": 1,
      "y": 9,
      "z": -6,
      "name": "Rock_Runic_Blue_Brick_Stairs",
      "rotation": 3
    },
    {
      "x": 1,
      "y": 1,
      "z": -5,
      "name": "Deco_Iron_Bars",
      "rotation": 1
    },
    {
      "x": 1,
      "y": 8,
      "z": -5,
      "name": "Rock_Runic_Blue_Brick"
    },
    {
      "x": 1,
      "y": 9,
      "z": -5,
      "name": "Rock_Runic_Blue_Brick_Stairs",
      "rotation": 3
    },
    {
      "x": 1,
      "y": 1,
      "z": -4,
      "name": "Rock_Runic_Blue_Brick"
    },
    {
      "x": 1,
      "y": 8,
      "z": -4,
      "name": "Rock_Runic_Blue_Brick"
    },
    {
      "x": 1,
      "y": 9,
      "z": -4,
      "name": "Rock_Runic_Blue_Brick_Stairs",
      "rotation": 3
    },
    {
      "x": 1,
      "y": 0,
      "z": -3,
      "name": "Deco_Iron_Bars"
    },
    {
      "x": 1,
      "y": 8,
      "z": -3,
      "name": "Rock_Runic_Blue_Brick"
    },
    {
      "x": 1,
      "y": 9,
      "z": -3,
      "name": "Rock_Runic_Blue_Brick_Stairs",
      "rotation": 3
    },
    {
      "x": 1,
      "y": 8,
      "z": -2,
      "name": "Rock_Runic_Blue_Brick"
    },
    {
      "x": 1,
      "y": 9,
      "z": -2,
      "name": "Rock_Runic_Blue_Brick_Stairs",
      "rotation": 3
    },
    {
      "x": 1,
      "y": 8,
      "z": -1,
      "name": "Rock_Runic_Blue_Brick"
    },
    {
      "x": 1,
      "y": 9,
      "z": -1,
      "name": "Rock_Runic_Blue_Brick_Stairs",
      "rotation": 3
    },
    {
      "x": 1,
      "y": 8,
      "z": 0,
      "name": "Rock_Runic_Blue_Brick"
    },
    {
      "x": 1,
      "y": 9,
      "z": 0,
      "name": "Rock_Runic_Blue_Brick_Stairs",
      "rotation": 3
    },
    {
      "x": 1,
      "y": 8,
      "z": 1,
      "name": "Rock_Runic_Blue_Brick"
    },
    {
      "x": 1,
      "y": 9,
      "z": 1,
      "name": "Rock_Runic_Blue_Brick_Stairs",
      "rotation": 3
    },
    {
      "x": 1,
      "y": 8,
      "z": 2,
      "name": "Rock_Runic_Blue_Brick"
    },
    {
      "x": 1,
      "y": 9,
      "z": 2,
      "name": "Rock_Runic_Blue_Brick_Stairs",
      "rotation": 3
    },
    {
      "x": 1,
      "y": 8,
      "z": 3,
      "name": "Rock_Runic_Blue_Brick"
    },
    {
      "x": 1,
      "y": 9,
      "z": 3,
      "name": "Rock_Runic_Blue_Brick_Stairs",
      "rotation": 3
    },
    {
      "x": 1,
      "y": 8,
      "z": 4,
      "name": "Rock_Runic_Blue_Brick"
    },
    {
      "x": 1,
      "y": 9,
      "z": 4,
      "name": "Rock_Runic_Blue_Brick_Stairs",
      "rotation": 3
    },
    {
      "x": 1,
      "y": 8,
      "z": 5,
      "name": "Rock_Runic_Blue_Brick"
    },
    {
      "x": 1,
      "y": 9,
      "z": 5,
      "name": "Rock_Runic_Blue_Brick_Stairs",
      "rotation": 3
    },
    {
      "x": 1,
      "y": 8,
      "z": 6,
      "name": "Rock_Runic_Blue_Brick"
    },
    {
      "x": 1,
      "y": 9,
      "z": 6,
      "name": "Rock_Runic_Blue_Brick_Stairs",
      "rotation": 3
    },
    {
      "x": 1,
      "y": 8,
      "z": 7,
      "name": "Rock_Runic_Blue_Brick"
    },
    {
      "x": 1,
      "y": 9,
      "z": 7,
      "name": "Rock_Runic_Blue_Brick_Stairs",
      "rotation": 3
    },
    {
      "x": 1,
      "y": 8,
      "z": 8,
      "name": "Rock_Runic_Blue_Brick"
    },
    {
      "x": 1,
      "y": 9,
      "z": 8,
      "name": "Rock_Runic_Blue_Brick_Stairs",
      "rotation": 3
    },
    {
      "x": 1,
      "y": 8,
      "z": 9,
      "name": "Rock_Runic_Blue_Brick"
    },
    {
      "x": 1,
      "y": 9,
      "z": 9,
      "name": "Rock_Runic_Blue_Brick_Stairs",
      "rotation": 3
    },
    {
      "x": 1,
      "y": 8,
      "z": 10,
      "name": "Rock_Runic_Blue_Brick"
    },
    {
      "x": 1,
      "y": 9,
      "z": 10,
      "name": "Rock_Runic_Blue_Brick_Stairs",
      "rotation": 3
    },
    {
      "x": 1,
      "y": 8,
      "z": 11,
      "name": "Rock_Runic_Blue_Brick"
    },
    {
      "x": 1,
      "y": 9,
      "z": 11,
      "name": "Rock_Runic_Blue_Brick_Stairs",
      "rotation": 3
    },
    {
      "x": 1,
      "y": 8,
      "z": 12,
      "name": "Rock_Runic_Blue_Brick"
    },
    {
      "x": 1,
      "y": 9,
      "z": 12,
      "name": "Rock_Runic_Blue_Brick_Stairs",
      "rotation": 3
    },
    {
      "x": 1,
      "y": 0,
      "z": 13,
      "name": "Rock_Runic_Blue_Brick"
    },
    {
      "x": 1,
      "y": 8,
      "z": 13,
      "name": "Rock_Runic_Blue_Brick"
    },
    {
      "x": 1,
      "y": 9,
      "z": 13,
      "name": "Rock_Runic_Blue_Brick"
    },
    {
      "x": 2,
      "y": 0,
      "z": -10,
      "name": "Rock_Runic_Blue_Brick"
    },
    {
      "x": 2,
      "y": 1,
      "z": -10,
      "name": "Rock_Runic_Blue_Brick"
    },
    {
      "x": 2,
      "y": 2,
      "z": -10,
      "name": "Rock_Runic_Blue_Brick"
    },
    {
      "x": 2,
      "y": 3,
      "z": -10,
      "name": "Rock_Runic_Blue_Brick"
    },
    {
      "x": 2,
      "y": 4,
      "z": -10,
      "name": "Rock_Runic_Blue_Brick"
    },
    {
      "x": 2,
      "y": 5,
      "z": -10,
      "name": "Rock_Runic_Blue_Brick"
    },
    {
      "x": 2,
      "y": 6,
      "z": -10,
      "name": "Rock_Runic_Blue_Brick_Stairs",
      "rotation": 1
    },
    {
      "x": 2,
      "y": 8,
      "z": -10,
      "name": "Rock_Runic_Blue_Brick_Stairs",
      "rotation": 11
    },
    {
      "x": 2,
      "y": 9,
      "z": -10,
      "name": "Rock_Runic_Blue_Brick"
    },
    {
      "x": 2,
      "y": 2,
      "z": -9,
      "name": "Deco_Iron_Bars",
      "rotation": 1
    },
    {
      "x": 2,
      "y": 9,
      "z": -9,
      "name": "Rock_Runic_Blue_Brick"
    },
    {
      "x": 2,
      "y": 2,
      "z": -8,
      "name": "Deco_Iron_Bars",
      "rotation": 1
    },
    {
      "x": 2,
      "y": 9,
      "z": -8,
      "name": "Rock_Runic_Blue_Brick"
    },
    {
      "x": 2,
      "y": 2,
      "z": -7,
      "name": "Deco_Iron_Bars",
      "rotation": 1
    },
    {
      "x": 2,
      "y": 9,
      "z": -7,
      "name": "Rock_Runic_Blue_Brick"
    },
    {
      "x": 2,
      "y": 2,
      "z": -6,
      "name": "Deco_Iron_Bars",
      "rotation": 1
    },
    {
      "x": 2,
      "y": 9,
      "z": -6,
      "name": "Rock_Runic_Blue_Brick"
    },
    {
      "x": 2,
      "y": 2,
      "z": -5,
      "name": "Rock_Runic_Blue_Brick"
    },
    {
      "x": 2,
      "y": 9,
      "z": -5,
      "name": "Rock_Marble_Brick"
    },
    {
      "x": 2,
      "y": 1,
      "z": -4,
      "name": "Deco_Iron_Bars"
    },
    {
      "x": 2,
      "y": 9,
      "z": -4,
      "name": "Rock_Runic_Blue_Brick"
    },
    {
      "x": 2,
      "y": 0,
      "z": -3,
      "name": "Deco_Iron_Bars"
    },
    {
      "x": 2,
      "y": 9,
      "z": -3,
      "name": "Rock_Runic_Blue_Brick"
    },
    {
      "x": 2,
      "y": 9,
      "z": -2,
      "name": "Rock_Runic_Blue_Brick"
    },
    {
      "x": 2,
      "y": 9,
      "z": -1,
      "name": "Rock_Marble_Brick"
    },
    {
      "x": 2,
      "y": 9,
      "z": 0,
      "name": "Rock_Marble_Brick"
    },
    {
      "x": 2,
      "y": 9,
      "z": 1,
      "name": "Rock_Marble_Brick"
    },
    {
      "x": 2,
      "y": 9,
      "z": 2,
      "name": "Rock_Runic_Blue_Brick"
    },
    {
      "x": 2,
      "y": 9,
      "z": 3,
      "name": "Rock_Runic_Blue_Brick"
    },
    {
      "x": 2,
      "y": 9,
      "z": 4,
      "name": "Rock_Marble_Brick"
    },
    {
      "x": 2,
      "y": 9,
      "z": 5,
      "name": "Rock_Runic_Blue_Brick"
    },
    {
      "x": 2,
      "y": 9,
      "z": 6,
      "name": "Rock_Marble_Brick"
    },
    {
      "x": 2,
      "y": 9,
      "z": 7,
      "name": "Rock_Runic_Blue_Brick"
    },
    {
      "x": 2,
      "y": 9,
      "z": 8,
      "name": "Rock_Runic_Blue_Brick"
    },
    {
      "x": 2,
      "y": 9,
      "z": 9,
      "name": "Rock_Marble_Brick"
    },
    {
      "x": 2,
      "y": 9,
      "z": 10,
      "name": "Rock_Runic_Blue_Brick"
    },
    {
      "x": 2,
      "y": 9,
      "z": 11,
      "name": "Rock_Runic_Blue_Brick"
    },
    {
      "x": 2,
      "y": 9,
      "z": 12,
      "name": "Rock_Runic_Blue_Brick"
    },
    {
      "x": 2,
      "y": 0,
      "z": 13,
      "name": "Rock_Runic_Blue_Brick"
    },
    {
      "x": 2,
      "y": 9,
      "z": 13,
      "name": "Rock_Runic_Blue_Brick"
    },
    {
      "x": 3,
      "y": 0,
      "z": -10,
      "name": "Rock_Runic_Blue_Brick"
    },
    {
      "x": 3,
      "y": 1,
      "z": -10,
      "name": "Rock_Runic_Blue_Brick"
    },
    {
      "x": 3,
      "y": 2,
      "z": -10,
      "name": "Rock_Runic_Blue_Brick"
    },
    {
      "x": 3,
      "y": 3,
      "z": -10,
      "name": "Rock_Runic_Blue_Brick"
    },
    {
      "x": 3,
      "y": 4,
      "z": -10,
      "name": "Rock_Runic_Blue_Brick"
    },
    {
      "x": 3,
      "y": 5,
      "z": -10,
      "name": "Rock_Runic_Blue_Brick"
    },
    {
      "x": 3,
      "y": 9,
      "z": -10,
      "name": "Rock_Runic_Blue_Brick"
    },
    {
      "x": 3,
      "y": 10,
      "z": -10,
      "name": "Rock_Runic_Blue_Brick_Stairs",
      "rotation": 3
    },
    {
      "x": 3,
      "y": 3,
      "z": -9,
      "name": "Deco_Iron_Bars",
      "rotation": 1
    },
    {
      "x": 3,
      "y": 9,
      "z": -9,
      "name": "Rock_Runic_Blue_Brick"
    },
    {
      "x": 3,
      "y": 3,
      "z": -8,
      "name": "Deco_Iron_Bars",
      "rotation": 1
    },
    {
      "x": 3,
      "y": 9,
      "z": -8,
      "name": "Rock_Runic_Blue_Brick"
    },
    {
      "x": 3,
      "y": 3,
      "z": -7,
      "name": "Deco_Iron_Bars",
      "rotation": 1
    },
    {
      "x": 3,
      "y": 9,
      "z": -7,
      "name": "Rock_Runic_Blue_Brick"
    },
    {
      "x": 3,
      "y": 3,
      "z": -6,
      "name": "Rock_Runic_Blue_Brick"
    },
    {
      "x": 3,
      "y": 9,
      "z": -6,
      "name": "Rock_Marble_Brick"
    },
    {
      "x": 3,
      "y": 2,
      "z": -5,
      "name": "Deco_Iron_Bars"
    },
    {
      "x": 3,
      "y": 9,
      "z": -5,
      "name": "Rock_Marble_Brick"
    },
    {
      "x": 3,
      "y": 1,
      "z": -4,
      "name": "Deco_Iron_Bars"
    },
    {
      "x": 3,
      "y": 9,
      "z": -4,
      "name": "Rock_Runic_Blue_Brick"
    },
    {
      "x": 3,
      "y": 0,
      "z": -3,
      "name": "Deco_Iron_Bars"
    },
    {
      "x": 3,
      "y": 9,
      "z": -3,
      "name": "Rock_Marble_Brick"
    },
    {
      "x": 3,
      "y": 9,
      "z": -2,
      "name": "Rock_Runic_Blue_Brick"
    },
    {
      "x": 3,
      "y": 9,
      "z": -1,
      "name": "Rock_Runic_Blue_Brick"
    },
    {
      "x": 3,
      "y": 9,
      "z": 0,
      "name": "Rock_Marble_Brick"
    },
    {
      "x": 3,
      "y": 9,
      "z": 1,
      "name": "Rock_Runic_Blue_Brick"
    },
    {
      "x": 3,
      "y": 9,
      "z": 2,
      "name": "Rock_Runic_Blue_Brick"
    },
    {
      "x": 3,
      "y": 9,
      "z": 3,
      "name": "Rock_Runic_Blue_Brick"
    },
    {
      "x": 3,
      "y": 9,
      "z": 4,
      "name": "Rock_Marble_Brick"
    },
    {
      "x": 3,
      "y": 9,
      "z": 5,
      "name": "Rock_Runic_Blue_Brick"
    },
    {
      "x": 3,
      "y": 9,
      "z": 6,
      "name": "Rock_Marble_Brick"
    },
    {
      "x": 3,
      "y": 9,
      "z": 7,
      "name": "Rock_Runic_Blue_Brick"
    },
    {
      "x": 3,
      "y": 9,
      "z": 8,
      "name": "Rock_Runic_Blue_Brick"
    },
    {
      "x": 3,
      "y": 9,
      "z": 9,
      "name": "Rock_Runic_Blue_Brick"
    },
    {
      "x": 3,
      "y": 9,
      "z": 10,
      "name": "Rock_Runic_Blue_Brick"
    },
    {
      "x": 3,
      "y": 9,
      "z": 11,
      "name": "Rock_Runic_Blue_Brick"
    },
    {
      "x": 3,
      "y": 9,
      "z": 12,
      "name": "Rock_Runic_Blue_Brick"
    },
    {
      "x": 3,
      "y": 0,
      "z": 13,
      "name": "Rock_Runic_Blue_Brick"
    },
    {
      "x": 3,
      "y": 9,
      "z": 13,
      "name": "Rock_Runic_Blue_Brick"
    },
    {
      "x": 3,
      "y": 10,
      "z": 13,
      "name": "Rock_Runic_Blue_Brick_Stairs",
      "rotation": 3
    },
    {
      "x": 4,
      "y": 0,
      "z": -10,
      "name": "Rock_Runic_Blue_Brick"
    },
    {
      "x": 4,
      "y": 1,
      "z": -10,
      "name": "Rock_Runic_Blue_Brick"
    },
    {
      "x": 4,
      "y": 2,
      "z": -10,
      "name": "Rock_Runic_Blue_Brick"
    },
    {
      "x": 4,
      "y": 3,
      "z": -10,
      "name": "Rock_Runic_Blue_Brick"
    },
    {
      "x": 4,
      "y": 4,
      "z": -10,
      "name": "Rock_Runic_Blue_Brick"
    },
    {
      "x": 4,
      "y": 5,
      "z": -10,
      "name": "Rock_Runic_Blue_Brick"
    },
    {
      "x": 4,
      "y": 9,
      "z": -10,
      "name": "Rock_Runic_Blue_Brick"
    },
    {
      "x": 4,
      "y": 10,
      "z": -10,
      "name": "Rock_Runic_Blue_Brick"
    },
    {
      "x": 4,
      "y": 4,
      "z": -9,
      "name": "Deco_Iron_Bars",
      "rotation": 1
    },
    {
      "x": 4,
      "y": 9,
      "z": -9,
      "name": "Rock_Runic_Blue_Brick"
    },
    {
      "x": 4,
      "y": 4,
      "z": -8,
      "name": "Deco_Iron_Bars",
      "rotation": 1
    },
    {
      "x": 4,
      "y": 9,
      "z": -8,
      "name": "Rock_Runic_Blue_Brick"
    },
    {
      "x": 4,
      "y": 4,
      "z": -7,
      "name": "Rock_Runic_Blue_Brick"
    },
    {
      "x": 4,
      "y": 9,
      "z": -7,
      "name": "Rock_Runic_Blue_Brick"
    },
    {
      "x": 4,
      "y": 3,
      "z": -6,
      "name": "Deco_Iron_Bars"
    },
    {
      "x": 4,
      "y": 9,
      "z": -6,
      "name": "Rock_Runic_Blue_Brick"
    },
    {
      "x": 4,
      "y": 2,
      "z": -5,
      "name": "Deco_Iron_Bars"
    },
    {
      "x": 4,
      "y": 9,
      "z": -5,
      "name": "Rock_Marble_Brick"
    },
    {
      "x": 4,
      "y": 1,
      "z": -4,
      "name": "Deco_Iron_Bars"
    },
    {
      "x": 4,
      "y": 9,
      "z": -4,
      "name": "Rock_Runic_Blue_Brick"
    },
    {
      "x": 4,
      "y": 0,
      "z": -3,
      "name": "Deco_Iron_Bars"
    },
    {
      "x": 4,
      "y": 9,
      "z": -3,
      "name": "Rock_Runic_Blue_Brick"
    },
    {
      "x": 4,
      "y": 9,
      "z": -2,
      "name": "Rock_Runic_Blue_Brick"
    },
    {
      "x": 4,
      "y": 9,
      "z": -1,
      "name": "Rock_Runic_Blue_Brick"
    },
    {
      "x": 4,
      "y": 9,
      "z": 0,
      "name": "Rock_Marble_Brick"
    },
    {
      "x": 4,
      "y": 9,
      "z": 1,
      "name": "Rock_Runic_Blue_Brick"
    },
    {
      "x": 4,
      "y": 9,
      "z": 2,
      "name": "Rock_Runic_Blue_Brick"
    },
    {
      "x": 4,
      "y": 9,
      "z": 3,
      "name": "Rock_Runic_Blue_Brick"
    },
    {
      "x": 4,
      "y": 9,
      "z": 4,
      "name": "Rock_Runic_Blue_Brick"
    },
    {
      "x": 4,
      "y": 9,
      "z": 5,
      "name": "Rock_Marble_Brick"
    },
    {
      "x": 4,
      "y": 9,
      "z": 6,
      "name": "Rock_Runic_Blue_Brick"
    },
    {
      "x": 4,
      "y": 9,
      "z": 7,
      "name": "Rock_Runic_Blue_Brick"
    },
    {
      "x": 4,
      "y": 9,
      "z": 8,
      "name": "Rock_Runic_Blue_Brick"
    },
    {
      "x": 4,
      "y": 9,
      "z": 9,
      "name": "Rock_Marble_Brick"
    },
    {
      "x": 4,
      "y": 9,
      "z": 10,
      "name": "Rock_Runic_Blue_Brick"
    },
    {
      "x": 4,
      "y": 9,
      "z": 11,
      "name": "Rock_Runic_Blue_Brick"
    },
    {
      "x": 4,
      "y": 10,
      "z": 11,
      "name": "Plant_Seaweed_Dead_Ghostly",
      "support": 15
    },
    {
      "x": 4,
      "y": 11,
      "z": 11,
      "name": "Plant_Seaweed_Dead_Ghostly",
      "filler": 1024
    },
    {
      "x": 4,
      "y": 9,
      "z": 12,
      "name": "Rock_Runic_Blue_Brick"
    },
    {
      "x": 4,
      "y": 0,
      "z": 13,
      "name": "Rock_Runic_Blue_Brick"
    },
    {
      "x": 4,
      "y": 9,
      "z": 13,
      "name": "Rock_Runic_Blue_Brick"
    },
    {
      "x": 4,
      "y": 10,
      "z": 13,
      "name": "Rock_Runic_Blue_Brick"
    },
    {
      "x": 5,
      "y": 0,
      "z": -11,
      "name": "Plant_Seaweed_Dead_Short",
      "support": 15
    },
    {
      "x": 5,
      "y": 0,
      "z": -10,
      "name": "Rock_Runic_Blue_Brick"
    },
    {
      "x": 5,
      "y": 1,
      "z": -10,
      "name": "Rock_Runic_Blue_Brick"
    },
    {
      "x": 5,
      "y": 2,
      "z": -10,
      "name": "Rock_Runic_Blue_Brick"
    },
    {
      "x": 5,
      "y": 3,
      "z": -10,
      "name": "Rock_Runic_Blue_Brick"
    },
    {
      "x": 5,
      "y": 4,
      "z": -10,
      "name": "Rock_Runic_Blue_Brick"
    },
    {
      "x": 5,
      "y": 5,
      "z": -10,
      "name": "Rock_Runic_Blue_Brick"
    },
    {
      "x": 5,
      "y": 10,
      "z": -10,
      "name": "Rock_Runic_Blue_Brick"
    },
    {
      "x": 5,
      "y": 5,
      "z": -9,
      "name": "Deco_Iron_Bars",
      "rotation": 1
    },
    {
      "x": 5,
      "y": 10,
      "z": -9,
      "name": "Rock_Runic_Blue_Brick"
    },
    {
      "x": 5,
      "y": 5,
      "z": -8,
      "name": "Rock_Runic_Blue_Brick"
    },
    {
      "x": 5,
      "y": 10,
      "z": -8,
      "name": "Rock_Runic_Blue_Brick"
    },
    {
      "x": 5,
      "y": 11,
      "z": -8,
      "name": "Plant_Seaweed_Dead_Short",
      "support": 15
    },
    {
      "x": 5,
      "y": 4,
      "z": -7,
      "name": "Deco_Iron_Bars"
    },
    {
      "x": 5,
      "y": 10,
      "z": -7,
      "name": "Rock_Runic_Blue_Brick"
    },
    {
      "x": 5,
      "y": 11,
      "z": -7,
      "name": "Plant_Seaweed_Dead_Short",
      "support": 15
    },
    {
      "x": 5,
      "y": 3,
      "z": -6,
      "name": "Deco_Iron_Bars"
    },
    {
      "x": 5,
      "y": 10,
      "z": -6,
      "name": "Rock_Runic_Blue_Brick"
    },
    {
      "x": 5,
      "y": 11,
      "z": -6,
      "name": "Plant_Seaweed_Dead_Short",
      "support": 15
    },
    {
      "x": 5,
      "y": 2,
      "z": -5,
      "name": "Deco_Iron_Bars"
    },
    {
      "x": 5,
      "y": 10,
      "z": -5,
      "name": "Rock_Runic_Blue_Brick"
    },
    {
      "x": 5,
      "y": 1,
      "z": -4,
      "name": "Deco_Iron_Bars"
    },
    {
      "x": 5,
      "y": 10,
      "z": -4,
      "name": "Rock_Runic_Blue_Brick"
    },
    {
      "x": 5,
      "y": 0,
      "z": -3,
      "name": "Deco_Iron_Bars"
    },
    {
      "x": 5,
      "y": 10,
      "z": -3,
      "name": "Rock_Runic_Blue_Brick"
    },
    {
      "x": 5,
      "y": 10,
      "z": -2,
      "name": "Rock_Runic_Blue_Brick"
    },
    {
      "x": 5,
      "y": 10,
      "z": -1,
      "name": "Rock_Runic_Blue_Brick"
    },
    {
      "x": 5,
      "y": 10,
      "z": 0,
      "name": "Rock_Runic_Blue_Brick"
    },
    {
      "x": 5,
      "y": 10,
      "z": 1,
      "name": "Rock_Runic_Blue_Brick"
    },
    {
      "x": 5,
      "y": 10,
      "z": 2,
      "name": "Rock_Runic_Blue_Brick"
    },
    {
      "x": 5,
      "y": 10,
      "z": 3,
      "name": "Rock_Runic_Blue_Brick"
    },
    {
      "x": 5,
      "y": 10,
      "z": 4,
      "name": "Rock_Runic_Blue_Brick"
    },
    {
      "x": 5,
      "y": 10,
      "z": 5,
      "name": "Rock_Runic_Blue_Brick"
    },
    {
      "x": 5,
      "y": 10,
      "z": 6,
      "name": "Rock_Runic_Blue_Brick"
    },
    {
      "x": 5,
      "y": 11,
      "z": 6,
      "name": "Plant_Seaweed_Dead_Short",
      "support": 15
    },
    {
      "x": 5,
      "y": 10,
      "z": 7,
      "name": "Rock_Runic_Blue_Brick"
    },
    {
      "x": 5,
      "y": 11,
      "z": 7,
      "name": "Plant_Seaweed_Dead_Short",
      "support": 15
    },
    {
      "x": 5,
      "y": 10,
      "z": 8,
      "name": "Rock_Runic_Blue_Brick"
    },
    {
      "x": 5,
      "y": 10,
      "z": 9,
      "name": "Rock_Runic_Blue_Brick"
    },
    {
      "x": 5,
      "y": 10,
      "z": 10,
      "name": "Rock_Runic_Blue_Brick"
    },
    {
      "x": 5,
      "y": 10,
      "z": 11,
      "name": "Rock_Runic_Blue_Brick"
    },
    {
      "x": 5,
      "y": 10,
      "z": 12,
      "name": "Rock_Runic_Blue_Brick"
    },
    {
      "x": 5,
      "y": 0,
      "z": 13,
      "name": "Rock_Runic_Blue_Brick"
    },
    {
      "x": 5,
      "y": 10,
      "z": 13,
      "name": "Rock_Runic_Blue_Brick"
    },
    {
      "x": 6,
      "y": 0,
      "z": -11,
      "name": "Plant_Seaweed_Dead_Ghostly",
      "support": 15
    },
    {
      "x": 6,
      "y": 1,
      "z": -11,
      "name": "Plant_Seaweed_Dead_Ghostly",
      "filler": 1024
    },
    {
      "x": 6,
      "y": 0,
      "z": -10,
      "name": "Rock_Runic_Blue_Brick_Stairs",
      "rotation": 8
    },
    {
      "x": 6,
      "y": 1,
      "z": -10,
      "name": "Rock_Runic_Blue_Brick"
    },
    {
      "x": 6,
      "y": 2,
      "z": -10,
      "name": "Rock_Runic_Blue_Brick"
    },
    {
      "x": 6,
      "y": 3,
      "z": -10,
      "name": "Rock_Runic_Blue_Brick"
    },
    {
      "x": 6,
      "y": 4,
      "z": -10,
      "name": "Rock_Runic_Blue_Brick"
    },
    {
      "x": 6,
      "y": 5,
      "z": -10,
      "name": "Rock_Runic_Blue_Brick"
    },
    {
      "x": 6,
      "y": 6,
      "z": -10,
      "name": "Rock_Runic_Blue_Brick_Stairs",
      "rotation": 3
    },
    {
      "x": 6,
      "y": 9,
      "z": -10,
      "name": "Rock_Runic_Blue_Brick_Stairs",
      "rotation": 9
    },
    {
      "x": 6,
      "y": 10,
      "z": -10,
      "name": "Rock_Runic_Blue_Brick"
    },
    {
      "x": 6,
      "y": 11,
      "z": -10,
      "name": "Rock_Runic_Blue_Brick_Stairs",
      "rotation": 2
    },
    {
      "x": 6,
      "y": 5,
      "z": -9,
      "name": "Rock_Runic_Blue_Brick"
    },
    {
      "x": 6,
      "y": 10,
      "z": -9,
      "name": "Rock_Runic_Blue_Brick"
    },
    {
      "x": 6,
      "y": 5,
      "z": -8,
      "name": "Deco_Iron_Bars"
    },
    {
      "x": 6,
      "y": 10,
      "z": -8,
      "name": "Rock_Runic_Blue_Brick"
    },
    {
      "x": 6,
      "y": 11,
      "z": -8,
      "name": "Plant_Seaweed_Dead_Ghostly",
      "support": 15
    },
    {
      "x": 6,
      "y": 4,
      "z": -7,
      "name": "Deco_Iron_Bars"
    },
    {
      "x": 6,
      "y": 10,
      "z": -7,
      "name": "Rock_Runic_Blue_Brick"
    },
    {
      "x": 6,
      "y": 11,
      "z": -7,
      "name": "Plant_Seaweed_Dead_Ghostly",
      "support": 15
    },
    {
      "x": 6,
      "y": 3,
      "z": -6,
      "name": "Deco_Iron_Bars"
    },
    {
      "x": 6,
      "y": 10,
      "z": -6,
      "name": "Rock_Runic_Blue_Brick"
    },
    {
      "x": 6,
      "y": 2,
      "z": -5,
      "name": "Deco_Iron_Bars"
    },
    {
      "x": 6,
      "y": 10,
      "z": -5,
      "name": "Rock_Runic_Blue_Brick"
    },
    {
      "x": 6,
      "y": 1,
      "z": -4,
      "name": "Deco_Iron_Bars"
    },
    {
      "x": 6,
      "y": 10,
      "z": -4,
      "name": "Rock_Runic_Blue_Brick"
    },
    {
      "x": 6,
      "y": 0,
      "z": -3,
      "name": "Deco_Iron_Bars"
    },
    {
      "x": 6,
      "y": 10,
      "z": -3,
      "name": "Rock_Runic_Blue_Brick"
    },
    {
      "x": 6,
      "y": 10,
      "z": -2,
      "name": "Rock_Runic_Blue_Brick"
    },
    {
      "x": 6,
      "y": 10,
      "z": -1,
      "name": "Rock_Runic_Blue_Brick"
    },
    {
      "x": 6,
      "y": 10,
      "z": 0,
      "name": "Rock_Runic_Blue_Brick"
    },
    {
      "x": 6,
      "y": 10,
      "z": 1,
      "name": "Rock_Runic_Blue_Brick"
    },
    {
      "x": 6,
      "y": 10,
      "z": 2,
      "name": "Rock_Runic_Blue_Brick"
    },
    {
      "x": 6,
      "y": 10,
      "z": 3,
      "name": "Rock_Runic_Blue_Brick"
    },
    {
      "x": 6,
      "y": 10,
      "z": 4,
      "name": "Rock_Runic_Blue_Brick"
    },
    {
      "x": 6,
      "y": 10,
      "z": 5,
      "name": "Rock_Runic_Blue_Brick"
    },
    {
      "x": 6,
      "y": 10,
      "z": 6,
      "name": "Rock_Runic_Blue_Brick"
    },
    {
      "x": 6,
      "y": 10,
      "z": 7,
      "name": "Rock_Runic_Blue_Brick"
    },
    {
      "x": 6,
      "y": 11,
      "z": 7,
      "name": "Plant_Seaweed_Dead_Ghostly",
      "support": 15
    },
    {
      "x": 6,
      "y": 10,
      "z": 8,
      "name": "Rock_Runic_Blue_Brick"
    },
    {
      "x": 6,
      "y": 11,
      "z": 8,
      "name": "Plant_Seaweed_Dead_Short",
      "support": 15
    },
    {
      "x": 6,
      "y": 10,
      "z": 9,
      "name": "Rock_Runic_Blue_Brick"
    },
    {
      "x": 6,
      "y": 10,
      "z": 10,
      "name": "Rock_Runic_Blue_Brick"
    },
    {
      "x": 6,
      "y": 10,
      "z": 11,
      "name": "Rock_Runic_Blue_Brick"
    },
    {
      "x": 6,
      "y": 10,
      "z": 12,
      "name": "Rock_Runic_Blue_Brick"
    },
    {
      "x": 6,
      "y": 0,
      "z": 13,
      "name": "Rock_Runic_Blue_Brick_Stairs",
      "rotation": 10
    },
    {
      "x": 6,
      "y": 1,
      "z": 13,
      "name": "Rock_Runic_Blue_Brick"
    },
    {
      "x": 6,
      "y": 9,
      "z": 13,
      "name": "Rock_Runic_Blue_Brick_Stairs",
      "rotation": 9
    },
    {
      "x": 6,
      "y": 10,
      "z": 13,
      "name": "Rock_Runic_Blue_Brick"
    },
    {
      "x": 6,
      "y": 11,
      "z": 13,
      "name": "Rock_Runic_Blue_Brick_Stairs"
    },
    {
      "x": 7,
      "y": 0,
      "z": -11,
      "name": "Plant_Seaweed_Dead_Ghostly",
      "support": 15
    },
    {
      "x": 7,
      "y": 1,
      "z": -11,
      "name": "Plant_Seaweed_Dead_Ghostly",
      "filler": 1024
    },
    {
      "x": 7,
      "y": 0,
      "z": -10,
      "name": "*Rock_Runic_Blue_Brick_Stairs_State_Definitions_Corner_Right",
      "rotation": 11
    },
    {
      "x": 7,
      "y": 1,
      "z": -10,
      "name": "Rock_Runic_Blue_Brick"
    },
    {
      "x": 7,
      "y": 2,
      "z": -10,
      "name": "Rock_Runic_Blue_Brick"
    },
    {
      "x": 7,
      "y": 3,
      "z": -10,
      "name": "Rock_Runic_Blue_Brick"
    },
    {
      "x": 7,
      "y": 4,
      "z": -10,
      "name": "Rock_Runic_Blue_Brick"
    },
    {
      "x": 7,
      "y": 5,
      "z": -10,
      "name": "Rock_Runic_Blue_Brick"
    },
    {
      "x": 7,
      "y": 6,
      "z": -10,
      "name": "Rock_Runic_Blue_Brick"
    },
    {
      "x": 7,
      "y": 7,
      "z": -10,
      "name": "Rock_Runic_Blue_Brick"
    },
    {
      "x": 7,
      "y": 8,
      "z": -10,
      "name": "Rock_Runic_Blue_Brick"
    },
    {
      "x": 7,
      "y": 9,
      "z": -10,
      "name": "Rock_Runic_Blue_Brick"
    },
    {
      "x": 7,
      "y": 10,
      "z": -10,
      "name": "Rock_Runic_Blue_Brick"
    },
    {
      "x": 7,
      "y": 11,
      "z": -10,
      "name": "*Rock_Runic_Blue_Brick_Stairs_State_Definitions_Corner_Left",
      "rotation": 1
    },
    {
      "x": 7,
      "y": 0,
      "z": -9,
      "name": "Rock_Runic_Blue_Brick_Stairs",
      "rotation": 11
    },
    {
      "x": 7,
      "y": 1,
      "z": -9,
      "name": "Rock_Runic_Blue_Brick"
    },
    {
      "x": 7,
      "y": 2,
      "z": -9,
      "name": "Rock_Runic_Blue_Brick"
    },
    {
      "x": 7,
      "y": 3,
      "z": -9,
      "name": "Rock_Runic_Blue_Brick"
    },
    {
      "x": 7,
      "y": 4,
      "z": -9,
      "name": "Rock_Runic_Blue_Brick"
    },
    {
      "x": 7,
      "y": 5,
      "z": -9,
      "name": "Rock_Runic_Blue_Brick"
    },
    {
      "x": 7,
      "y": 10,
      "z": -9,
      "name": "Rock_Runic_Blue_Brick"
    },
    {
      "x": 7,
      "y": 11,
      "z": -9,
      "name": "Rock_Runic_Blue_Brick_Stairs",
      "rotation": 1
    },
    {
      "x": 7,
      "y": 0,
      "z": -8,
      "name": "Rock_Runic_Blue_Brick"
    },
    {
      "x": 7,
      "y": 1,
      "z": -8,
      "name": "Rock_Runic_Blue_Brick"
    },
    {
      "x": 7,
      "y": 2,
      "z": -8,
      "name": "Rock_Runic_Blue_Brick"
    },
    {
      "x": 7,
      "y": 3,
      "z": -8,
      "name": "Rock_Runic_Blue_Brick"
    },
    {
      "x": 7,
      "y": 4,
      "z": -8,
      "name": "Rock_Runic_Blue_Brick"
    },
    {
      "x": 7,
      "y": 5,
      "z": -8,
      "name": "Rock_Runic_Blue_Brick"
    },
    {
      "x": 7,
      "y": 10,
      "z": -8,
      "name": "Rock_Runic_Blue_Brick"
    },
    {
      "x": 7,
      "y": 11,
      "z": -8,
      "name": "Rock_Runic_Blue_Brick_Stairs",
      "rotation": 1
    },
    {
      "x": 7,
      "y": 0,
      "z": -7,
      "name": "Rock_Runic_Blue_Brick"
    },
    {
      "x": 7,
      "y": 1,
      "z": -7,
      "name": "Rock_Runic_Blue_Brick"
    },
    {
      "x": 7,
      "y": 2,
      "z": -7,
      "name": "Rock_Runic_Blue_Brick"
    },
    {
      "x": 7,
      "y": 3,
      "z": -7,
      "name": "Rock_Runic_Blue_Brick"
    },
    {
      "x": 7,
      "y": 4,
      "z": -7,
      "name": "Rock_Runic_Blue_Brick"
    },
    {
      "x": 7,
      "y": 5,
      "z": -7,
      "name": "Rock_Runic_Blue_Brick"
    },
    {
      "x": 7,
      "y": 10,
      "z": -7,
      "name": "Rock_Runic_Blue_Brick"
    },
    {
      "x": 7,
      "y": 11,
      "z": -7,
      "name": "Rock_Runic_Blue_Brick_Stairs",
      "rotation": 1
    },
    {
      "x": 7,
      "y": 0,
      "z": -6,
      "name": "Rock_Runic_Blue_Brick"
    },
    {
      "x": 7,
      "y": 1,
      "z": -6,
      "name": "Rock_Runic_Blue_Brick"
    },
    {
      "x": 7,
      "y": 2,
      "z": -6,
      "name": "Rock_Runic_Blue_Brick"
    },
    {
      "x": 7,
      "y": 3,
      "z": -6,
      "name": "Rock_Runic_Blue_Brick"
    },
    {
      "x": 7,
      "y": 4,
      "z": -6,
      "name": "Rock_Runic_Blue_Brick"
    },
    {
      "x": 7,
      "y": 5,
      "z": -6,
      "name": "Rock_Runic_Blue_Brick"
    },
    {
      "x": 7,
      "y": 10,
      "z": -6,
      "name": "Rock_Runic_Blue_Brick"
    },
    {
      "x": 7,
      "y": 11,
      "z": -6,
      "name": "Rock_Runic_Blue_Brick_Stairs",
      "rotation": 1
    },
    {
      "x": 7,
      "y": 0,
      "z": -5,
      "name": "Rock_Runic_Blue_Brick"
    },
    {
      "x": 7,
      "y": 1,
      "z": -5,
      "name": "Rock_Runic_Blue_Brick"
    },
    {
      "x": 7,
      "y": 2,
      "z": -5,
      "name": "Rock_Runic_Blue_Brick"
    },
    {
      "x": 7,
      "y": 3,
      "z": -5,
      "name": "Rock_Runic_Blue_Brick"
    },
    {
      "x": 7,
      "y": 4,
      "z": -5,
      "name": "Rock_Runic_Blue_Brick"
    },
    {
      "x": 7,
      "y": 5,
      "z": -5,
      "name": "Rock_Runic_Blue_Brick"
    },
    {
      "x": 7,
      "y": 10,
      "z": -5,
      "name": "Rock_Runic_Blue_Brick"
    },
    {
      "x": 7,
      "y": 11,
      "z": -5,
      "name": "Rock_Runic_Blue_Brick_Stairs",
      "rotation": 1
    },
    {
      "x": 7,
      "y": 0,
      "z": -4,
      "name": "Rock_Runic_Blue_Brick"
    },
    {
      "x": 7,
      "y": 1,
      "z": -4,
      "name": "Rock_Runic_Blue_Brick"
    },
    {
      "x": 7,
      "y": 2,
      "z": -4,
      "name": "Rock_Runic_Blue_Brick"
    },
    {
      "x": 7,
      "y": 3,
      "z": -4,
      "name": "Rock_Runic_Blue_Brick"
    },
    {
      "x": 7,
      "y": 4,
      "z": -4,
      "name": "Rock_Runic_Blue_Brick"
    },
    {
      "x": 7,
      "y": 5,
      "z": -4,
      "name": "Rock_Runic_Blue_Brick"
    },
    {
      "x": 7,
      "y": 10,
      "z": -4,
      "name": "Rock_Runic_Blue_Brick"
    },
    {
      "x": 7,
      "y": 11,
      "z": -4,
      "name": "Rock_Runic_Blue_Brick_Stairs",
      "rotation": 1
    },
    {
      "x": 7,
      "y": 0,
      "z": -3,
      "name": "Rock_Runic_Blue_Brick"
    },
    {
      "x": 7,
      "y": 1,
      "z": -3,
      "name": "Rock_Runic_Blue_Brick"
    },
    {
      "x": 7,
      "y": 2,
      "z": -3,
      "name": "Rock_Runic_Blue_Brick"
    },
    {
      "x": 7,
      "y": 3,
      "z": -3,
      "name": "Rock_Runic_Blue_Brick"
    },
    {
      "x": 7,
      "y": 4,
      "z": -3,
      "name": "Rock_Runic_Blue_Brick"
    },
    {
      "x": 7,
      "y": 5,
      "z": -3,
      "name": "Rock_Runic_Blue_Brick"
    },
    {
      "x": 7,
      "y": 10,
      "z": -3,
      "name": "Rock_Runic_Blue_Brick"
    },
    {
      "x": 7,
      "y": 11,
      "z": -3,
      "name": "Rock_Runic_Blue_Brick_Stairs",
      "rotation": 1
    },
    {
      "x": 7,
      "y": 0,
      "z": -2,
      "name": "Rock_Runic_Blue_Brick"
    },
    {
      "x": 7,
      "y": 10,
      "z": -2,
      "name": "Rock_Runic_Blue_Brick"
    },
    {
      "x": 7,
      "y": 11,
      "z": -2,
      "name": "Rock_Runic_Blue_Brick_Stairs",
      "rotation": 1
    },
    {
      "x": 7,
      "y": 0,
      "z": -1,
      "name": "Rock_Runic_Blue_Brick"
    },
    {
      "x": 7,
      "y": 10,
      "z": -1,
      "name": "Rock_Runic_Blue_Brick"
    },
    {
      "x": 7,
      "y": 11,
      "z": -1,
      "name": "Rock_Runic_Blue_Brick_Stairs",
      "rotation": 1
    },
    {
      "x": 7,
      "y": 0,
      "z": 0,
      "name": "Rock_Runic_Blue_Brick"
    },
    {
      "x": 7,
      "y": 10,
      "z": 0,
      "name": "Rock_Runic_Blue_Brick"
    },
    {
      "x": 7,
      "y": 11,
      "z": 0,
      "name": "Rock_Runic_Blue_Brick_Stairs",
      "rotation": 1
    },
    {
      "x": 7,
      "y": 0,
      "z": 1,
      "name": "Rock_Runic_Blue_Brick"
    },
    {
      "x": 7,
      "y": 10,
      "z": 1,
      "name": "Rock_Runic_Blue_Brick"
    },
    {
      "x": 7,
      "y": 11,
      "z": 1,
      "name": "Rock_Runic_Blue_Brick_Stairs",
      "rotation": 1
    },
    {
      "x": 7,
      "y": 0,
      "z": 2,
      "name": "Rock_Runic_Blue_Brick"
    },
    {
      "x": 7,
      "y": 10,
      "z": 2,
      "name": "Rock_Runic_Blue_Brick"
    },
    {
      "x": 7,
      "y": 11,
      "z": 2,
      "name": "Rock_Runic_Blue_Brick_Stairs",
      "rotation": 1
    },
    {
      "x": 7,
      "y": 0,
      "z": 3,
      "name": "Rock_Runic_Blue_Brick"
    },
    {
      "x": 7,
      "y": 10,
      "z": 3,
      "name": "Rock_Runic_Blue_Brick"
    },
    {
      "x": 7,
      "y": 11,
      "z": 3,
      "name": "Rock_Runic_Blue_Brick_Stairs",
      "rotation": 1
    },
    {
      "x": 7,
      "y": 0,
      "z": 4,
      "name": "Rock_Runic_Blue_Brick"
    },
    {
      "x": 7,
      "y": 10,
      "z": 4,
      "name": "Rock_Runic_Blue_Brick"
    },
    {
      "x": 7,
      "y": 11,
      "z": 4,
      "name": "Rock_Runic_Blue_Brick_Stairs",
      "rotation": 1
    },
    {
      "x": 7,
      "y": 0,
      "z": 5,
      "name": "Rock_Runic_Blue_Brick"
    },
    {
      "x": 7,
      "y": 10,
      "z": 5,
      "name": "Rock_Runic_Blue_Brick"
    },
    {
      "x": 7,
      "y": 11,
      "z": 5,
      "name": "Rock_Runic_Blue_Brick_Stairs",
      "rotation": 1
    },
    {
      "x": 7,
      "y": 0,
      "z": 6,
      "name": "Rock_Runic_Blue_Brick"
    },
    {
      "x": 7,
      "y": 10,
      "z": 6,
      "name": "Rock_Runic_Blue_Brick"
    },
    {
      "x": 7,
      "y": 11,
      "z": 6,
      "name": "Rock_Runic_Blue_Brick_Stairs",
      "rotation": 1
    },
    {
      "x": 7,
      "y": 0,
      "z": 7,
      "name": "Rock_Runic_Blue_Brick"
    },
    {
      "x": 7,
      "y": 10,
      "z": 7,
      "name": "Rock_Runic_Blue_Brick"
    },
    {
      "x": 7,
      "y": 11,
      "z": 7,
      "name": "Rock_Runic_Blue_Brick_Stairs",
      "rotation": 1
    },
    {
      "x": 7,
      "y": 0,
      "z": 8,
      "name": "Rock_Runic_Blue_Brick"
    },
    {
      "x": 7,
      "y": 10,
      "z": 8,
      "name": "Rock_Runic_Blue_Brick"
    },
    {
      "x": 7,
      "y": 11,
      "z": 8,
      "name": "Rock_Runic_Blue_Brick_Stairs",
      "rotation": 1
    },
    {
      "x": 7,
      "y": 0,
      "z": 9,
      "name": "Rock_Runic_Blue_Brick"
    },
    {
      "x": 7,
      "y": 10,
      "z": 9,
      "name": "Rock_Runic_Blue_Brick"
    },
    {
      "x": 7,
      "y": 11,
      "z": 9,
      "name": "Rock_Runic_Blue_Brick_Stairs",
      "rotation": 1
    },
    {
      "x": 7,
      "y": 0,
      "z": 10,
      "name": "Rock_Runic_Blue_Brick"
    },
    {
      "x": 7,
      "y": 10,
      "z": 10,
      "name": "Rock_Runic_Blue_Brick"
    },
    {
      "x": 7,
      "y": 11,
      "z": 10,
      "name": "Rock_Runic_Blue_Brick_Stairs",
      "rotation": 1
    },
    {
      "x": 7,
      "y": 0,
      "z": 11,
      "name": "Rock_Runic_Blue_Brick"
    },
    {
      "x": 7,
      "y": 10,
      "z": 11,
      "name": "Rock_Runic_Blue_Brick"
    },
    {
      "x": 7,
      "y": 11,
      "z": 11,
      "name": "Rock_Runic_Blue_Brick_Stairs",
      "rotation": 1
    },
    {
      "x": 7,
      "y": 0,
      "z": 12,
      "name": "Rock_Runic_Blue_Brick_Stairs",
      "rotation": 11
    },
    {
      "x": 7,
      "y": 1,
      "z": 12,
      "name": "Rock_Runic_Blue_Brick"
    },
    {
      "x": 7,
      "y": 10,
      "z": 12,
      "name": "Rock_Runic_Blue_Brick"
    },
    {
      "x": 7,
      "y": 11,
      "z": 12,
      "name": "Rock_Runic_Blue_Brick_Stairs",
      "rotation": 1
    },
    {
      "x": 7,
      "y": 0,
      "z": 13,
      "name": "*Rock_Runic_Blue_Brick_Stairs_State_Definitions_Corner_Right",
      "rotation": 10
    },
    {
      "x": 7,
      "y": 1,
      "z": 13,
      "name": "Rock_Runic_Blue_Brick"
    },
    {
      "x": 7,
      "y": 2,
      "z": 13,
      "name": "Rock_Runic_Blue_Brick"
    },
    {
      "x": 7,
      "y": 3,
      "z": 13,
      "name": "Rock_Runic_Blue_Brick"
    },
    {
      "x": 7,
      "y": 4,
      "z": 13,
      "name": "Rock_Runic_Blue_Brick"
    },
    {
      "x": 7,
      "y": 5,
      "z": 13,
      "name": "Rock_Runic_Blue_Brick"
    },
    {
      "x": 7,
      "y": 6,
      "z": 13,
      "name": "Rock_Runic_Blue_Brick"
    },
    {
      "x": 7,
      "y": 7,
      "z": 13,
      "name": "Rock_Runic_Blue_Brick"
    },
    {
      "x": 7,
      "y": 8,
      "z": 13,
      "name": "Rock_Runic_Blue_Brick"
    },
    {
      "x": 7,
      "y": 9,
      "z": 13,
      "name": "Rock_Runic_Blue_Brick"
    },
    {
      "x": 7,
      "y": 10,
      "z": 13,
      "name": "Rock_Runic_Blue_Brick"
    },
    {
      "x": 7,
      "y": 11,
      "z": 13,
      "name": "*Rock_Runic_Blue_Brick_Stairs_State_Definitions_Corner_Right",
      "rotation": 1
    },
    {
      "x": 8,
      "y": 0,
      "z": -5,
      "name": "Plant_Seaweed_Dead_Ghostly",
      "support": 15
    },
    {
      "x": 8,
      "y": 1,
      "z": -5,
      "name": "Plant_Seaweed_Dead_Ghostly",
      "filler": 1024
    },
    {
      "x": 8,
      "y": 0,
      "z": -4,
      "name": "Plant_Seaweed_Dead_Short",
      "support": 15
    },
    {
      "x": 9,
      "y": 0,
      "z": -5,
      "name": "Plant_Seaweed_Dead_Short",
      "support": 15
    }
  ],
  "fluids": [
    {
      "x": -8,
      "y": 0,
      "z": -5,
      "name": "Empty",
      "level": 0
    },
    {
      "x": -8,
      "y": 0,
      "z": -4,
      "name": "Empty",
      "level": 0
    },
    {
      "x": -7,
      "y": 0,
      "z": -6,
      "name": "Empty",
      "level": 0
    },
    {
      "x": -7,
      "y": 0,
      "z": -5,
      "name": "Empty",
      "level": 0
    },
    {
      "x": -7,
      "y": 1,
      "z": -5,
      "name": "Empty",
      "level": 0
    },
    {
      "x": -7,
      "y": 0,
      "z": -4,
      "name": "Empty",
      "level": 0
    },
    {
      "x": -7,
      "y": 1,
      "z": -4,
      "name": "Empty",
      "level": 0
    },
    {
      "x": -7,
      "y": 0,
      "z": -3,
      "name": "Empty",
      "level": 0
    },
    {
      "x": -6,
      "y": 0,
      "z": -10,
      "name": "Empty",
      "level": 0
    },
    {
      "x": -6,
      "y": 1,
      "z": -10,
      "name": "Empty",
      "level": 0
    },
    {
      "x": -6,
      "y": 2,
      "z": -10,
      "name": "Empty",
      "level": 0
    },
    {
      "x": -6,
      "y": 3,
      "z": -10,
      "name": "Empty",
      "level": 0
    },
    {
      "x": -6,
      "y": 4,
      "z": -10,
      "name": "Empty",
      "level": 0
    },
    {
      "x": -6,
      "y": 5,
      "z": -10,
      "name": "Empty",
      "level": 0
    },
    {
      "x": -6,
      "y": 6,
      "z": -10,
      "name": "Empty",
      "level": 0
    },
    {
      "x": -6,
      "y": 7,
      "z": -10,
      "name": "Empty",
      "level": 0
    },
    {
      "x": -6,
      "y": 8,
      "z": -10,
      "name": "Empty",
      "level": 0
    },
    {
      "x": -6,
      "y": 0,
      "z": -9,
      "name": "Empty",
      "level": 0
    },
    {
      "x": -6,
      "y": 1,
      "z": -9,
      "name": "Empty",
      "level": 0
    },
    {
      "x": -6,
      "y": 2,
      "z": -9,
      "name": "Empty",
      "level": 0
    },
    {
      "x": -6,
      "y": 3,
      "z": -9,
      "name": "Empty",
      "level": 0
    },
    {
      "x": -6,
      "y": 4,
      "z": -9,
      "name": "Empty",
      "level": 0
    },
    {
      "x": -6,
      "y": 5,
      "z": -9,
      "name": "Empty",
      "level": 0
    },
    {
      "x": -6,
      "y": 6,
      "z": -9,
      "name": "Empty",
      "level": 0
    },
    {
      "x": -6,
      "y": 7,
      "z": -9,
      "name": "Empty",
      "level": 0
    },
    {
      "x": -6,
      "y": 0,
      "z": -8,
      "name": "Empty",
      "level": 0
    },
    {
      "x": -6,
      "y": 1,
      "z": -8,
      "name": "Empty",
      "level": 0
    },
    {
      "x": -6,
      "y": 2,
      "z": -8,
      "name": "Empty",
      "level": 0
    },
    {
      "x": -6,
      "y": 3,
      "z": -8,
      "name": "Empty",
      "level": 0
    },
    {
      "x": -6,
      "y": 4,
      "z": -8,
      "name": "Empty",
      "level": 0
    },
    {
      "x": -6,
      "y": 5,
      "z": -8,
      "name": "Empty",
      "level": 0
    },
    {
      "x": -6,
      "y": 6,
      "z": -8,
      "name": "Empty",
      "level": 0
    },
    {
      "x": -6,
      "y": 7,
      "z": -8,
      "name": "Empty",
      "level": 0
    },
    {
      "x": -6,
      "y": 0,
      "z": -7,
      "name": "Empty",
      "level": 0
    },
    {
      "x": -6,
      "y": 1,
      "z": -7,
      "name": "Empty",
      "level": 0
    },
    {
      "x": -6,
      "y": 2,
      "z": -7,
      "name": "Empty",
      "level": 0
    },
    {
      "x": -6,
      "y": 3,
      "z": -7,
      "name": "Empty",
      "level": 0
    },
    {
      "x": -6,
      "y": 4,
      "z": -7,
      "name": "Empty",
      "level": 0
    },
    {
      "x": -6,
      "y": 5,
      "z": -7,
      "name": "Empty",
      "level": 0
    },
    {
      "x": -6,
      "y": 6,
      "z": -7,
      "name": "Empty",
      "level": 0
    },
    {
      "x": -6,
      "y": 7,
      "z": -7,
      "name": "Empty",
      "level": 0
    },
    {
      "x": -6,
      "y": 0,
      "z": -6,
      "name": "Empty",
      "level": 0
    },
    {
      "x": -6,
      "y": 1,
      "z": -6,
      "name": "Empty",
      "level": 0
    },
    {
      "x": -6,
      "y": 2,
      "z": -6,
      "name": "Empty",
      "level": 0
    },
    {
      "x": -6,
      "y": 3,
      "z": -6,
      "name": "Empty",
      "level": 0
    },
    {
      "x": -6,
      "y": 4,
      "z": -6,
      "name": "Empty",
      "level": 0
    },
    {
      "x": -6,
      "y": 5,
      "z": -6,
      "name": "Empty",
      "level": 0
    },
    {
      "x": -6,
      "y": 6,
      "z": -6,
      "name": "Empty",
      "level": 0
    },
    {
      "x": -6,
      "y": 7,
      "z": -6,
      "name": "Empty",
      "level": 0
    },
    {
      "x": -6,
      "y": 0,
      "z": -5,
      "name": "Empty",
      "level": 0
    },
    {
      "x": -6,
      "y": 1,
      "z": -5,
      "name": "Empty",
      "level": 0
    },
    {
      "x": -6,
      "y": 2,
      "z": -5,
      "name": "Empty",
      "level": 0
    },
    {
      "x": -6,
      "y": 3,
      "z": -5,
      "name": "Empty",
      "level": 0
    },
    {
      "x": -6,
      "y": 4,
      "z": -5,
      "name": "Empty",
      "level": 0
    },
    {
      "x": -6,
      "y": 5,
      "z": -5,
      "name": "Empty",
      "level": 0
    },
    {
      "x": -6,
      "y": 6,
      "z": -5,
      "name": "Empty",
      "level": 0
    },
    {
      "x": -6,
      "y": 7,
      "z": -5,
      "name": "Empty",
      "level": 0
    },
    {
      "x": -6,
      "y": 0,
      "z": -4,
      "name": "Empty",
      "level": 0
    },
    {
      "x": -6,
      "y": 1,
      "z": -4,
      "name": "Empty",
      "level": 0
    },
    {
      "x": -6,
      "y": 2,
      "z": -4,
      "name": "Empty",
      "level": 0
    },
    {
      "x": -6,
      "y": 3,
      "z": -4,
      "name": "Empty",
      "level": 0
    },
    {
      "x": -6,
      "y": 4,
      "z": -4,
      "name": "Empty",
      "level": 0
    },
    {
      "x": -6,
      "y": 5,
      "z": -4,
      "name": "Empty",
      "level": 0
    },
    {
      "x": -6,
      "y": 6,
      "z": -4,
      "name": "Empty",
      "level": 0
    },
    {
      "x": -6,
      "y": 7,
      "z": -4,
      "name": "Empty",
      "level": 0
    },
    {
      "x": -6,
      "y": 0,
      "z": -3,
      "name": "Empty",
      "level": 0
    },
    {
      "x": -6,
      "y": 1,
      "z": -3,
      "name": "Empty",
      "level": 0
    },
    {
      "x": -6,
      "y": 2,
      "z": -3,
      "name": "Empty",
      "level": 0
    },
    {
      "x": -6,
      "y": 3,
      "z": -3,
      "name": "Empty",
      "level": 0
    },
    {
      "x": -6,
      "y": 4,
      "z": -3,
      "name": "Empty",
      "level": 0
    },
    {
      "x": -6,
      "y": 5,
      "z": -3,
      "name": "Empty",
      "level": 0
    },
    {
      "x": -6,
      "y": 6,
      "z": -3,
      "name": "Empty",
      "level": 0
    },
    {
      "x": -6,
      "y": 7,
      "z": -3,
      "name": "Empty",
      "level": 0
    },
    {
      "x": -6,
      "y": 0,
      "z": -2,
      "name": "Empty",
      "level": 0
    },
    {
      "x": -6,
      "y": 1,
      "z": -2,
      "name": "Empty",
      "level": 0
    },
    {
      "x": -6,
      "y": 2,
      "z": -2,
      "name": "Empty",
      "level": 0
    },
    {
      "x": -6,
      "y": 3,
      "z": -2,
      "name": "Empty",
      "level": 0
    },
    {
      "x": -6,
      "y": 4,
      "z": -2,
      "name": "Empty",
      "level": 0
    },
    {
      "x": -6,
      "y": 5,
      "z": -2,
      "name": "Empty",
      "level": 0
    },
    {
      "x": -6,
      "y": 6,
      "z": -2,
      "name": "Empty",
      "level": 0
    },
    {
      "x": -6,
      "y": 7,
      "z": -2,
      "name": "Empty",
      "level": 0
    },
    {
      "x": -6,
      "y": 0,
      "z": -1,
      "name": "Empty",
      "level": 0
    },
    {
      "x": -6,
      "y": 1,
      "z": -1,
      "name": "Empty",
      "level": 0
    },
    {
      "x": -6,
      "y": 2,
      "z": -1,
      "name": "Empty",
      "level": 0
    },
    {
      "x": -6,
      "y": 3,
      "z": -1,
      "name": "Empty",
      "level": 0
    },
    {
      "x": -6,
      "y": 4,
      "z": -1,
      "name": "Empty",
      "level": 0
    },
    {
      "x": -6,
      "y": 5,
      "z": -1,
      "name": "Empty",
      "level": 0
    },
    {
      "x": -6,
      "y": 6,
      "z": -1,
      "name": "Empty",
      "level": 0
    },
    {
      "x": -6,
      "y": 7,
      "z": -1,
      "name": "Empty",
      "level": 0
    },
    {
      "x": -6,
      "y": 0,
      "z": 0,
      "name": "Empty",
      "level": 0
    },
    {
      "x": -6,
      "y": 1,
      "z": 0,
      "name": "Empty",
      "level": 0
    },
    {
      "x": -6,
      "y": 2,
      "z": 0,
      "name": "Empty",
      "level": 0
    },
    {
      "x": -6,
      "y": 3,
      "z": 0,
      "name": "Empty",
      "level": 0
    },
    {
      "x": -6,
      "y": 4,
      "z": 0,
      "name": "Empty",
      "level": 0
    },
    {
      "x": -6,
      "y": 5,
      "z": 0,
      "name": "Empty",
      "level": 0
    },
    {
      "x": -6,
      "y": 6,
      "z": 0,
      "name": "Empty",
      "level": 0
    },
    {
      "x": -6,
      "y": 7,
      "z": 0,
      "name": "Empty",
      "level": 0
    },
    {
      "x": -6,
      "y": 0,
      "z": 1,
      "name": "Empty",
      "level": 0
    },
    {
      "x": -6,
      "y": 1,
      "z": 1,
      "name": "Empty",
      "level": 0
    },
    {
      "x": -6,
      "y": 2,
      "z": 1,
      "name": "Empty",
      "level": 0
    },
    {
      "x": -6,
      "y": 3,
      "z": 1,
      "name": "Empty",
      "level": 0
    },
    {
      "x": -6,
      "y": 4,
      "z": 1,
      "name": "Empty",
      "level": 0
    },
    {
      "x": -6,
      "y": 5,
      "z": 1,
      "name": "Empty",
      "level": 0
    },
    {
      "x": -6,
      "y": 6,
      "z": 1,
      "name": "Empty",
      "level": 0
    },
    {
      "x": -6,
      "y": 7,
      "z": 1,
      "name": "Empty",
      "level": 0
    },
    {
      "x": -6,
      "y": 0,
      "z": 2,
      "name": "Empty",
      "level": 0
    },
    {
      "x": -6,
      "y": 1,
      "z": 2,
      "name": "Empty",
      "level": 0
    },
    {
      "x": -6,
      "y": 2,
      "z": 2,
      "name": "Empty",
      "level": 0
    },
    {
      "x": -6,
      "y": 3,
      "z": 2,
      "name": "Empty",
      "level": 0
    },
    {
      "x": -6,
      "y": 4,
      "z": 2,
      "name": "Empty",
      "level": 0
    },
    {
      "x": -6,
      "y": 5,
      "z": 2,
      "name": "Empty",
      "level": 0
    },
    {
      "x": -6,
      "y": 6,
      "z": 2,
      "name": "Empty",
      "level": 0
    },
    {
      "x": -6,
      "y": 7,
      "z": 2,
      "name": "Empty",
      "level": 0
    },
    {
      "x": -6,
      "y": 0,
      "z": 3,
      "name": "Empty",
      "level": 0
    },
    {
      "x": -6,
      "y": 1,
      "z": 3,
      "name": "Empty",
      "level": 0
    },
    {
      "x": -6,
      "y": 2,
      "z": 3,
      "name": "Empty",
      "level": 0
    },
    {
      "x": -6,
      "y": 3,
      "z": 3,
      "name": "Empty",
      "level": 0
    },
    {
      "x": -6,
      "y": 4,
      "z": 3,
      "name": "Empty",
      "level": 0
    },
    {
      "x": -6,
      "y": 5,
      "z": 3,
      "name": "Empty",
      "level": 0
    },
    {
      "x": -6,
      "y": 6,
      "z": 3,
      "name": "Empty",
      "level": 0
    },
    {
      "x": -6,
      "y": 7,
      "z": 3,
      "name": "Empty",
      "level": 0
    },
    {
      "x": -6,
      "y": 0,
      "z": 4,
      "name": "Empty",
      "level": 0
    },
    {
      "x": -6,
      "y": 1,
      "z": 4,
      "name": "Empty",
      "level": 0
    },
    {
      "x": -6,
      "y": 2,
      "z": 4,
      "name": "Empty",
      "level": 0
    },
    {
      "x": -6,
      "y": 3,
      "z": 4,
      "name": "Empty",
      "level": 0
    },
    {
      "x": -6,
      "y": 4,
      "z": 4,
      "name": "Empty",
      "level": 0
    },
    {
      "x": -6,
      "y": 5,
      "z": 4,
      "name": "Empty",
      "level": 0
    },
    {
      "x": -6,
      "y": 6,
      "z": 4,
      "name": "Empty",
      "level": 0
    },
    {
      "x": -6,
      "y": 7,
      "z": 4,
      "name": "Empty",
      "level": 0
    },
    {
      "x": -6,
      "y": 0,
      "z": 5,
      "name": "Empty",
      "level": 0
    },
    {
      "x": -6,
      "y": 1,
      "z": 5,
      "name": "Empty",
      "level": 0
    },
    {
      "x": -6,
      "y": 2,
      "z": 5,
      "name": "Empty",
      "level": 0
    },
    {
      "x": -6,
      "y": 3,
      "z": 5,
      "name": "Empty",
      "level": 0
    },
    {
      "x": -6,
      "y": 4,
      "z": 5,
      "name": "Empty",
      "level": 0
    },
    {
      "x": -6,
      "y": 5,
      "z": 5,
      "name": "Empty",
      "level": 0
    },
    {
      "x": -6,
      "y": 6,
      "z": 5,
      "name": "Empty",
      "level": 0
    },
    {
      "x": -6,
      "y": 7,
      "z": 5,
      "name": "Empty",
      "level": 0
    },
    {
      "x": -6,
      "y": 0,
      "z": 6,
      "name": "Empty",
      "level": 0
    },
    {
      "x": -6,
      "y": 1,
      "z": 6,
      "name": "Empty",
      "level": 0
    },
    {
      "x": -6,
      "y": 2,
      "z": 6,
      "name": "Empty",
      "level": 0
    },
    {
      "x": -6,
      "y": 3,
      "z": 6,
      "name": "Empty",
      "level": 0
    },
    {
      "x": -6,
      "y": 4,
      "z": 6,
      "name": "Empty",
      "level": 0
    },
    {
      "x": -6,
      "y": 5,
      "z": 6,
      "name": "Empty",
      "level": 0
    },
    {
      "x": -6,
      "y": 6,
      "z": 6,
      "name": "Empty",
      "level": 0
    },
    {
      "x": -6,
      "y": 7,
      "z": 6,
      "name": "Empty",
      "level": 0
    },
    {
      "x": -6,
      "y": 0,
      "z": 7,
      "name": "Empty",
      "level": 0
    },
    {
      "x": -6,
      "y": 1,
      "z": 7,
      "name": "Empty",
      "level": 0
    },
    {
      "x": -6,
      "y": 2,
      "z": 7,
      "name": "Empty",
      "level": 0
    },
    {
      "x": -6,
      "y": 3,
      "z": 7,
      "name": "Empty",
      "level": 0
    },
    {
      "x": -6,
      "y": 4,
      "z": 7,
      "name": "Empty",
      "level": 0
    },
    {
      "x": -6,
      "y": 5,
      "z": 7,
      "name": "Empty",
      "level": 0
    },
    {
      "x": -6,
      "y": 6,
      "z": 7,
      "name": "Empty",
      "level": 0
    },
    {
      "x": -6,
      "y": 7,
      "z": 7,
      "name": "Empty",
      "level": 0
    },
    {
      "x": -6,
      "y": 0,
      "z": 8,
      "name": "Empty",
      "level": 0
    },
    {
      "x": -6,
      "y": 1,
      "z": 8,
      "name": "Empty",
      "level": 0
    },
    {
      "x": -6,
      "y": 2,
      "z": 8,
      "name": "Empty",
      "level": 0
    },
    {
      "x": -6,
      "y": 3,
      "z": 8,
      "name": "Empty",
      "level": 0
    },
    {
      "x": -6,
      "y": 4,
      "z": 8,
      "name": "Empty",
      "level": 0
    },
    {
      "x": -6,
      "y": 5,
      "z": 8,
      "name": "Empty",
      "level": 0
    },
    {
      "x": -6,
      "y": 6,
      "z": 8,
      "name": "Empty",
      "level": 0
    },
    {
      "x": -6,
      "y": 7,
      "z": 8,
      "name": "Empty",
      "level": 0
    },
    {
      "x": -6,
      "y": 0,
      "z": 9,
      "name": "Empty",
      "level": 0
    },
    {
      "x": -6,
      "y": 1,
      "z": 9,
      "name": "Empty",
      "level": 0
    },
    {
      "x": -6,
      "y": 2,
      "z": 9,
      "name": "Empty",
      "level": 0
    },
    {
      "x": -6,
      "y": 3,
      "z": 9,
      "name": "Empty",
      "level": 0
    },
    {
      "x": -6,
      "y": 4,
      "z": 9,
      "name": "Empty",
      "level": 0
    },
    {
      "x": -6,
      "y": 5,
      "z": 9,
      "name": "Empty",
      "level": 0
    },
    {
      "x": -6,
      "y": 6,
      "z": 9,
      "name": "Empty",
      "level": 0
    },
    {
      "x": -6,
      "y": 7,
      "z": 9,
      "name": "Empty",
      "level": 0
    },
    {
      "x": -6,
      "y": 0,
      "z": 10,
      "name": "Empty",
      "level": 0
    },
    {
      "x": -6,
      "y": 1,
      "z": 10,
      "name": "Empty",
      "level": 0
    },
    {
      "x": -6,
      "y": 2,
      "z": 10,
      "name": "Empty",
      "level": 0
    },
    {
      "x": -6,
      "y": 3,
      "z": 10,
      "name": "Empty",
      "level": 0
    },
    {
      "x": -6,
      "y": 4,
      "z": 10,
      "name": "Empty",
      "level": 0
    },
    {
      "x": -6,
      "y": 5,
      "z": 10,
      "name": "Empty",
      "level": 0
    },
    {
      "x": -6,
      "y": 6,
      "z": 10,
      "name": "Empty",
      "level": 0
    },
    {
      "x": -6,
      "y": 7,
      "z": 10,
      "name": "Empty",
      "level": 0
    },
    {
      "x": -6,
      "y": 0,
      "z": 11,
      "name": "Empty",
      "level": 0
    },
    {
      "x": -6,
      "y": 1,
      "z": 11,
      "name": "Empty",
      "level": 0
    },
    {
      "x": -6,
      "y": 2,
      "z": 11,
      "name": "Empty",
      "level": 0
    },
    {
      "x": -6,
      "y": 3,
      "z": 11,
      "name": "Empty",
      "level": 0
    },
    {
      "x": -6,
      "y": 4,
      "z": 11,
      "name": "Empty",
      "level": 0
    },
    {
      "x": -6,
      "y": 5,
      "z": 11,
      "name": "Empty",
      "level": 0
    },
    {
      "x": -6,
      "y": 6,
      "z": 11,
      "name": "Empty",
      "level": 0
    },
    {
      "x": -6,
      "y": 7,
      "z": 11,
      "name": "Empty",
      "level": 0
    },
    {
      "x": -6,
      "y": 0,
      "z": 12,
      "name": "Empty",
      "level": 0
    },
    {
      "x": -6,
      "y": 1,
      "z": 12,
      "name": "Empty",
      "level": 0
    },
    {
      "x": -6,
      "y": 2,
      "z": 12,
      "name": "Empty",
      "level": 0
    },
    {
      "x": -6,
      "y": 3,
      "z": 12,
      "name": "Empty",
      "level": 0
    },
    {
      "x": -6,
      "y": 4,
      "z": 12,
      "name": "Empty",
      "level": 0
    },
    {
      "x": -6,
      "y": 5,
      "z": 12,
      "name": "Empty",
      "level": 0
